## Original File URL: https://github.com/arita37/mlmodels_store/blob/master/log_json/log_json.py


### Error 1, [Traceback at line 48](https://github.com/arita37/mlmodels_store/blob/master/log_json/log_json.py#L48)<br />48..Traceback (most recent call last):
<br />  File "/opt/hostedtoolcache/Python/3.6.12/x64/bin/ml_models", line 11, in <module>
<br />    load_entry_point('mlmodels', 'console_scripts', 'ml_models')()
<br />  File "https://github.com/arita37/mlmodels/tree/ff21906d63b46d89670bd3ed148b01355ca5ff0e/mlmodels/models.py", line 530, in main
<br />    fit_cli(arg)
<br />  File "https://github.com/arita37/mlmodels/tree/ff21906d63b46d89670bd3ed148b01355ca5ff0e/mlmodels/models.py", line 414, in fit_cli
<br />    model_uri = model_p['model_uri']
<br />KeyError: 'model_uri'



### Error 2, [Traceback at line 72](https://github.com/arita37/mlmodels_store/blob/master/log_json/log_json.py#L72)<br />72..Traceback (most recent call last):
<br />  File "/opt/hostedtoolcache/Python/3.6.12/x64/bin/ml_models", line 11, in <module>
<br />    load_entry_point('mlmodels', 'console_scripts', 'ml_models')()
<br />  File "https://github.com/arita37/mlmodels/tree/ff21906d63b46d89670bd3ed148b01355ca5ff0e/mlmodels/models.py", line 530, in main
<br />    fit_cli(arg)
<br />  File "https://github.com/arita37/mlmodels/tree/ff21906d63b46d89670bd3ed148b01355ca5ff0e/mlmodels/models.py", line 415, in fit_cli
<br />    path      = out_p['path']
<br />KeyError: 'path'



### Error 3, [Traceback at line 96](https://github.com/arita37/mlmodels_store/blob/master/log_json/log_json.py#L96)<br />96..Traceback (most recent call last):
<br />  File "/opt/hostedtoolcache/Python/3.6.12/x64/bin/ml_models", line 11, in <module>
<br />    load_entry_point('mlmodels', 'console_scripts', 'ml_models')()
<br />  File "https://github.com/arita37/mlmodels/tree/ff21906d63b46d89670bd3ed148b01355ca5ff0e/mlmodels/models.py", line 530, in main
<br />    fit_cli(arg)
<br />  File "https://github.com/arita37/mlmodels/tree/ff21906d63b46d89670bd3ed148b01355ca5ff0e/mlmodels/models.py", line 415, in fit_cli
<br />    path      = out_p['path']
<br />KeyError: 'path'



### Error 4, [Traceback at line 120](https://github.com/arita37/mlmodels_store/blob/master/log_json/log_json.py#L120)<br />120..Traceback (most recent call last):
<br />  File "/opt/hostedtoolcache/Python/3.6.12/x64/bin/ml_models", line 11, in <module>
<br />    load_entry_point('mlmodels', 'console_scripts', 'ml_models')()
<br />  File "https://github.com/arita37/mlmodels/tree/ff21906d63b46d89670bd3ed148b01355ca5ff0e/mlmodels/models.py", line 530, in main
<br />    fit_cli(arg)
<br />  File "https://github.com/arita37/mlmodels/tree/ff21906d63b46d89670bd3ed148b01355ca5ff0e/mlmodels/models.py", line 415, in fit_cli
<br />    path      = out_p['path']
<br />KeyError: 'path'



### Error 5, [Traceback at line 139](https://github.com/arita37/mlmodels_store/blob/master/log_json/log_json.py#L139)<br />139..Traceback (most recent call last):
<br />  File "/opt/hostedtoolcache/Python/3.6.12/x64/bin/ml_models", line 11, in <module>
<br />    load_entry_point('mlmodels', 'console_scripts', 'ml_models')()
<br />  File "https://github.com/arita37/mlmodels/tree/ff21906d63b46d89670bd3ed148b01355ca5ff0e/mlmodels/models.py", line 530, in main
<br />    fit_cli(arg)
<br />  File "https://github.com/arita37/mlmodels/tree/ff21906d63b46d89670bd3ed148b01355ca5ff0e/mlmodels/models.py", line 413, in fit_cli
<br />    model_p, data_p, compute_p, out_p = config_get_pars(config_file, arg.config_mode)
<br />  File "https://github.com/arita37/mlmodels/tree/ff21906d63b46d89670bd3ed148b01355ca5ff0e/mlmodels/models.py", line 297, in config_get_pars
<br />    data_p    = path_norm_dict( js.get("data_pars") )
<br />  File "https://github.com/arita37/mlmodels/tree/ff21906d63b46d89670bd3ed148b01355ca5ff0e/mlmodels/util.py", line 201, in path_norm_dict
<br />    for k,v in ddict.items():
<br />AttributeError: 'NoneType' object has no attribute 'items'



### Error 6, [Traceback at line 167](https://github.com/arita37/mlmodels_store/blob/master/log_json/log_json.py#L167)<br />167..Traceback (most recent call last):
<br />  File "/opt/hostedtoolcache/Python/3.6.12/x64/bin/ml_models", line 11, in <module>
<br />    load_entry_point('mlmodels', 'console_scripts', 'ml_models')()
<br />  File "https://github.com/arita37/mlmodels/tree/ff21906d63b46d89670bd3ed148b01355ca5ff0e/mlmodels/models.py", line 530, in main
<br />    fit_cli(arg)
<br />  File "https://github.com/arita37/mlmodels/tree/ff21906d63b46d89670bd3ed148b01355ca5ff0e/mlmodels/models.py", line 415, in fit_cli
<br />    path      = out_p['path']
<br />KeyError: 'path'



### Error 7, [Traceback at line 186](https://github.com/arita37/mlmodels_store/blob/master/log_json/log_json.py#L186)<br />186..Traceback (most recent call last):
<br />  File "/opt/hostedtoolcache/Python/3.6.12/x64/bin/ml_models", line 11, in <module>
<br />    load_entry_point('mlmodels', 'console_scripts', 'ml_models')()
<br />  File "https://github.com/arita37/mlmodels/tree/ff21906d63b46d89670bd3ed148b01355ca5ff0e/mlmodels/models.py", line 530, in main
<br />    fit_cli(arg)
<br />  File "https://github.com/arita37/mlmodels/tree/ff21906d63b46d89670bd3ed148b01355ca5ff0e/mlmodels/models.py", line 415, in fit_cli
<br />    path      = out_p['path']
<br />KeyError: 'path'



### Error 8, [Traceback at line 205](https://github.com/arita37/mlmodels_store/blob/master/log_json/log_json.py#L205)<br />205..Traceback (most recent call last):
<br />  File "/opt/hostedtoolcache/Python/3.6.12/x64/bin/ml_models", line 11, in <module>
<br />    load_entry_point('mlmodels', 'console_scripts', 'ml_models')()
<br />  File "https://github.com/arita37/mlmodels/tree/ff21906d63b46d89670bd3ed148b01355ca5ff0e/mlmodels/models.py", line 530, in main
<br />    fit_cli(arg)
<br />  File "https://github.com/arita37/mlmodels/tree/ff21906d63b46d89670bd3ed148b01355ca5ff0e/mlmodels/models.py", line 415, in fit_cli
<br />    path      = out_p['path']
<br />KeyError: 'path'



### Error 9, [Traceback at line 226](https://github.com/arita37/mlmodels_store/blob/master/log_json/log_json.py#L226)<br />226..Traceback (most recent call last):
<br />  File "https://github.com/arita37/mlmodels/tree/ff21906d63b46d89670bd3ed148b01355ca5ff0e/mlmodels/models.py", line 72, in module_load
<br />    module = import_module(f"mlmodels.{model_name}")
<br />  File "/opt/hostedtoolcache/Python/3.6.12/x64/lib/python3.6/importlib/__init__.py", line 126, in import_module
<br />    return _bootstrap._gcd_import(name[level:], package, level)
<br />  File "<frozen importlib._bootstrap>", line 994, in _gcd_import
<br />  File "<frozen importlib._bootstrap>", line 971, in _find_and_load
<br />  File "<frozen importlib._bootstrap>", line 955, in _find_and_load_unlocked
<br />  File "<frozen importlib._bootstrap>", line 665, in _load_unlocked
<br />  File "<frozen importlib._bootstrap_external>", line 674, in exec_module
<br />  File "<frozen importlib._bootstrap_external>", line 781, in get_code
<br />  File "<frozen importlib._bootstrap_external>", line 741, in source_to_code
<br />  File "<frozen importlib._bootstrap>", line 219, in _call_with_frames_removed
<br />  File "https://github.com/arita37/mlmodels/tree/ff21906d63b46d89670bd3ed148b01355ca5ff0e/mlmodels/model_gluon/gluonts_model.py", line 203
<br />    if d ==  "single_dataframe" :
<br />                                ^
<br />SyntaxError: invalid syntax



### Error 10, [Traceback at line 246](https://github.com/arita37/mlmodels_store/blob/master/log_json/log_json.py#L246)<br />246..Traceback (most recent call last):
<br />  File "https://github.com/arita37/mlmodels/tree/ff21906d63b46d89670bd3ed148b01355ca5ff0e/mlmodels/models.py", line 84, in module_load
<br />    model_name = str(Path(model_uri).parts[-2]) + "." + str(model_name)
<br />IndexError: tuple index out of range



### Error 11, [Traceback at line 253](https://github.com/arita37/mlmodels_store/blob/master/log_json/log_json.py#L253)<br />253..Traceback (most recent call last):
<br />  File "/opt/hostedtoolcache/Python/3.6.12/x64/bin/ml_models", line 11, in <module>
<br />    load_entry_point('mlmodels', 'console_scripts', 'ml_models')()
<br />  File "https://github.com/arita37/mlmodels/tree/ff21906d63b46d89670bd3ed148b01355ca5ff0e/mlmodels/models.py", line 530, in main
<br />    fit_cli(arg)
<br />  File "https://github.com/arita37/mlmodels/tree/ff21906d63b46d89670bd3ed148b01355ca5ff0e/mlmodels/models.py", line 420, in fit_cli
<br />    module = module_load(model_uri)  # '1_lstm.py
<br />  File "https://github.com/arita37/mlmodels/tree/ff21906d63b46d89670bd3ed148b01355ca5ff0e/mlmodels/models.py", line 89, in module_load
<br />    raise NameError(f"Module {model_name} notfound, {e1}, {e2}")
<br />NameError: Module model_gluon notfound, invalid syntax (gluonts_model.py, line 203), tuple index out of range



### Error 12, [Traceback at line 276](https://github.com/arita37/mlmodels_store/blob/master/log_json/log_json.py#L276)<br />276..Traceback (most recent call last):
<br />  File "https://github.com/arita37/mlmodels/tree/ff21906d63b46d89670bd3ed148b01355ca5ff0e/mlmodels/models.py", line 72, in module_load
<br />    module = import_module(f"mlmodels.{model_name}")
<br />  File "/opt/hostedtoolcache/Python/3.6.12/x64/lib/python3.6/importlib/__init__.py", line 126, in import_module
<br />    return _bootstrap._gcd_import(name[level:], package, level)
<br />  File "<frozen importlib._bootstrap>", line 994, in _gcd_import
<br />  File "<frozen importlib._bootstrap>", line 971, in _find_and_load
<br />  File "<frozen importlib._bootstrap>", line 955, in _find_and_load_unlocked
<br />  File "<frozen importlib._bootstrap>", line 665, in _load_unlocked
<br />  File "<frozen importlib._bootstrap_external>", line 674, in exec_module
<br />  File "<frozen importlib._bootstrap_external>", line 781, in get_code
<br />  File "<frozen importlib._bootstrap_external>", line 741, in source_to_code
<br />  File "<frozen importlib._bootstrap>", line 219, in _call_with_frames_removed
<br />  File "https://github.com/arita37/mlmodels/tree/ff21906d63b46d89670bd3ed148b01355ca5ff0e/mlmodels/model_gluon/gluonts_model.py", line 203
<br />    if d ==  "single_dataframe" :
<br />                                ^
<br />SyntaxError: invalid syntax



### Error 13, [Traceback at line 296](https://github.com/arita37/mlmodels_store/blob/master/log_json/log_json.py#L296)<br />296..Traceback (most recent call last):
<br />  File "https://github.com/arita37/mlmodels/tree/ff21906d63b46d89670bd3ed148b01355ca5ff0e/mlmodels/models.py", line 84, in module_load
<br />    model_name = str(Path(model_uri).parts[-2]) + "." + str(model_name)
<br />IndexError: tuple index out of range



### Error 14, [Traceback at line 303](https://github.com/arita37/mlmodels_store/blob/master/log_json/log_json.py#L303)<br />303..Traceback (most recent call last):
<br />  File "/opt/hostedtoolcache/Python/3.6.12/x64/bin/ml_models", line 11, in <module>
<br />    load_entry_point('mlmodels', 'console_scripts', 'ml_models')()
<br />  File "https://github.com/arita37/mlmodels/tree/ff21906d63b46d89670bd3ed148b01355ca5ff0e/mlmodels/models.py", line 530, in main
<br />    fit_cli(arg)
<br />  File "https://github.com/arita37/mlmodels/tree/ff21906d63b46d89670bd3ed148b01355ca5ff0e/mlmodels/models.py", line 420, in fit_cli
<br />    module = module_load(model_uri)  # '1_lstm.py
<br />  File "https://github.com/arita37/mlmodels/tree/ff21906d63b46d89670bd3ed148b01355ca5ff0e/mlmodels/models.py", line 89, in module_load
<br />    raise NameError(f"Module {model_name} notfound, {e1}, {e2}")
<br />NameError: Module model_gluon notfound, invalid syntax (gluonts_model.py, line 203), tuple index out of range



### Error 15, [Traceback at line 326](https://github.com/arita37/mlmodels_store/blob/master/log_json/log_json.py#L326)<br />326..Traceback (most recent call last):
<br />  File "https://github.com/arita37/mlmodels/tree/ff21906d63b46d89670bd3ed148b01355ca5ff0e/mlmodels/models.py", line 72, in module_load
<br />    module = import_module(f"mlmodels.{model_name}")
<br />  File "/opt/hostedtoolcache/Python/3.6.12/x64/lib/python3.6/importlib/__init__.py", line 126, in import_module
<br />    return _bootstrap._gcd_import(name[level:], package, level)
<br />  File "<frozen importlib._bootstrap>", line 994, in _gcd_import
<br />  File "<frozen importlib._bootstrap>", line 971, in _find_and_load
<br />  File "<frozen importlib._bootstrap>", line 955, in _find_and_load_unlocked
<br />  File "<frozen importlib._bootstrap>", line 665, in _load_unlocked
<br />  File "<frozen importlib._bootstrap_external>", line 674, in exec_module
<br />  File "<frozen importlib._bootstrap_external>", line 781, in get_code
<br />  File "<frozen importlib._bootstrap_external>", line 741, in source_to_code
<br />  File "<frozen importlib._bootstrap>", line 219, in _call_with_frames_removed
<br />  File "https://github.com/arita37/mlmodels/tree/ff21906d63b46d89670bd3ed148b01355ca5ff0e/mlmodels/model_gluon/gluonts_model.py", line 203
<br />    if d ==  "single_dataframe" :
<br />                                ^
<br />SyntaxError: invalid syntax



### Error 16, [Traceback at line 346](https://github.com/arita37/mlmodels_store/blob/master/log_json/log_json.py#L346)<br />346..Traceback (most recent call last):
<br />  File "https://github.com/arita37/mlmodels/tree/ff21906d63b46d89670bd3ed148b01355ca5ff0e/mlmodels/models.py", line 84, in module_load
<br />    model_name = str(Path(model_uri).parts[-2]) + "." + str(model_name)
<br />IndexError: tuple index out of range



### Error 17, [Traceback at line 353](https://github.com/arita37/mlmodels_store/blob/master/log_json/log_json.py#L353)<br />353..Traceback (most recent call last):
<br />  File "/opt/hostedtoolcache/Python/3.6.12/x64/bin/ml_models", line 11, in <module>
<br />    load_entry_point('mlmodels', 'console_scripts', 'ml_models')()
<br />  File "https://github.com/arita37/mlmodels/tree/ff21906d63b46d89670bd3ed148b01355ca5ff0e/mlmodels/models.py", line 530, in main
<br />    fit_cli(arg)
<br />  File "https://github.com/arita37/mlmodels/tree/ff21906d63b46d89670bd3ed148b01355ca5ff0e/mlmodels/models.py", line 420, in fit_cli
<br />    module = module_load(model_uri)  # '1_lstm.py
<br />  File "https://github.com/arita37/mlmodels/tree/ff21906d63b46d89670bd3ed148b01355ca5ff0e/mlmodels/models.py", line 89, in module_load
<br />    raise NameError(f"Module {model_name} notfound, {e1}, {e2}")
<br />NameError: Module model_gluon notfound, invalid syntax (gluonts_model.py, line 203), tuple index out of range



### Error 18, [Traceback at line 376](https://github.com/arita37/mlmodels_store/blob/master/log_json/log_json.py#L376)<br />376..Traceback (most recent call last):
<br />  File "https://github.com/arita37/mlmodels/tree/ff21906d63b46d89670bd3ed148b01355ca5ff0e/mlmodels/models.py", line 72, in module_load
<br />    module = import_module(f"mlmodels.{model_name}")
<br />  File "/opt/hostedtoolcache/Python/3.6.12/x64/lib/python3.6/importlib/__init__.py", line 126, in import_module
<br />    return _bootstrap._gcd_import(name[level:], package, level)
<br />  File "<frozen importlib._bootstrap>", line 994, in _gcd_import
<br />  File "<frozen importlib._bootstrap>", line 971, in _find_and_load
<br />  File "<frozen importlib._bootstrap>", line 955, in _find_and_load_unlocked
<br />  File "<frozen importlib._bootstrap>", line 665, in _load_unlocked
<br />  File "<frozen importlib._bootstrap_external>", line 674, in exec_module
<br />  File "<frozen importlib._bootstrap_external>", line 781, in get_code
<br />  File "<frozen importlib._bootstrap_external>", line 741, in source_to_code
<br />  File "<frozen importlib._bootstrap>", line 219, in _call_with_frames_removed
<br />  File "https://github.com/arita37/mlmodels/tree/ff21906d63b46d89670bd3ed148b01355ca5ff0e/mlmodels/model_gluon/gluonts_model.py", line 203
<br />    if d ==  "single_dataframe" :
<br />                                ^
<br />SyntaxError: invalid syntax



### Error 19, [Traceback at line 396](https://github.com/arita37/mlmodels_store/blob/master/log_json/log_json.py#L396)<br />396..Traceback (most recent call last):
<br />  File "https://github.com/arita37/mlmodels/tree/ff21906d63b46d89670bd3ed148b01355ca5ff0e/mlmodels/models.py", line 84, in module_load
<br />    model_name = str(Path(model_uri).parts[-2]) + "." + str(model_name)
<br />IndexError: tuple index out of range



### Error 20, [Traceback at line 403](https://github.com/arita37/mlmodels_store/blob/master/log_json/log_json.py#L403)<br />403..Traceback (most recent call last):
<br />  File "/opt/hostedtoolcache/Python/3.6.12/x64/bin/ml_models", line 11, in <module>
<br />    load_entry_point('mlmodels', 'console_scripts', 'ml_models')()
<br />  File "https://github.com/arita37/mlmodels/tree/ff21906d63b46d89670bd3ed148b01355ca5ff0e/mlmodels/models.py", line 530, in main
<br />    fit_cli(arg)
<br />  File "https://github.com/arita37/mlmodels/tree/ff21906d63b46d89670bd3ed148b01355ca5ff0e/mlmodels/models.py", line 420, in fit_cli
<br />    module = module_load(model_uri)  # '1_lstm.py
<br />  File "https://github.com/arita37/mlmodels/tree/ff21906d63b46d89670bd3ed148b01355ca5ff0e/mlmodels/models.py", line 89, in module_load
<br />    raise NameError(f"Module {model_name} notfound, {e1}, {e2}")
<br />NameError: Module model_gluon notfound, invalid syntax (gluonts_model.py, line 203), tuple index out of range



### Error 21, [Traceback at line 426](https://github.com/arita37/mlmodels_store/blob/master/log_json/log_json.py#L426)<br />426..Traceback (most recent call last):
<br />  File "https://github.com/arita37/mlmodels/tree/ff21906d63b46d89670bd3ed148b01355ca5ff0e/mlmodels/models.py", line 72, in module_load
<br />    module = import_module(f"mlmodels.{model_name}")
<br />  File "/opt/hostedtoolcache/Python/3.6.12/x64/lib/python3.6/importlib/__init__.py", line 126, in import_module
<br />    return _bootstrap._gcd_import(name[level:], package, level)
<br />  File "<frozen importlib._bootstrap>", line 994, in _gcd_import
<br />  File "<frozen importlib._bootstrap>", line 971, in _find_and_load
<br />  File "<frozen importlib._bootstrap>", line 955, in _find_and_load_unlocked
<br />  File "<frozen importlib._bootstrap>", line 665, in _load_unlocked
<br />  File "<frozen importlib._bootstrap_external>", line 674, in exec_module
<br />  File "<frozen importlib._bootstrap_external>", line 781, in get_code
<br />  File "<frozen importlib._bootstrap_external>", line 741, in source_to_code
<br />  File "<frozen importlib._bootstrap>", line 219, in _call_with_frames_removed
<br />  File "https://github.com/arita37/mlmodels/tree/ff21906d63b46d89670bd3ed148b01355ca5ff0e/mlmodels/model_gluon/gluonts_model.py", line 203
<br />    if d ==  "single_dataframe" :
<br />                                ^
<br />SyntaxError: invalid syntax



### Error 22, [Traceback at line 446](https://github.com/arita37/mlmodels_store/blob/master/log_json/log_json.py#L446)<br />446..Traceback (most recent call last):
<br />  File "https://github.com/arita37/mlmodels/tree/ff21906d63b46d89670bd3ed148b01355ca5ff0e/mlmodels/models.py", line 84, in module_load
<br />    model_name = str(Path(model_uri).parts[-2]) + "." + str(model_name)
<br />IndexError: tuple index out of range



### Error 23, [Traceback at line 453](https://github.com/arita37/mlmodels_store/blob/master/log_json/log_json.py#L453)<br />453..Traceback (most recent call last):
<br />  File "/opt/hostedtoolcache/Python/3.6.12/x64/bin/ml_models", line 11, in <module>
<br />    load_entry_point('mlmodels', 'console_scripts', 'ml_models')()
<br />  File "https://github.com/arita37/mlmodels/tree/ff21906d63b46d89670bd3ed148b01355ca5ff0e/mlmodels/models.py", line 530, in main
<br />    fit_cli(arg)
<br />  File "https://github.com/arita37/mlmodels/tree/ff21906d63b46d89670bd3ed148b01355ca5ff0e/mlmodels/models.py", line 420, in fit_cli
<br />    module = module_load(model_uri)  # '1_lstm.py
<br />  File "https://github.com/arita37/mlmodels/tree/ff21906d63b46d89670bd3ed148b01355ca5ff0e/mlmodels/models.py", line 89, in module_load
<br />    raise NameError(f"Module {model_name} notfound, {e1}, {e2}")
<br />NameError: Module model_gluon notfound, invalid syntax (gluonts_model.py, line 203), tuple index out of range



### Error 24, [Traceback at line 476](https://github.com/arita37/mlmodels_store/blob/master/log_json/log_json.py#L476)<br />476..Traceback (most recent call last):
<br />  File "https://github.com/arita37/mlmodels/tree/ff21906d63b46d89670bd3ed148b01355ca5ff0e/mlmodels/models.py", line 72, in module_load
<br />    module = import_module(f"mlmodels.{model_name}")
<br />  File "/opt/hostedtoolcache/Python/3.6.12/x64/lib/python3.6/importlib/__init__.py", line 126, in import_module
<br />    return _bootstrap._gcd_import(name[level:], package, level)
<br />  File "<frozen importlib._bootstrap>", line 994, in _gcd_import
<br />  File "<frozen importlib._bootstrap>", line 971, in _find_and_load
<br />  File "<frozen importlib._bootstrap>", line 955, in _find_and_load_unlocked
<br />  File "<frozen importlib._bootstrap>", line 665, in _load_unlocked
<br />  File "<frozen importlib._bootstrap_external>", line 674, in exec_module
<br />  File "<frozen importlib._bootstrap_external>", line 781, in get_code
<br />  File "<frozen importlib._bootstrap_external>", line 741, in source_to_code
<br />  File "<frozen importlib._bootstrap>", line 219, in _call_with_frames_removed
<br />  File "https://github.com/arita37/mlmodels/tree/ff21906d63b46d89670bd3ed148b01355ca5ff0e/mlmodels/model_gluon/gluonts_model.py", line 203
<br />    if d ==  "single_dataframe" :
<br />                                ^
<br />SyntaxError: invalid syntax



### Error 25, [Traceback at line 496](https://github.com/arita37/mlmodels_store/blob/master/log_json/log_json.py#L496)<br />496..Traceback (most recent call last):
<br />  File "https://github.com/arita37/mlmodels/tree/ff21906d63b46d89670bd3ed148b01355ca5ff0e/mlmodels/models.py", line 84, in module_load
<br />    model_name = str(Path(model_uri).parts[-2]) + "." + str(model_name)
<br />IndexError: tuple index out of range



### Error 26, [Traceback at line 503](https://github.com/arita37/mlmodels_store/blob/master/log_json/log_json.py#L503)<br />503..Traceback (most recent call last):
<br />  File "/opt/hostedtoolcache/Python/3.6.12/x64/bin/ml_models", line 11, in <module>
<br />    load_entry_point('mlmodels', 'console_scripts', 'ml_models')()
<br />  File "https://github.com/arita37/mlmodels/tree/ff21906d63b46d89670bd3ed148b01355ca5ff0e/mlmodels/models.py", line 530, in main
<br />    fit_cli(arg)
<br />  File "https://github.com/arita37/mlmodels/tree/ff21906d63b46d89670bd3ed148b01355ca5ff0e/mlmodels/models.py", line 420, in fit_cli
<br />    module = module_load(model_uri)  # '1_lstm.py
<br />  File "https://github.com/arita37/mlmodels/tree/ff21906d63b46d89670bd3ed148b01355ca5ff0e/mlmodels/models.py", line 89, in module_load
<br />    raise NameError(f"Module {model_name} notfound, {e1}, {e2}")
<br />NameError: Module model_gluon notfound, invalid syntax (gluonts_model.py, line 203), tuple index out of range



### Error 27, [Traceback at line 526](https://github.com/arita37/mlmodels_store/blob/master/log_json/log_json.py#L526)<br />526..Traceback (most recent call last):
<br />  File "https://github.com/arita37/mlmodels/tree/ff21906d63b46d89670bd3ed148b01355ca5ff0e/mlmodels/models.py", line 72, in module_load
<br />    module = import_module(f"mlmodels.{model_name}")
<br />  File "/opt/hostedtoolcache/Python/3.6.12/x64/lib/python3.6/importlib/__init__.py", line 126, in import_module
<br />    return _bootstrap._gcd_import(name[level:], package, level)
<br />  File "<frozen importlib._bootstrap>", line 994, in _gcd_import
<br />  File "<frozen importlib._bootstrap>", line 971, in _find_and_load
<br />  File "<frozen importlib._bootstrap>", line 955, in _find_and_load_unlocked
<br />  File "<frozen importlib._bootstrap>", line 665, in _load_unlocked
<br />  File "<frozen importlib._bootstrap_external>", line 674, in exec_module
<br />  File "<frozen importlib._bootstrap_external>", line 781, in get_code
<br />  File "<frozen importlib._bootstrap_external>", line 741, in source_to_code
<br />  File "<frozen importlib._bootstrap>", line 219, in _call_with_frames_removed
<br />  File "https://github.com/arita37/mlmodels/tree/ff21906d63b46d89670bd3ed148b01355ca5ff0e/mlmodels/model_gluon/gluonts_model.py", line 203
<br />    if d ==  "single_dataframe" :
<br />                                ^
<br />SyntaxError: invalid syntax



### Error 28, [Traceback at line 546](https://github.com/arita37/mlmodels_store/blob/master/log_json/log_json.py#L546)<br />546..Traceback (most recent call last):
<br />  File "https://github.com/arita37/mlmodels/tree/ff21906d63b46d89670bd3ed148b01355ca5ff0e/mlmodels/models.py", line 84, in module_load
<br />    model_name = str(Path(model_uri).parts[-2]) + "." + str(model_name)
<br />IndexError: tuple index out of range



### Error 29, [Traceback at line 553](https://github.com/arita37/mlmodels_store/blob/master/log_json/log_json.py#L553)<br />553..Traceback (most recent call last):
<br />  File "/opt/hostedtoolcache/Python/3.6.12/x64/bin/ml_models", line 11, in <module>
<br />    load_entry_point('mlmodels', 'console_scripts', 'ml_models')()
<br />  File "https://github.com/arita37/mlmodels/tree/ff21906d63b46d89670bd3ed148b01355ca5ff0e/mlmodels/models.py", line 530, in main
<br />    fit_cli(arg)
<br />  File "https://github.com/arita37/mlmodels/tree/ff21906d63b46d89670bd3ed148b01355ca5ff0e/mlmodels/models.py", line 420, in fit_cli
<br />    module = module_load(model_uri)  # '1_lstm.py
<br />  File "https://github.com/arita37/mlmodels/tree/ff21906d63b46d89670bd3ed148b01355ca5ff0e/mlmodels/models.py", line 89, in module_load
<br />    raise NameError(f"Module {model_name} notfound, {e1}, {e2}")
<br />NameError: Module model_gluon notfound, invalid syntax (gluonts_model.py, line 203), tuple index out of range



### Error 30, [Traceback at line 576](https://github.com/arita37/mlmodels_store/blob/master/log_json/log_json.py#L576)<br />576..Traceback (most recent call last):
<br />  File "https://github.com/arita37/mlmodels/tree/ff21906d63b46d89670bd3ed148b01355ca5ff0e/mlmodels/models.py", line 72, in module_load
<br />    module = import_module(f"mlmodels.{model_name}")
<br />  File "/opt/hostedtoolcache/Python/3.6.12/x64/lib/python3.6/importlib/__init__.py", line 126, in import_module
<br />    return _bootstrap._gcd_import(name[level:], package, level)
<br />  File "<frozen importlib._bootstrap>", line 994, in _gcd_import
<br />  File "<frozen importlib._bootstrap>", line 971, in _find_and_load
<br />  File "<frozen importlib._bootstrap>", line 955, in _find_and_load_unlocked
<br />  File "<frozen importlib._bootstrap>", line 665, in _load_unlocked
<br />  File "<frozen importlib._bootstrap_external>", line 674, in exec_module
<br />  File "<frozen importlib._bootstrap_external>", line 781, in get_code
<br />  File "<frozen importlib._bootstrap_external>", line 741, in source_to_code
<br />  File "<frozen importlib._bootstrap>", line 219, in _call_with_frames_removed
<br />  File "https://github.com/arita37/mlmodels/tree/ff21906d63b46d89670bd3ed148b01355ca5ff0e/mlmodels/model_gluon/gluonts_model.py", line 203
<br />    if d ==  "single_dataframe" :
<br />                                ^
<br />SyntaxError: invalid syntax



### Error 31, [Traceback at line 596](https://github.com/arita37/mlmodels_store/blob/master/log_json/log_json.py#L596)<br />596..Traceback (most recent call last):
<br />  File "https://github.com/arita37/mlmodels/tree/ff21906d63b46d89670bd3ed148b01355ca5ff0e/mlmodels/models.py", line 84, in module_load
<br />    model_name = str(Path(model_uri).parts[-2]) + "." + str(model_name)
<br />IndexError: tuple index out of range



### Error 32, [Traceback at line 603](https://github.com/arita37/mlmodels_store/blob/master/log_json/log_json.py#L603)<br />603..Traceback (most recent call last):
<br />  File "/opt/hostedtoolcache/Python/3.6.12/x64/bin/ml_models", line 11, in <module>
<br />    load_entry_point('mlmodels', 'console_scripts', 'ml_models')()
<br />  File "https://github.com/arita37/mlmodels/tree/ff21906d63b46d89670bd3ed148b01355ca5ff0e/mlmodels/models.py", line 530, in main
<br />    fit_cli(arg)
<br />  File "https://github.com/arita37/mlmodels/tree/ff21906d63b46d89670bd3ed148b01355ca5ff0e/mlmodels/models.py", line 420, in fit_cli
<br />    module = module_load(model_uri)  # '1_lstm.py
<br />  File "https://github.com/arita37/mlmodels/tree/ff21906d63b46d89670bd3ed148b01355ca5ff0e/mlmodels/models.py", line 89, in module_load
<br />    raise NameError(f"Module {model_name} notfound, {e1}, {e2}")
<br />NameError: Module model_gluon notfound, invalid syntax (gluonts_model.py, line 203), tuple index out of range



### Error 33, [Traceback at line 631](https://github.com/arita37/mlmodels_store/blob/master/log_json/log_json.py#L631)<br />631..Traceback (most recent call last):
<br />  File "https://github.com/arita37/mlmodels/tree/ff21906d63b46d89670bd3ed148b01355ca5ff0e/mlmodels/models.py", line 72, in module_load
<br />    module = import_module(f"mlmodels.{model_name}")
<br />  File "/opt/hostedtoolcache/Python/3.6.12/x64/lib/python3.6/importlib/__init__.py", line 126, in import_module
<br />    return _bootstrap._gcd_import(name[level:], package, level)
<br />  File "<frozen importlib._bootstrap>", line 994, in _gcd_import
<br />  File "<frozen importlib._bootstrap>", line 971, in _find_and_load
<br />  File "<frozen importlib._bootstrap>", line 955, in _find_and_load_unlocked
<br />  File "<frozen importlib._bootstrap>", line 665, in _load_unlocked
<br />  File "<frozen importlib._bootstrap_external>", line 674, in exec_module
<br />  File "<frozen importlib._bootstrap_external>", line 781, in get_code
<br />  File "<frozen importlib._bootstrap_external>", line 741, in source_to_code
<br />  File "<frozen importlib._bootstrap>", line 219, in _call_with_frames_removed
<br />  File "https://github.com/arita37/mlmodels/tree/ff21906d63b46d89670bd3ed148b01355ca5ff0e/mlmodels/model_gluon/gluonts_model.py", line 203
<br />    if d ==  "single_dataframe" :
<br />                                ^
<br />SyntaxError: invalid syntax



### Error 34, [Traceback at line 651](https://github.com/arita37/mlmodels_store/blob/master/log_json/log_json.py#L651)<br />651..Traceback (most recent call last):
<br />  File "https://github.com/arita37/mlmodels/tree/ff21906d63b46d89670bd3ed148b01355ca5ff0e/mlmodels/models.py", line 84, in module_load
<br />    model_name = str(Path(model_uri).parts[-2]) + "." + str(model_name)
<br />IndexError: tuple index out of range



### Error 35, [Traceback at line 658](https://github.com/arita37/mlmodels_store/blob/master/log_json/log_json.py#L658)<br />658..Traceback (most recent call last):
<br />  File "/opt/hostedtoolcache/Python/3.6.12/x64/bin/ml_models", line 11, in <module>
<br />    load_entry_point('mlmodels', 'console_scripts', 'ml_models')()
<br />  File "https://github.com/arita37/mlmodels/tree/ff21906d63b46d89670bd3ed148b01355ca5ff0e/mlmodels/models.py", line 530, in main
<br />    fit_cli(arg)
<br />  File "https://github.com/arita37/mlmodels/tree/ff21906d63b46d89670bd3ed148b01355ca5ff0e/mlmodels/models.py", line 420, in fit_cli
<br />    module = module_load(model_uri)  # '1_lstm.py
<br />  File "https://github.com/arita37/mlmodels/tree/ff21906d63b46d89670bd3ed148b01355ca5ff0e/mlmodels/models.py", line 89, in module_load
<br />    raise NameError(f"Module {model_name} notfound, {e1}, {e2}")
<br />NameError: Module model_gluon notfound, invalid syntax (gluonts_model.py, line 203), tuple index out of range



### Error 36, [Traceback at line 681](https://github.com/arita37/mlmodels_store/blob/master/log_json/log_json.py#L681)<br />681..Traceback (most recent call last):
<br />  File "https://github.com/arita37/mlmodels/tree/ff21906d63b46d89670bd3ed148b01355ca5ff0e/mlmodels/models.py", line 72, in module_load
<br />    module = import_module(f"mlmodels.{model_name}")
<br />  File "/opt/hostedtoolcache/Python/3.6.12/x64/lib/python3.6/importlib/__init__.py", line 126, in import_module
<br />    return _bootstrap._gcd_import(name[level:], package, level)
<br />  File "<frozen importlib._bootstrap>", line 994, in _gcd_import
<br />  File "<frozen importlib._bootstrap>", line 971, in _find_and_load
<br />  File "<frozen importlib._bootstrap>", line 955, in _find_and_load_unlocked
<br />  File "<frozen importlib._bootstrap>", line 665, in _load_unlocked
<br />  File "<frozen importlib._bootstrap_external>", line 674, in exec_module
<br />  File "<frozen importlib._bootstrap_external>", line 781, in get_code
<br />  File "<frozen importlib._bootstrap_external>", line 741, in source_to_code
<br />  File "<frozen importlib._bootstrap>", line 219, in _call_with_frames_removed
<br />  File "https://github.com/arita37/mlmodels/tree/ff21906d63b46d89670bd3ed148b01355ca5ff0e/mlmodels/model_gluon/gluonts_model.py", line 203
<br />    if d ==  "single_dataframe" :
<br />                                ^
<br />SyntaxError: invalid syntax



### Error 37, [Traceback at line 701](https://github.com/arita37/mlmodels_store/blob/master/log_json/log_json.py#L701)<br />701..Traceback (most recent call last):
<br />  File "https://github.com/arita37/mlmodels/tree/ff21906d63b46d89670bd3ed148b01355ca5ff0e/mlmodels/models.py", line 84, in module_load
<br />    model_name = str(Path(model_uri).parts[-2]) + "." + str(model_name)
<br />IndexError: tuple index out of range



### Error 38, [Traceback at line 708](https://github.com/arita37/mlmodels_store/blob/master/log_json/log_json.py#L708)<br />708..Traceback (most recent call last):
<br />  File "/opt/hostedtoolcache/Python/3.6.12/x64/bin/ml_models", line 11, in <module>
<br />    load_entry_point('mlmodels', 'console_scripts', 'ml_models')()
<br />  File "https://github.com/arita37/mlmodels/tree/ff21906d63b46d89670bd3ed148b01355ca5ff0e/mlmodels/models.py", line 530, in main
<br />    fit_cli(arg)
<br />  File "https://github.com/arita37/mlmodels/tree/ff21906d63b46d89670bd3ed148b01355ca5ff0e/mlmodels/models.py", line 420, in fit_cli
<br />    module = module_load(model_uri)  # '1_lstm.py
<br />  File "https://github.com/arita37/mlmodels/tree/ff21906d63b46d89670bd3ed148b01355ca5ff0e/mlmodels/models.py", line 89, in module_load
<br />    raise NameError(f"Module {model_name} notfound, {e1}, {e2}")
<br />NameError: Module model_gluon notfound, invalid syntax (gluonts_model.py, line 203), tuple index out of range



### Error 39, [Traceback at line 731](https://github.com/arita37/mlmodels_store/blob/master/log_json/log_json.py#L731)<br />731..Traceback (most recent call last):
<br />  File "https://github.com/arita37/mlmodels/tree/ff21906d63b46d89670bd3ed148b01355ca5ff0e/mlmodels/models.py", line 72, in module_load
<br />    module = import_module(f"mlmodels.{model_name}")
<br />  File "/opt/hostedtoolcache/Python/3.6.12/x64/lib/python3.6/importlib/__init__.py", line 126, in import_module
<br />    return _bootstrap._gcd_import(name[level:], package, level)
<br />  File "<frozen importlib._bootstrap>", line 994, in _gcd_import
<br />  File "<frozen importlib._bootstrap>", line 971, in _find_and_load
<br />  File "<frozen importlib._bootstrap>", line 955, in _find_and_load_unlocked
<br />  File "<frozen importlib._bootstrap>", line 665, in _load_unlocked
<br />  File "<frozen importlib._bootstrap_external>", line 674, in exec_module
<br />  File "<frozen importlib._bootstrap_external>", line 781, in get_code
<br />  File "<frozen importlib._bootstrap_external>", line 741, in source_to_code
<br />  File "<frozen importlib._bootstrap>", line 219, in _call_with_frames_removed
<br />  File "https://github.com/arita37/mlmodels/tree/ff21906d63b46d89670bd3ed148b01355ca5ff0e/mlmodels/model_gluon/gluonts_model.py", line 203
<br />    if d ==  "single_dataframe" :
<br />                                ^
<br />SyntaxError: invalid syntax



### Error 40, [Traceback at line 751](https://github.com/arita37/mlmodels_store/blob/master/log_json/log_json.py#L751)<br />751..Traceback (most recent call last):
<br />  File "https://github.com/arita37/mlmodels/tree/ff21906d63b46d89670bd3ed148b01355ca5ff0e/mlmodels/models.py", line 84, in module_load
<br />    model_name = str(Path(model_uri).parts[-2]) + "." + str(model_name)
<br />IndexError: tuple index out of range



### Error 41, [Traceback at line 758](https://github.com/arita37/mlmodels_store/blob/master/log_json/log_json.py#L758)<br />758..Traceback (most recent call last):
<br />  File "/opt/hostedtoolcache/Python/3.6.12/x64/bin/ml_models", line 11, in <module>
<br />    load_entry_point('mlmodels', 'console_scripts', 'ml_models')()
<br />  File "https://github.com/arita37/mlmodels/tree/ff21906d63b46d89670bd3ed148b01355ca5ff0e/mlmodels/models.py", line 530, in main
<br />    fit_cli(arg)
<br />  File "https://github.com/arita37/mlmodels/tree/ff21906d63b46d89670bd3ed148b01355ca5ff0e/mlmodels/models.py", line 420, in fit_cli
<br />    module = module_load(model_uri)  # '1_lstm.py
<br />  File "https://github.com/arita37/mlmodels/tree/ff21906d63b46d89670bd3ed148b01355ca5ff0e/mlmodels/models.py", line 89, in module_load
<br />    raise NameError(f"Module {model_name} notfound, {e1}, {e2}")
<br />NameError: Module model_gluon notfound, invalid syntax (gluonts_model.py, line 203), tuple index out of range



### Error 42, [Traceback at line 781](https://github.com/arita37/mlmodels_store/blob/master/log_json/log_json.py#L781)<br />781..Traceback (most recent call last):
<br />  File "https://github.com/arita37/mlmodels/tree/ff21906d63b46d89670bd3ed148b01355ca5ff0e/mlmodels/models.py", line 72, in module_load
<br />    module = import_module(f"mlmodels.{model_name}")
<br />  File "/opt/hostedtoolcache/Python/3.6.12/x64/lib/python3.6/importlib/__init__.py", line 126, in import_module
<br />    return _bootstrap._gcd_import(name[level:], package, level)
<br />  File "<frozen importlib._bootstrap>", line 994, in _gcd_import
<br />  File "<frozen importlib._bootstrap>", line 971, in _find_and_load
<br />  File "<frozen importlib._bootstrap>", line 955, in _find_and_load_unlocked
<br />  File "<frozen importlib._bootstrap>", line 665, in _load_unlocked
<br />  File "<frozen importlib._bootstrap_external>", line 674, in exec_module
<br />  File "<frozen importlib._bootstrap_external>", line 781, in get_code
<br />  File "<frozen importlib._bootstrap_external>", line 741, in source_to_code
<br />  File "<frozen importlib._bootstrap>", line 219, in _call_with_frames_removed
<br />  File "https://github.com/arita37/mlmodels/tree/ff21906d63b46d89670bd3ed148b01355ca5ff0e/mlmodels/model_gluon/gluonts_model.py", line 203
<br />    if d ==  "single_dataframe" :
<br />                                ^
<br />SyntaxError: invalid syntax



### Error 43, [Traceback at line 801](https://github.com/arita37/mlmodels_store/blob/master/log_json/log_json.py#L801)<br />801..Traceback (most recent call last):
<br />  File "https://github.com/arita37/mlmodels/tree/ff21906d63b46d89670bd3ed148b01355ca5ff0e/mlmodels/models.py", line 84, in module_load
<br />    model_name = str(Path(model_uri).parts[-2]) + "." + str(model_name)
<br />IndexError: tuple index out of range



### Error 44, [Traceback at line 808](https://github.com/arita37/mlmodels_store/blob/master/log_json/log_json.py#L808)<br />808..Traceback (most recent call last):
<br />  File "/opt/hostedtoolcache/Python/3.6.12/x64/bin/ml_models", line 11, in <module>
<br />    load_entry_point('mlmodels', 'console_scripts', 'ml_models')()
<br />  File "https://github.com/arita37/mlmodels/tree/ff21906d63b46d89670bd3ed148b01355ca5ff0e/mlmodels/models.py", line 530, in main
<br />    fit_cli(arg)
<br />  File "https://github.com/arita37/mlmodels/tree/ff21906d63b46d89670bd3ed148b01355ca5ff0e/mlmodels/models.py", line 420, in fit_cli
<br />    module = module_load(model_uri)  # '1_lstm.py
<br />  File "https://github.com/arita37/mlmodels/tree/ff21906d63b46d89670bd3ed148b01355ca5ff0e/mlmodels/models.py", line 89, in module_load
<br />    raise NameError(f"Module {model_name} notfound, {e1}, {e2}")
<br />NameError: Module model_gluon notfound, invalid syntax (gluonts_model.py, line 203), tuple index out of range



### Error 45, [Traceback at line 831](https://github.com/arita37/mlmodels_store/blob/master/log_json/log_json.py#L831)<br />831..Traceback (most recent call last):
<br />  File "https://github.com/arita37/mlmodels/tree/ff21906d63b46d89670bd3ed148b01355ca5ff0e/mlmodels/models.py", line 72, in module_load
<br />    module = import_module(f"mlmodels.{model_name}")
<br />  File "/opt/hostedtoolcache/Python/3.6.12/x64/lib/python3.6/importlib/__init__.py", line 126, in import_module
<br />    return _bootstrap._gcd_import(name[level:], package, level)
<br />  File "<frozen importlib._bootstrap>", line 994, in _gcd_import
<br />  File "<frozen importlib._bootstrap>", line 971, in _find_and_load
<br />  File "<frozen importlib._bootstrap>", line 955, in _find_and_load_unlocked
<br />  File "<frozen importlib._bootstrap>", line 665, in _load_unlocked
<br />  File "<frozen importlib._bootstrap_external>", line 674, in exec_module
<br />  File "<frozen importlib._bootstrap_external>", line 781, in get_code
<br />  File "<frozen importlib._bootstrap_external>", line 741, in source_to_code
<br />  File "<frozen importlib._bootstrap>", line 219, in _call_with_frames_removed
<br />  File "https://github.com/arita37/mlmodels/tree/ff21906d63b46d89670bd3ed148b01355ca5ff0e/mlmodels/model_gluon/gluonts_model.py", line 203
<br />    if d ==  "single_dataframe" :
<br />                                ^
<br />SyntaxError: invalid syntax



### Error 46, [Traceback at line 851](https://github.com/arita37/mlmodels_store/blob/master/log_json/log_json.py#L851)<br />851..Traceback (most recent call last):
<br />  File "https://github.com/arita37/mlmodels/tree/ff21906d63b46d89670bd3ed148b01355ca5ff0e/mlmodels/models.py", line 84, in module_load
<br />    model_name = str(Path(model_uri).parts[-2]) + "." + str(model_name)
<br />IndexError: tuple index out of range



### Error 47, [Traceback at line 858](https://github.com/arita37/mlmodels_store/blob/master/log_json/log_json.py#L858)<br />858..Traceback (most recent call last):
<br />  File "/opt/hostedtoolcache/Python/3.6.12/x64/bin/ml_models", line 11, in <module>
<br />    load_entry_point('mlmodels', 'console_scripts', 'ml_models')()
<br />  File "https://github.com/arita37/mlmodels/tree/ff21906d63b46d89670bd3ed148b01355ca5ff0e/mlmodels/models.py", line 530, in main
<br />    fit_cli(arg)
<br />  File "https://github.com/arita37/mlmodels/tree/ff21906d63b46d89670bd3ed148b01355ca5ff0e/mlmodels/models.py", line 420, in fit_cli
<br />    module = module_load(model_uri)  # '1_lstm.py
<br />  File "https://github.com/arita37/mlmodels/tree/ff21906d63b46d89670bd3ed148b01355ca5ff0e/mlmodels/models.py", line 89, in module_load
<br />    raise NameError(f"Module {model_name} notfound, {e1}, {e2}")
<br />NameError: Module model_gluon notfound, invalid syntax (gluonts_model.py, line 203), tuple index out of range



### Error 48, [Traceback at line 881](https://github.com/arita37/mlmodels_store/blob/master/log_json/log_json.py#L881)<br />881..Traceback (most recent call last):
<br />  File "https://github.com/arita37/mlmodels/tree/ff21906d63b46d89670bd3ed148b01355ca5ff0e/mlmodels/models.py", line 72, in module_load
<br />    module = import_module(f"mlmodels.{model_name}")
<br />  File "/opt/hostedtoolcache/Python/3.6.12/x64/lib/python3.6/importlib/__init__.py", line 126, in import_module
<br />    return _bootstrap._gcd_import(name[level:], package, level)
<br />  File "<frozen importlib._bootstrap>", line 994, in _gcd_import
<br />  File "<frozen importlib._bootstrap>", line 971, in _find_and_load
<br />  File "<frozen importlib._bootstrap>", line 955, in _find_and_load_unlocked
<br />  File "<frozen importlib._bootstrap>", line 665, in _load_unlocked
<br />  File "<frozen importlib._bootstrap_external>", line 674, in exec_module
<br />  File "<frozen importlib._bootstrap_external>", line 781, in get_code
<br />  File "<frozen importlib._bootstrap_external>", line 741, in source_to_code
<br />  File "<frozen importlib._bootstrap>", line 219, in _call_with_frames_removed
<br />  File "https://github.com/arita37/mlmodels/tree/ff21906d63b46d89670bd3ed148b01355ca5ff0e/mlmodels/model_gluon/gluonts_model.py", line 203
<br />    if d ==  "single_dataframe" :
<br />                                ^
<br />SyntaxError: invalid syntax



### Error 49, [Traceback at line 901](https://github.com/arita37/mlmodels_store/blob/master/log_json/log_json.py#L901)<br />901..Traceback (most recent call last):
<br />  File "https://github.com/arita37/mlmodels/tree/ff21906d63b46d89670bd3ed148b01355ca5ff0e/mlmodels/models.py", line 84, in module_load
<br />    model_name = str(Path(model_uri).parts[-2]) + "." + str(model_name)
<br />IndexError: tuple index out of range



### Error 50, [Traceback at line 908](https://github.com/arita37/mlmodels_store/blob/master/log_json/log_json.py#L908)<br />908..Traceback (most recent call last):
<br />  File "/opt/hostedtoolcache/Python/3.6.12/x64/bin/ml_models", line 11, in <module>
<br />    load_entry_point('mlmodels', 'console_scripts', 'ml_models')()
<br />  File "https://github.com/arita37/mlmodels/tree/ff21906d63b46d89670bd3ed148b01355ca5ff0e/mlmodels/models.py", line 530, in main
<br />    fit_cli(arg)
<br />  File "https://github.com/arita37/mlmodels/tree/ff21906d63b46d89670bd3ed148b01355ca5ff0e/mlmodels/models.py", line 420, in fit_cli
<br />    module = module_load(model_uri)  # '1_lstm.py
<br />  File "https://github.com/arita37/mlmodels/tree/ff21906d63b46d89670bd3ed148b01355ca5ff0e/mlmodels/models.py", line 89, in module_load
<br />    raise NameError(f"Module {model_name} notfound, {e1}, {e2}")
<br />NameError: Module model_gluon notfound, invalid syntax (gluonts_model.py, line 203), tuple index out of range



### Error 51, [Traceback at line 931](https://github.com/arita37/mlmodels_store/blob/master/log_json/log_json.py#L931)<br />931..Traceback (most recent call last):
<br />  File "https://github.com/arita37/mlmodels/tree/ff21906d63b46d89670bd3ed148b01355ca5ff0e/mlmodels/models.py", line 72, in module_load
<br />    module = import_module(f"mlmodels.{model_name}")
<br />  File "/opt/hostedtoolcache/Python/3.6.12/x64/lib/python3.6/importlib/__init__.py", line 126, in import_module
<br />    return _bootstrap._gcd_import(name[level:], package, level)
<br />  File "<frozen importlib._bootstrap>", line 994, in _gcd_import
<br />  File "<frozen importlib._bootstrap>", line 971, in _find_and_load
<br />  File "<frozen importlib._bootstrap>", line 955, in _find_and_load_unlocked
<br />  File "<frozen importlib._bootstrap>", line 665, in _load_unlocked
<br />  File "<frozen importlib._bootstrap_external>", line 674, in exec_module
<br />  File "<frozen importlib._bootstrap_external>", line 781, in get_code
<br />  File "<frozen importlib._bootstrap_external>", line 741, in source_to_code
<br />  File "<frozen importlib._bootstrap>", line 219, in _call_with_frames_removed
<br />  File "https://github.com/arita37/mlmodels/tree/ff21906d63b46d89670bd3ed148b01355ca5ff0e/mlmodels/model_gluon/gluonts_model.py", line 203
<br />    if d ==  "single_dataframe" :
<br />                                ^
<br />SyntaxError: invalid syntax



### Error 52, [Traceback at line 951](https://github.com/arita37/mlmodels_store/blob/master/log_json/log_json.py#L951)<br />951..Traceback (most recent call last):
<br />  File "https://github.com/arita37/mlmodels/tree/ff21906d63b46d89670bd3ed148b01355ca5ff0e/mlmodels/models.py", line 84, in module_load
<br />    model_name = str(Path(model_uri).parts[-2]) + "." + str(model_name)
<br />IndexError: tuple index out of range



### Error 53, [Traceback at line 958](https://github.com/arita37/mlmodels_store/blob/master/log_json/log_json.py#L958)<br />958..Traceback (most recent call last):
<br />  File "/opt/hostedtoolcache/Python/3.6.12/x64/bin/ml_models", line 11, in <module>
<br />    load_entry_point('mlmodels', 'console_scripts', 'ml_models')()
<br />  File "https://github.com/arita37/mlmodels/tree/ff21906d63b46d89670bd3ed148b01355ca5ff0e/mlmodels/models.py", line 530, in main
<br />    fit_cli(arg)
<br />  File "https://github.com/arita37/mlmodels/tree/ff21906d63b46d89670bd3ed148b01355ca5ff0e/mlmodels/models.py", line 420, in fit_cli
<br />    module = module_load(model_uri)  # '1_lstm.py
<br />  File "https://github.com/arita37/mlmodels/tree/ff21906d63b46d89670bd3ed148b01355ca5ff0e/mlmodels/models.py", line 89, in module_load
<br />    raise NameError(f"Module {model_name} notfound, {e1}, {e2}")
<br />NameError: Module model_gluon notfound, invalid syntax (gluonts_model.py, line 203), tuple index out of range



### Error 54, [Traceback at line 981](https://github.com/arita37/mlmodels_store/blob/master/log_json/log_json.py#L981)<br />981..Traceback (most recent call last):
<br />  File "https://github.com/arita37/mlmodels/tree/ff21906d63b46d89670bd3ed148b01355ca5ff0e/mlmodels/models.py", line 72, in module_load
<br />    module = import_module(f"mlmodels.{model_name}")
<br />  File "/opt/hostedtoolcache/Python/3.6.12/x64/lib/python3.6/importlib/__init__.py", line 126, in import_module
<br />    return _bootstrap._gcd_import(name[level:], package, level)
<br />  File "<frozen importlib._bootstrap>", line 994, in _gcd_import
<br />  File "<frozen importlib._bootstrap>", line 971, in _find_and_load
<br />  File "<frozen importlib._bootstrap>", line 955, in _find_and_load_unlocked
<br />  File "<frozen importlib._bootstrap>", line 665, in _load_unlocked
<br />  File "<frozen importlib._bootstrap_external>", line 674, in exec_module
<br />  File "<frozen importlib._bootstrap_external>", line 781, in get_code
<br />  File "<frozen importlib._bootstrap_external>", line 741, in source_to_code
<br />  File "<frozen importlib._bootstrap>", line 219, in _call_with_frames_removed
<br />  File "https://github.com/arita37/mlmodels/tree/ff21906d63b46d89670bd3ed148b01355ca5ff0e/mlmodels/model_gluon/gluonts_model.py", line 203
<br />    if d ==  "single_dataframe" :
<br />                                ^
<br />SyntaxError: invalid syntax



### Error 55, [Traceback at line 1001](https://github.com/arita37/mlmodels_store/blob/master/log_json/log_json.py#L1001)<br />1001..Traceback (most recent call last):
<br />  File "https://github.com/arita37/mlmodels/tree/ff21906d63b46d89670bd3ed148b01355ca5ff0e/mlmodels/models.py", line 84, in module_load
<br />    model_name = str(Path(model_uri).parts[-2]) + "." + str(model_name)
<br />IndexError: tuple index out of range



### Error 56, [Traceback at line 1008](https://github.com/arita37/mlmodels_store/blob/master/log_json/log_json.py#L1008)<br />1008..Traceback (most recent call last):
<br />  File "/opt/hostedtoolcache/Python/3.6.12/x64/bin/ml_models", line 11, in <module>
<br />    load_entry_point('mlmodels', 'console_scripts', 'ml_models')()
<br />  File "https://github.com/arita37/mlmodels/tree/ff21906d63b46d89670bd3ed148b01355ca5ff0e/mlmodels/models.py", line 530, in main
<br />    fit_cli(arg)
<br />  File "https://github.com/arita37/mlmodels/tree/ff21906d63b46d89670bd3ed148b01355ca5ff0e/mlmodels/models.py", line 420, in fit_cli
<br />    module = module_load(model_uri)  # '1_lstm.py
<br />  File "https://github.com/arita37/mlmodels/tree/ff21906d63b46d89670bd3ed148b01355ca5ff0e/mlmodels/models.py", line 89, in module_load
<br />    raise NameError(f"Module {model_name} notfound, {e1}, {e2}")
<br />NameError: Module model_gluon notfound, invalid syntax (gluonts_model.py, line 203), tuple index out of range



### Error 57, [Traceback at line 1034](https://github.com/arita37/mlmodels_store/blob/master/log_json/log_json.py#L1034)<br />1034..Traceback (most recent call last):
<br />  File "/opt/hostedtoolcache/Python/3.6.12/x64/bin/ml_models", line 11, in <module>
<br />    load_entry_point('mlmodels', 'console_scripts', 'ml_models')()
<br />  File "https://github.com/arita37/mlmodels/tree/ff21906d63b46d89670bd3ed148b01355ca5ff0e/mlmodels/models.py", line 530, in main
<br />    fit_cli(arg)
<br />  File "https://github.com/arita37/mlmodels/tree/ff21906d63b46d89670bd3ed148b01355ca5ff0e/mlmodels/models.py", line 414, in fit_cli
<br />    model_uri = model_p['model_uri']
<br />KeyError: 'model_uri'



### Error 58, [Traceback at line 1058](https://github.com/arita37/mlmodels_store/blob/master/log_json/log_json.py#L1058)<br />1058..Traceback (most recent call last):
<br />  File "/opt/hostedtoolcache/Python/3.6.12/x64/bin/ml_models", line 11, in <module>
<br />    load_entry_point('mlmodels', 'console_scripts', 'ml_models')()
<br />  File "https://github.com/arita37/mlmodels/tree/ff21906d63b46d89670bd3ed148b01355ca5ff0e/mlmodels/models.py", line 530, in main
<br />    fit_cli(arg)
<br />  File "https://github.com/arita37/mlmodels/tree/ff21906d63b46d89670bd3ed148b01355ca5ff0e/mlmodels/models.py", line 414, in fit_cli
<br />    model_uri = model_p['model_uri']
<br />KeyError: 'model_uri'



### Error 59, [Traceback at line 1082](https://github.com/arita37/mlmodels_store/blob/master/log_json/log_json.py#L1082)<br />1082..Traceback (most recent call last):
<br />  File "/opt/hostedtoolcache/Python/3.6.12/x64/bin/ml_models", line 11, in <module>
<br />    load_entry_point('mlmodels', 'console_scripts', 'ml_models')()
<br />  File "https://github.com/arita37/mlmodels/tree/ff21906d63b46d89670bd3ed148b01355ca5ff0e/mlmodels/models.py", line 530, in main
<br />    fit_cli(arg)
<br />  File "https://github.com/arita37/mlmodels/tree/ff21906d63b46d89670bd3ed148b01355ca5ff0e/mlmodels/models.py", line 414, in fit_cli
<br />    model_uri = model_p['model_uri']
<br />KeyError: 'model_uri'



### Error 60, [Traceback at line 1106](https://github.com/arita37/mlmodels_store/blob/master/log_json/log_json.py#L1106)<br />1106..Traceback (most recent call last):
<br />  File "/opt/hostedtoolcache/Python/3.6.12/x64/bin/ml_models", line 11, in <module>
<br />    load_entry_point('mlmodels', 'console_scripts', 'ml_models')()
<br />  File "https://github.com/arita37/mlmodels/tree/ff21906d63b46d89670bd3ed148b01355ca5ff0e/mlmodels/models.py", line 530, in main
<br />    fit_cli(arg)
<br />  File "https://github.com/arita37/mlmodels/tree/ff21906d63b46d89670bd3ed148b01355ca5ff0e/mlmodels/models.py", line 414, in fit_cli
<br />    model_uri = model_p['model_uri']
<br />KeyError: 'model_uri'



### Error 61, [Traceback at line 1130](https://github.com/arita37/mlmodels_store/blob/master/log_json/log_json.py#L1130)<br />1130..Traceback (most recent call last):
<br />  File "/opt/hostedtoolcache/Python/3.6.12/x64/bin/ml_models", line 11, in <module>
<br />    load_entry_point('mlmodels', 'console_scripts', 'ml_models')()
<br />  File "https://github.com/arita37/mlmodels/tree/ff21906d63b46d89670bd3ed148b01355ca5ff0e/mlmodels/models.py", line 530, in main
<br />    fit_cli(arg)
<br />  File "https://github.com/arita37/mlmodels/tree/ff21906d63b46d89670bd3ed148b01355ca5ff0e/mlmodels/models.py", line 414, in fit_cli
<br />    model_uri = model_p['model_uri']
<br />KeyError: 'model_uri'



### Error 62, [Traceback at line 1149](https://github.com/arita37/mlmodels_store/blob/master/log_json/log_json.py#L1149)<br />1149..Traceback (most recent call last):
<br />  File "/opt/hostedtoolcache/Python/3.6.12/x64/bin/ml_models", line 11, in <module>
<br />    load_entry_point('mlmodels', 'console_scripts', 'ml_models')()
<br />  File "https://github.com/arita37/mlmodels/tree/ff21906d63b46d89670bd3ed148b01355ca5ff0e/mlmodels/models.py", line 530, in main
<br />    fit_cli(arg)
<br />  File "https://github.com/arita37/mlmodels/tree/ff21906d63b46d89670bd3ed148b01355ca5ff0e/mlmodels/models.py", line 413, in fit_cli
<br />    model_p, data_p, compute_p, out_p = config_get_pars(config_file, arg.config_mode)
<br />  File "https://github.com/arita37/mlmodels/tree/ff21906d63b46d89670bd3ed148b01355ca5ff0e/mlmodels/models.py", line 299, in config_get_pars
<br />    out_p     = path_norm_dict( js.get("out_pars") )
<br />  File "https://github.com/arita37/mlmodels/tree/ff21906d63b46d89670bd3ed148b01355ca5ff0e/mlmodels/util.py", line 201, in path_norm_dict
<br />    for k,v in ddict.items():
<br />AttributeError: 'NoneType' object has no attribute 'items'



### Error 63, [Traceback at line 1177](https://github.com/arita37/mlmodels_store/blob/master/log_json/log_json.py#L1177)<br />1177..Traceback (most recent call last):
<br />  File "/opt/hostedtoolcache/Python/3.6.12/x64/bin/ml_models", line 11, in <module>
<br />    load_entry_point('mlmodels', 'console_scripts', 'ml_models')()
<br />  File "https://github.com/arita37/mlmodels/tree/ff21906d63b46d89670bd3ed148b01355ca5ff0e/mlmodels/models.py", line 530, in main
<br />    fit_cli(arg)
<br />  File "https://github.com/arita37/mlmodels/tree/ff21906d63b46d89670bd3ed148b01355ca5ff0e/mlmodels/models.py", line 414, in fit_cli
<br />    model_uri = model_p['model_uri']
<br />KeyError: 'model_uri'



### Error 64, [Traceback at line 1201](https://github.com/arita37/mlmodels_store/blob/master/log_json/log_json.py#L1201)<br />1201..Traceback (most recent call last):
<br />  File "/opt/hostedtoolcache/Python/3.6.12/x64/bin/ml_models", line 11, in <module>
<br />    load_entry_point('mlmodels', 'console_scripts', 'ml_models')()
<br />  File "https://github.com/arita37/mlmodels/tree/ff21906d63b46d89670bd3ed148b01355ca5ff0e/mlmodels/models.py", line 530, in main
<br />    fit_cli(arg)
<br />  File "https://github.com/arita37/mlmodels/tree/ff21906d63b46d89670bd3ed148b01355ca5ff0e/mlmodels/models.py", line 414, in fit_cli
<br />    model_uri = model_p['model_uri']
<br />KeyError: 'model_uri'



### Error 65, [Traceback at line 1220](https://github.com/arita37/mlmodels_store/blob/master/log_json/log_json.py#L1220)<br />1220..Traceback (most recent call last):
<br />  File "/opt/hostedtoolcache/Python/3.6.12/x64/bin/ml_models", line 11, in <module>
<br />    load_entry_point('mlmodels', 'console_scripts', 'ml_models')()
<br />  File "https://github.com/arita37/mlmodels/tree/ff21906d63b46d89670bd3ed148b01355ca5ff0e/mlmodels/models.py", line 530, in main
<br />    fit_cli(arg)
<br />  File "https://github.com/arita37/mlmodels/tree/ff21906d63b46d89670bd3ed148b01355ca5ff0e/mlmodels/models.py", line 413, in fit_cli
<br />    model_p, data_p, compute_p, out_p = config_get_pars(config_file, arg.config_mode)
<br />  File "https://github.com/arita37/mlmodels/tree/ff21906d63b46d89670bd3ed148b01355ca5ff0e/mlmodels/models.py", line 299, in config_get_pars
<br />    out_p     = path_norm_dict( js.get("out_pars") )
<br />  File "https://github.com/arita37/mlmodels/tree/ff21906d63b46d89670bd3ed148b01355ca5ff0e/mlmodels/util.py", line 201, in path_norm_dict
<br />    for k,v in ddict.items():
<br />AttributeError: 'NoneType' object has no attribute 'items'



### Error 66, [Traceback at line 1248](https://github.com/arita37/mlmodels_store/blob/master/log_json/log_json.py#L1248)<br />1248..Traceback (most recent call last):
<br />  File "/opt/hostedtoolcache/Python/3.6.12/x64/bin/ml_models", line 11, in <module>
<br />    load_entry_point('mlmodels', 'console_scripts', 'ml_models')()
<br />  File "https://github.com/arita37/mlmodels/tree/ff21906d63b46d89670bd3ed148b01355ca5ff0e/mlmodels/models.py", line 530, in main
<br />    fit_cli(arg)
<br />  File "https://github.com/arita37/mlmodels/tree/ff21906d63b46d89670bd3ed148b01355ca5ff0e/mlmodels/models.py", line 415, in fit_cli
<br />    path      = out_p['path']
<br />KeyError: 'path'



### Error 67, [Traceback at line 1272](https://github.com/arita37/mlmodels_store/blob/master/log_json/log_json.py#L1272)<br />1272..Traceback (most recent call last):
<br />  File "/opt/hostedtoolcache/Python/3.6.12/x64/bin/ml_models", line 11, in <module>
<br />    load_entry_point('mlmodels', 'console_scripts', 'ml_models')()
<br />  File "https://github.com/arita37/mlmodels/tree/ff21906d63b46d89670bd3ed148b01355ca5ff0e/mlmodels/models.py", line 530, in main
<br />    fit_cli(arg)
<br />  File "https://github.com/arita37/mlmodels/tree/ff21906d63b46d89670bd3ed148b01355ca5ff0e/mlmodels/models.py", line 414, in fit_cli
<br />    model_uri = model_p['model_uri']
<br />KeyError: 'model_uri'



### Error 68, [Traceback at line 1291](https://github.com/arita37/mlmodels_store/blob/master/log_json/log_json.py#L1291)<br />1291..Traceback (most recent call last):
<br />  File "/opt/hostedtoolcache/Python/3.6.12/x64/bin/ml_models", line 11, in <module>
<br />    load_entry_point('mlmodels', 'console_scripts', 'ml_models')()
<br />  File "https://github.com/arita37/mlmodels/tree/ff21906d63b46d89670bd3ed148b01355ca5ff0e/mlmodels/models.py", line 530, in main
<br />    fit_cli(arg)
<br />  File "https://github.com/arita37/mlmodels/tree/ff21906d63b46d89670bd3ed148b01355ca5ff0e/mlmodels/models.py", line 413, in fit_cli
<br />    model_p, data_p, compute_p, out_p = config_get_pars(config_file, arg.config_mode)
<br />  File "https://github.com/arita37/mlmodels/tree/ff21906d63b46d89670bd3ed148b01355ca5ff0e/mlmodels/models.py", line 297, in config_get_pars
<br />    data_p    = path_norm_dict( js.get("data_pars") )
<br />  File "https://github.com/arita37/mlmodels/tree/ff21906d63b46d89670bd3ed148b01355ca5ff0e/mlmodels/util.py", line 201, in path_norm_dict
<br />    for k,v in ddict.items():
<br />AttributeError: 'NoneType' object has no attribute 'items'



### Error 69, [Traceback at line 1319](https://github.com/arita37/mlmodels_store/blob/master/log_json/log_json.py#L1319)<br />1319..Traceback (most recent call last):
<br />  File "/opt/hostedtoolcache/Python/3.6.12/x64/bin/ml_models", line 11, in <module>
<br />    load_entry_point('mlmodels', 'console_scripts', 'ml_models')()
<br />  File "https://github.com/arita37/mlmodels/tree/ff21906d63b46d89670bd3ed148b01355ca5ff0e/mlmodels/models.py", line 530, in main
<br />    fit_cli(arg)
<br />  File "https://github.com/arita37/mlmodels/tree/ff21906d63b46d89670bd3ed148b01355ca5ff0e/mlmodels/models.py", line 414, in fit_cli
<br />    model_uri = model_p['model_uri']
<br />KeyError: 'model_uri'



### Error 70, [Traceback at line 1338](https://github.com/arita37/mlmodels_store/blob/master/log_json/log_json.py#L1338)<br />1338..Traceback (most recent call last):
<br />  File "/opt/hostedtoolcache/Python/3.6.12/x64/bin/ml_models", line 11, in <module>
<br />    load_entry_point('mlmodels', 'console_scripts', 'ml_models')()
<br />  File "https://github.com/arita37/mlmodels/tree/ff21906d63b46d89670bd3ed148b01355ca5ff0e/mlmodels/models.py", line 530, in main
<br />    fit_cli(arg)
<br />  File "https://github.com/arita37/mlmodels/tree/ff21906d63b46d89670bd3ed148b01355ca5ff0e/mlmodels/models.py", line 413, in fit_cli
<br />    model_p, data_p, compute_p, out_p = config_get_pars(config_file, arg.config_mode)
<br />  File "https://github.com/arita37/mlmodels/tree/ff21906d63b46d89670bd3ed148b01355ca5ff0e/mlmodels/models.py", line 299, in config_get_pars
<br />    out_p     = path_norm_dict( js.get("out_pars") )
<br />  File "https://github.com/arita37/mlmodels/tree/ff21906d63b46d89670bd3ed148b01355ca5ff0e/mlmodels/util.py", line 201, in path_norm_dict
<br />    for k,v in ddict.items():
<br />AttributeError: 'NoneType' object has no attribute 'items'



### Error 71, [Traceback at line 1366](https://github.com/arita37/mlmodels_store/blob/master/log_json/log_json.py#L1366)<br />1366..Traceback (most recent call last):
<br />  File "/opt/hostedtoolcache/Python/3.6.12/x64/bin/ml_models", line 11, in <module>
<br />    load_entry_point('mlmodels', 'console_scripts', 'ml_models')()
<br />  File "https://github.com/arita37/mlmodels/tree/ff21906d63b46d89670bd3ed148b01355ca5ff0e/mlmodels/models.py", line 530, in main
<br />    fit_cli(arg)
<br />  File "https://github.com/arita37/mlmodels/tree/ff21906d63b46d89670bd3ed148b01355ca5ff0e/mlmodels/models.py", line 414, in fit_cli
<br />    model_uri = model_p['model_uri']
<br />KeyError: 'model_uri'



### Error 72, [Traceback at line 1385](https://github.com/arita37/mlmodels_store/blob/master/log_json/log_json.py#L1385)<br />1385..Traceback (most recent call last):
<br />  File "/opt/hostedtoolcache/Python/3.6.12/x64/bin/ml_models", line 11, in <module>
<br />    load_entry_point('mlmodels', 'console_scripts', 'ml_models')()
<br />  File "https://github.com/arita37/mlmodels/tree/ff21906d63b46d89670bd3ed148b01355ca5ff0e/mlmodels/models.py", line 530, in main
<br />    fit_cli(arg)
<br />  File "https://github.com/arita37/mlmodels/tree/ff21906d63b46d89670bd3ed148b01355ca5ff0e/mlmodels/models.py", line 413, in fit_cli
<br />    model_p, data_p, compute_p, out_p = config_get_pars(config_file, arg.config_mode)
<br />  File "https://github.com/arita37/mlmodels/tree/ff21906d63b46d89670bd3ed148b01355ca5ff0e/mlmodels/models.py", line 299, in config_get_pars
<br />    out_p     = path_norm_dict( js.get("out_pars") )
<br />  File "https://github.com/arita37/mlmodels/tree/ff21906d63b46d89670bd3ed148b01355ca5ff0e/mlmodels/util.py", line 201, in path_norm_dict
<br />    for k,v in ddict.items():
<br />AttributeError: 'NoneType' object has no attribute 'items'



### Error 73, [Traceback at line 1415](https://github.com/arita37/mlmodels_store/blob/master/log_json/log_json.py#L1415)<br />1415..Traceback (most recent call last):
<br />  File "/opt/hostedtoolcache/Python/3.6.12/x64/bin/ml_models", line 11, in <module>
<br />    load_entry_point('mlmodels', 'console_scripts', 'ml_models')()
<br />  File "https://github.com/arita37/mlmodels/tree/ff21906d63b46d89670bd3ed148b01355ca5ff0e/mlmodels/models.py", line 530, in main
<br />    fit_cli(arg)
<br />  File "https://github.com/arita37/mlmodels/tree/ff21906d63b46d89670bd3ed148b01355ca5ff0e/mlmodels/models.py", line 421, in fit_cli
<br />    model = model_create(module, model_p, data_p, compute_p)  # Exact map JSON and paramters
<br />  File "https://github.com/arita37/mlmodels/tree/ff21906d63b46d89670bd3ed148b01355ca5ff0e/mlmodels/models.py", line 113, in model_create
<br />    module.init(model_pars=model_pars, data_pars=data_pars, compute_pars=compute_pars, **kwarg)
<br />AttributeError: module 'mlmodels.model_tch.torchhub' has no attribute 'init'



### Error 74, [Traceback at line 1436](https://github.com/arita37/mlmodels_store/blob/master/log_json/log_json.py#L1436)<br />1436..Traceback (most recent call last):
<br />  File "/opt/hostedtoolcache/Python/3.6.12/x64/bin/ml_models", line 11, in <module>
<br />    load_entry_point('mlmodels', 'console_scripts', 'ml_models')()
<br />  File "https://github.com/arita37/mlmodels/tree/ff21906d63b46d89670bd3ed148b01355ca5ff0e/mlmodels/models.py", line 530, in main
<br />    fit_cli(arg)
<br />  File "https://github.com/arita37/mlmodels/tree/ff21906d63b46d89670bd3ed148b01355ca5ff0e/mlmodels/models.py", line 413, in fit_cli
<br />    model_p, data_p, compute_p, out_p = config_get_pars(config_file, arg.config_mode)
<br />  File "https://github.com/arita37/mlmodels/tree/ff21906d63b46d89670bd3ed148b01355ca5ff0e/mlmodels/models.py", line 299, in config_get_pars
<br />    out_p     = path_norm_dict( js.get("out_pars") )
<br />  File "https://github.com/arita37/mlmodels/tree/ff21906d63b46d89670bd3ed148b01355ca5ff0e/mlmodels/util.py", line 201, in path_norm_dict
<br />    for k,v in ddict.items():
<br />AttributeError: 'NoneType' object has no attribute 'items'



### Error 75, [Traceback at line 1466](https://github.com/arita37/mlmodels_store/blob/master/log_json/log_json.py#L1466)<br />1466..Traceback (most recent call last):
<br />  File "/opt/hostedtoolcache/Python/3.6.12/x64/bin/ml_models", line 11, in <module>
<br />    load_entry_point('mlmodels', 'console_scripts', 'ml_models')()
<br />  File "https://github.com/arita37/mlmodels/tree/ff21906d63b46d89670bd3ed148b01355ca5ff0e/mlmodels/models.py", line 530, in main
<br />    fit_cli(arg)
<br />  File "https://github.com/arita37/mlmodels/tree/ff21906d63b46d89670bd3ed148b01355ca5ff0e/mlmodels/models.py", line 421, in fit_cli
<br />    model = model_create(module, model_p, data_p, compute_p)  # Exact map JSON and paramters
<br />  File "https://github.com/arita37/mlmodels/tree/ff21906d63b46d89670bd3ed148b01355ca5ff0e/mlmodels/models.py", line 113, in model_create
<br />    module.init(model_pars=model_pars, data_pars=data_pars, compute_pars=compute_pars, **kwarg)
<br />AttributeError: module 'mlmodels.model_tch.torchhub' has no attribute 'init'



### Error 76, [Traceback at line 1487](https://github.com/arita37/mlmodels_store/blob/master/log_json/log_json.py#L1487)<br />1487..Traceback (most recent call last):
<br />  File "/opt/hostedtoolcache/Python/3.6.12/x64/bin/ml_models", line 11, in <module>
<br />    load_entry_point('mlmodels', 'console_scripts', 'ml_models')()
<br />  File "https://github.com/arita37/mlmodels/tree/ff21906d63b46d89670bd3ed148b01355ca5ff0e/mlmodels/models.py", line 530, in main
<br />    fit_cli(arg)
<br />  File "https://github.com/arita37/mlmodels/tree/ff21906d63b46d89670bd3ed148b01355ca5ff0e/mlmodels/models.py", line 413, in fit_cli
<br />    model_p, data_p, compute_p, out_p = config_get_pars(config_file, arg.config_mode)
<br />  File "https://github.com/arita37/mlmodels/tree/ff21906d63b46d89670bd3ed148b01355ca5ff0e/mlmodels/models.py", line 299, in config_get_pars
<br />    out_p     = path_norm_dict( js.get("out_pars") )
<br />  File "https://github.com/arita37/mlmodels/tree/ff21906d63b46d89670bd3ed148b01355ca5ff0e/mlmodels/util.py", line 201, in path_norm_dict
<br />    for k,v in ddict.items():
<br />AttributeError: 'NoneType' object has no attribute 'items'



### Error 77, [Traceback at line 1517](https://github.com/arita37/mlmodels_store/blob/master/log_json/log_json.py#L1517)<br />1517..Traceback (most recent call last):
<br />  File "/opt/hostedtoolcache/Python/3.6.12/x64/bin/ml_models", line 11, in <module>
<br />    load_entry_point('mlmodels', 'console_scripts', 'ml_models')()
<br />  File "https://github.com/arita37/mlmodels/tree/ff21906d63b46d89670bd3ed148b01355ca5ff0e/mlmodels/models.py", line 530, in main
<br />    fit_cli(arg)
<br />  File "https://github.com/arita37/mlmodels/tree/ff21906d63b46d89670bd3ed148b01355ca5ff0e/mlmodels/models.py", line 421, in fit_cli
<br />    model = model_create(module, model_p, data_p, compute_p)  # Exact map JSON and paramters
<br />  File "https://github.com/arita37/mlmodels/tree/ff21906d63b46d89670bd3ed148b01355ca5ff0e/mlmodels/models.py", line 113, in model_create
<br />    module.init(model_pars=model_pars, data_pars=data_pars, compute_pars=compute_pars, **kwarg)
<br />AttributeError: module 'mlmodels.model_tch.torchhub' has no attribute 'init'



### Error 78, [Traceback at line 1538](https://github.com/arita37/mlmodels_store/blob/master/log_json/log_json.py#L1538)<br />1538..Traceback (most recent call last):
<br />  File "/opt/hostedtoolcache/Python/3.6.12/x64/bin/ml_models", line 11, in <module>
<br />    load_entry_point('mlmodels', 'console_scripts', 'ml_models')()
<br />  File "https://github.com/arita37/mlmodels/tree/ff21906d63b46d89670bd3ed148b01355ca5ff0e/mlmodels/models.py", line 530, in main
<br />    fit_cli(arg)
<br />  File "https://github.com/arita37/mlmodels/tree/ff21906d63b46d89670bd3ed148b01355ca5ff0e/mlmodels/models.py", line 413, in fit_cli
<br />    model_p, data_p, compute_p, out_p = config_get_pars(config_file, arg.config_mode)
<br />  File "https://github.com/arita37/mlmodels/tree/ff21906d63b46d89670bd3ed148b01355ca5ff0e/mlmodels/models.py", line 299, in config_get_pars
<br />    out_p     = path_norm_dict( js.get("out_pars") )
<br />  File "https://github.com/arita37/mlmodels/tree/ff21906d63b46d89670bd3ed148b01355ca5ff0e/mlmodels/util.py", line 201, in path_norm_dict
<br />    for k,v in ddict.items():
<br />AttributeError: 'NoneType' object has no attribute 'items'



### Error 79, [Traceback at line 1568](https://github.com/arita37/mlmodels_store/blob/master/log_json/log_json.py#L1568)<br />1568..Traceback (most recent call last):
<br />  File "/opt/hostedtoolcache/Python/3.6.12/x64/bin/ml_models", line 11, in <module>
<br />    load_entry_point('mlmodels', 'console_scripts', 'ml_models')()
<br />  File "https://github.com/arita37/mlmodels/tree/ff21906d63b46d89670bd3ed148b01355ca5ff0e/mlmodels/models.py", line 530, in main
<br />    fit_cli(arg)
<br />  File "https://github.com/arita37/mlmodels/tree/ff21906d63b46d89670bd3ed148b01355ca5ff0e/mlmodels/models.py", line 421, in fit_cli
<br />    model = model_create(module, model_p, data_p, compute_p)  # Exact map JSON and paramters
<br />  File "https://github.com/arita37/mlmodels/tree/ff21906d63b46d89670bd3ed148b01355ca5ff0e/mlmodels/models.py", line 113, in model_create
<br />    module.init(model_pars=model_pars, data_pars=data_pars, compute_pars=compute_pars, **kwarg)
<br />AttributeError: module 'mlmodels.model_tch.torchhub' has no attribute 'init'



### Error 80, [Traceback at line 1589](https://github.com/arita37/mlmodels_store/blob/master/log_json/log_json.py#L1589)<br />1589..Traceback (most recent call last):
<br />  File "/opt/hostedtoolcache/Python/3.6.12/x64/bin/ml_models", line 11, in <module>
<br />    load_entry_point('mlmodels', 'console_scripts', 'ml_models')()
<br />  File "https://github.com/arita37/mlmodels/tree/ff21906d63b46d89670bd3ed148b01355ca5ff0e/mlmodels/models.py", line 530, in main
<br />    fit_cli(arg)
<br />  File "https://github.com/arita37/mlmodels/tree/ff21906d63b46d89670bd3ed148b01355ca5ff0e/mlmodels/models.py", line 413, in fit_cli
<br />    model_p, data_p, compute_p, out_p = config_get_pars(config_file, arg.config_mode)
<br />  File "https://github.com/arita37/mlmodels/tree/ff21906d63b46d89670bd3ed148b01355ca5ff0e/mlmodels/models.py", line 299, in config_get_pars
<br />    out_p     = path_norm_dict( js.get("out_pars") )
<br />  File "https://github.com/arita37/mlmodels/tree/ff21906d63b46d89670bd3ed148b01355ca5ff0e/mlmodels/util.py", line 201, in path_norm_dict
<br />    for k,v in ddict.items():
<br />AttributeError: 'NoneType' object has no attribute 'items'



### Error 81, [Traceback at line 1619](https://github.com/arita37/mlmodels_store/blob/master/log_json/log_json.py#L1619)<br />1619..Traceback (most recent call last):
<br />  File "/opt/hostedtoolcache/Python/3.6.12/x64/bin/ml_models", line 11, in <module>
<br />    load_entry_point('mlmodels', 'console_scripts', 'ml_models')()
<br />  File "https://github.com/arita37/mlmodels/tree/ff21906d63b46d89670bd3ed148b01355ca5ff0e/mlmodels/models.py", line 530, in main
<br />    fit_cli(arg)
<br />  File "https://github.com/arita37/mlmodels/tree/ff21906d63b46d89670bd3ed148b01355ca5ff0e/mlmodels/models.py", line 421, in fit_cli
<br />    model = model_create(module, model_p, data_p, compute_p)  # Exact map JSON and paramters
<br />  File "https://github.com/arita37/mlmodels/tree/ff21906d63b46d89670bd3ed148b01355ca5ff0e/mlmodels/models.py", line 113, in model_create
<br />    module.init(model_pars=model_pars, data_pars=data_pars, compute_pars=compute_pars, **kwarg)
<br />AttributeError: module 'mlmodels.model_tch.torchhub' has no attribute 'init'



### Error 82, [Traceback at line 1640](https://github.com/arita37/mlmodels_store/blob/master/log_json/log_json.py#L1640)<br />1640..Traceback (most recent call last):
<br />  File "/opt/hostedtoolcache/Python/3.6.12/x64/bin/ml_models", line 11, in <module>
<br />    load_entry_point('mlmodels', 'console_scripts', 'ml_models')()
<br />  File "https://github.com/arita37/mlmodels/tree/ff21906d63b46d89670bd3ed148b01355ca5ff0e/mlmodels/models.py", line 530, in main
<br />    fit_cli(arg)
<br />  File "https://github.com/arita37/mlmodels/tree/ff21906d63b46d89670bd3ed148b01355ca5ff0e/mlmodels/models.py", line 413, in fit_cli
<br />    model_p, data_p, compute_p, out_p = config_get_pars(config_file, arg.config_mode)
<br />  File "https://github.com/arita37/mlmodels/tree/ff21906d63b46d89670bd3ed148b01355ca5ff0e/mlmodels/models.py", line 299, in config_get_pars
<br />    out_p     = path_norm_dict( js.get("out_pars") )
<br />  File "https://github.com/arita37/mlmodels/tree/ff21906d63b46d89670bd3ed148b01355ca5ff0e/mlmodels/util.py", line 201, in path_norm_dict
<br />    for k,v in ddict.items():
<br />AttributeError: 'NoneType' object has no attribute 'items'



### Error 83, [Traceback at line 1670](https://github.com/arita37/mlmodels_store/blob/master/log_json/log_json.py#L1670)<br />1670..Traceback (most recent call last):
<br />  File "/opt/hostedtoolcache/Python/3.6.12/x64/bin/ml_models", line 11, in <module>
<br />    load_entry_point('mlmodels', 'console_scripts', 'ml_models')()
<br />  File "https://github.com/arita37/mlmodels/tree/ff21906d63b46d89670bd3ed148b01355ca5ff0e/mlmodels/models.py", line 530, in main
<br />    fit_cli(arg)
<br />  File "https://github.com/arita37/mlmodels/tree/ff21906d63b46d89670bd3ed148b01355ca5ff0e/mlmodels/models.py", line 421, in fit_cli
<br />    model = model_create(module, model_p, data_p, compute_p)  # Exact map JSON and paramters
<br />  File "https://github.com/arita37/mlmodels/tree/ff21906d63b46d89670bd3ed148b01355ca5ff0e/mlmodels/models.py", line 113, in model_create
<br />    module.init(model_pars=model_pars, data_pars=data_pars, compute_pars=compute_pars, **kwarg)
<br />AttributeError: module 'mlmodels.model_tch.torchhub' has no attribute 'init'



### Error 84, [Traceback at line 1691](https://github.com/arita37/mlmodels_store/blob/master/log_json/log_json.py#L1691)<br />1691..Traceback (most recent call last):
<br />  File "/opt/hostedtoolcache/Python/3.6.12/x64/bin/ml_models", line 11, in <module>
<br />    load_entry_point('mlmodels', 'console_scripts', 'ml_models')()
<br />  File "https://github.com/arita37/mlmodels/tree/ff21906d63b46d89670bd3ed148b01355ca5ff0e/mlmodels/models.py", line 530, in main
<br />    fit_cli(arg)
<br />  File "https://github.com/arita37/mlmodels/tree/ff21906d63b46d89670bd3ed148b01355ca5ff0e/mlmodels/models.py", line 413, in fit_cli
<br />    model_p, data_p, compute_p, out_p = config_get_pars(config_file, arg.config_mode)
<br />  File "https://github.com/arita37/mlmodels/tree/ff21906d63b46d89670bd3ed148b01355ca5ff0e/mlmodels/models.py", line 299, in config_get_pars
<br />    out_p     = path_norm_dict( js.get("out_pars") )
<br />  File "https://github.com/arita37/mlmodels/tree/ff21906d63b46d89670bd3ed148b01355ca5ff0e/mlmodels/util.py", line 201, in path_norm_dict
<br />    for k,v in ddict.items():
<br />AttributeError: 'NoneType' object has no attribute 'items'



### Error 85, [Traceback at line 1721](https://github.com/arita37/mlmodels_store/blob/master/log_json/log_json.py#L1721)<br />1721..Traceback (most recent call last):
<br />  File "/opt/hostedtoolcache/Python/3.6.12/x64/bin/ml_models", line 11, in <module>
<br />    load_entry_point('mlmodels', 'console_scripts', 'ml_models')()
<br />  File "https://github.com/arita37/mlmodels/tree/ff21906d63b46d89670bd3ed148b01355ca5ff0e/mlmodels/models.py", line 530, in main
<br />    fit_cli(arg)
<br />  File "https://github.com/arita37/mlmodels/tree/ff21906d63b46d89670bd3ed148b01355ca5ff0e/mlmodels/models.py", line 421, in fit_cli
<br />    model = model_create(module, model_p, data_p, compute_p)  # Exact map JSON and paramters
<br />  File "https://github.com/arita37/mlmodels/tree/ff21906d63b46d89670bd3ed148b01355ca5ff0e/mlmodels/models.py", line 113, in model_create
<br />    module.init(model_pars=model_pars, data_pars=data_pars, compute_pars=compute_pars, **kwarg)
<br />AttributeError: module 'mlmodels.model_tch.torchhub' has no attribute 'init'



### Error 86, [Traceback at line 1742](https://github.com/arita37/mlmodels_store/blob/master/log_json/log_json.py#L1742)<br />1742..Traceback (most recent call last):
<br />  File "/opt/hostedtoolcache/Python/3.6.12/x64/bin/ml_models", line 11, in <module>
<br />    load_entry_point('mlmodels', 'console_scripts', 'ml_models')()
<br />  File "https://github.com/arita37/mlmodels/tree/ff21906d63b46d89670bd3ed148b01355ca5ff0e/mlmodels/models.py", line 530, in main
<br />    fit_cli(arg)
<br />  File "https://github.com/arita37/mlmodels/tree/ff21906d63b46d89670bd3ed148b01355ca5ff0e/mlmodels/models.py", line 413, in fit_cli
<br />    model_p, data_p, compute_p, out_p = config_get_pars(config_file, arg.config_mode)
<br />  File "https://github.com/arita37/mlmodels/tree/ff21906d63b46d89670bd3ed148b01355ca5ff0e/mlmodels/models.py", line 299, in config_get_pars
<br />    out_p     = path_norm_dict( js.get("out_pars") )
<br />  File "https://github.com/arita37/mlmodels/tree/ff21906d63b46d89670bd3ed148b01355ca5ff0e/mlmodels/util.py", line 201, in path_norm_dict
<br />    for k,v in ddict.items():
<br />AttributeError: 'NoneType' object has no attribute 'items'



### Error 87, [Traceback at line 1772](https://github.com/arita37/mlmodels_store/blob/master/log_json/log_json.py#L1772)<br />1772..Traceback (most recent call last):
<br />  File "/opt/hostedtoolcache/Python/3.6.12/x64/bin/ml_models", line 11, in <module>
<br />    load_entry_point('mlmodels', 'console_scripts', 'ml_models')()
<br />  File "https://github.com/arita37/mlmodels/tree/ff21906d63b46d89670bd3ed148b01355ca5ff0e/mlmodels/models.py", line 530, in main
<br />    fit_cli(arg)
<br />  File "https://github.com/arita37/mlmodels/tree/ff21906d63b46d89670bd3ed148b01355ca5ff0e/mlmodels/models.py", line 421, in fit_cli
<br />    model = model_create(module, model_p, data_p, compute_p)  # Exact map JSON and paramters
<br />  File "https://github.com/arita37/mlmodels/tree/ff21906d63b46d89670bd3ed148b01355ca5ff0e/mlmodels/models.py", line 113, in model_create
<br />    module.init(model_pars=model_pars, data_pars=data_pars, compute_pars=compute_pars, **kwarg)
<br />AttributeError: module 'mlmodels.model_tch.torchhub' has no attribute 'init'



### Error 88, [Traceback at line 1793](https://github.com/arita37/mlmodels_store/blob/master/log_json/log_json.py#L1793)<br />1793..Traceback (most recent call last):
<br />  File "/opt/hostedtoolcache/Python/3.6.12/x64/bin/ml_models", line 11, in <module>
<br />    load_entry_point('mlmodels', 'console_scripts', 'ml_models')()
<br />  File "https://github.com/arita37/mlmodels/tree/ff21906d63b46d89670bd3ed148b01355ca5ff0e/mlmodels/models.py", line 530, in main
<br />    fit_cli(arg)
<br />  File "https://github.com/arita37/mlmodels/tree/ff21906d63b46d89670bd3ed148b01355ca5ff0e/mlmodels/models.py", line 413, in fit_cli
<br />    model_p, data_p, compute_p, out_p = config_get_pars(config_file, arg.config_mode)
<br />  File "https://github.com/arita37/mlmodels/tree/ff21906d63b46d89670bd3ed148b01355ca5ff0e/mlmodels/models.py", line 299, in config_get_pars
<br />    out_p     = path_norm_dict( js.get("out_pars") )
<br />  File "https://github.com/arita37/mlmodels/tree/ff21906d63b46d89670bd3ed148b01355ca5ff0e/mlmodels/util.py", line 201, in path_norm_dict
<br />    for k,v in ddict.items():
<br />AttributeError: 'NoneType' object has no attribute 'items'



### Error 89, [Traceback at line 1823](https://github.com/arita37/mlmodels_store/blob/master/log_json/log_json.py#L1823)<br />1823..Traceback (most recent call last):
<br />  File "/opt/hostedtoolcache/Python/3.6.12/x64/bin/ml_models", line 11, in <module>
<br />    load_entry_point('mlmodels', 'console_scripts', 'ml_models')()
<br />  File "https://github.com/arita37/mlmodels/tree/ff21906d63b46d89670bd3ed148b01355ca5ff0e/mlmodels/models.py", line 530, in main
<br />    fit_cli(arg)
<br />  File "https://github.com/arita37/mlmodels/tree/ff21906d63b46d89670bd3ed148b01355ca5ff0e/mlmodels/models.py", line 421, in fit_cli
<br />    model = model_create(module, model_p, data_p, compute_p)  # Exact map JSON and paramters
<br />  File "https://github.com/arita37/mlmodels/tree/ff21906d63b46d89670bd3ed148b01355ca5ff0e/mlmodels/models.py", line 113, in model_create
<br />    module.init(model_pars=model_pars, data_pars=data_pars, compute_pars=compute_pars, **kwarg)
<br />AttributeError: module 'mlmodels.model_tch.torchhub' has no attribute 'init'



### Error 90, [Traceback at line 1844](https://github.com/arita37/mlmodels_store/blob/master/log_json/log_json.py#L1844)<br />1844..Traceback (most recent call last):
<br />  File "/opt/hostedtoolcache/Python/3.6.12/x64/bin/ml_models", line 11, in <module>
<br />    load_entry_point('mlmodels', 'console_scripts', 'ml_models')()
<br />  File "https://github.com/arita37/mlmodels/tree/ff21906d63b46d89670bd3ed148b01355ca5ff0e/mlmodels/models.py", line 530, in main
<br />    fit_cli(arg)
<br />  File "https://github.com/arita37/mlmodels/tree/ff21906d63b46d89670bd3ed148b01355ca5ff0e/mlmodels/models.py", line 413, in fit_cli
<br />    model_p, data_p, compute_p, out_p = config_get_pars(config_file, arg.config_mode)
<br />  File "https://github.com/arita37/mlmodels/tree/ff21906d63b46d89670bd3ed148b01355ca5ff0e/mlmodels/models.py", line 299, in config_get_pars
<br />    out_p     = path_norm_dict( js.get("out_pars") )
<br />  File "https://github.com/arita37/mlmodels/tree/ff21906d63b46d89670bd3ed148b01355ca5ff0e/mlmodels/util.py", line 201, in path_norm_dict
<br />    for k,v in ddict.items():
<br />AttributeError: 'NoneType' object has no attribute 'items'



### Error 91, [Traceback at line 1874](https://github.com/arita37/mlmodels_store/blob/master/log_json/log_json.py#L1874)<br />1874..Traceback (most recent call last):
<br />  File "/opt/hostedtoolcache/Python/3.6.12/x64/bin/ml_models", line 11, in <module>
<br />    load_entry_point('mlmodels', 'console_scripts', 'ml_models')()
<br />  File "https://github.com/arita37/mlmodels/tree/ff21906d63b46d89670bd3ed148b01355ca5ff0e/mlmodels/models.py", line 530, in main
<br />    fit_cli(arg)
<br />  File "https://github.com/arita37/mlmodels/tree/ff21906d63b46d89670bd3ed148b01355ca5ff0e/mlmodels/models.py", line 421, in fit_cli
<br />    model = model_create(module, model_p, data_p, compute_p)  # Exact map JSON and paramters
<br />  File "https://github.com/arita37/mlmodels/tree/ff21906d63b46d89670bd3ed148b01355ca5ff0e/mlmodels/models.py", line 113, in model_create
<br />    module.init(model_pars=model_pars, data_pars=data_pars, compute_pars=compute_pars, **kwarg)
<br />AttributeError: module 'mlmodels.model_tch.torchhub' has no attribute 'init'



### Error 92, [Traceback at line 1895](https://github.com/arita37/mlmodels_store/blob/master/log_json/log_json.py#L1895)<br />1895..Traceback (most recent call last):
<br />  File "/opt/hostedtoolcache/Python/3.6.12/x64/bin/ml_models", line 11, in <module>
<br />    load_entry_point('mlmodels', 'console_scripts', 'ml_models')()
<br />  File "https://github.com/arita37/mlmodels/tree/ff21906d63b46d89670bd3ed148b01355ca5ff0e/mlmodels/models.py", line 530, in main
<br />    fit_cli(arg)
<br />  File "https://github.com/arita37/mlmodels/tree/ff21906d63b46d89670bd3ed148b01355ca5ff0e/mlmodels/models.py", line 413, in fit_cli
<br />    model_p, data_p, compute_p, out_p = config_get_pars(config_file, arg.config_mode)
<br />  File "https://github.com/arita37/mlmodels/tree/ff21906d63b46d89670bd3ed148b01355ca5ff0e/mlmodels/models.py", line 299, in config_get_pars
<br />    out_p     = path_norm_dict( js.get("out_pars") )
<br />  File "https://github.com/arita37/mlmodels/tree/ff21906d63b46d89670bd3ed148b01355ca5ff0e/mlmodels/util.py", line 201, in path_norm_dict
<br />    for k,v in ddict.items():
<br />AttributeError: 'NoneType' object has no attribute 'items'



### Error 93, [Traceback at line 1925](https://github.com/arita37/mlmodels_store/blob/master/log_json/log_json.py#L1925)<br />1925..Traceback (most recent call last):
<br />  File "/opt/hostedtoolcache/Python/3.6.12/x64/bin/ml_models", line 11, in <module>
<br />    load_entry_point('mlmodels', 'console_scripts', 'ml_models')()
<br />  File "https://github.com/arita37/mlmodels/tree/ff21906d63b46d89670bd3ed148b01355ca5ff0e/mlmodels/models.py", line 530, in main
<br />    fit_cli(arg)
<br />  File "https://github.com/arita37/mlmodels/tree/ff21906d63b46d89670bd3ed148b01355ca5ff0e/mlmodels/models.py", line 421, in fit_cli
<br />    model = model_create(module, model_p, data_p, compute_p)  # Exact map JSON and paramters
<br />  File "https://github.com/arita37/mlmodels/tree/ff21906d63b46d89670bd3ed148b01355ca5ff0e/mlmodels/models.py", line 113, in model_create
<br />    module.init(model_pars=model_pars, data_pars=data_pars, compute_pars=compute_pars, **kwarg)
<br />AttributeError: module 'mlmodels.model_tch.torchhub' has no attribute 'init'



### Error 94, [Traceback at line 1946](https://github.com/arita37/mlmodels_store/blob/master/log_json/log_json.py#L1946)<br />1946..Traceback (most recent call last):
<br />  File "/opt/hostedtoolcache/Python/3.6.12/x64/bin/ml_models", line 11, in <module>
<br />    load_entry_point('mlmodels', 'console_scripts', 'ml_models')()
<br />  File "https://github.com/arita37/mlmodels/tree/ff21906d63b46d89670bd3ed148b01355ca5ff0e/mlmodels/models.py", line 530, in main
<br />    fit_cli(arg)
<br />  File "https://github.com/arita37/mlmodels/tree/ff21906d63b46d89670bd3ed148b01355ca5ff0e/mlmodels/models.py", line 413, in fit_cli
<br />    model_p, data_p, compute_p, out_p = config_get_pars(config_file, arg.config_mode)
<br />  File "https://github.com/arita37/mlmodels/tree/ff21906d63b46d89670bd3ed148b01355ca5ff0e/mlmodels/models.py", line 299, in config_get_pars
<br />    out_p     = path_norm_dict( js.get("out_pars") )
<br />  File "https://github.com/arita37/mlmodels/tree/ff21906d63b46d89670bd3ed148b01355ca5ff0e/mlmodels/util.py", line 201, in path_norm_dict
<br />    for k,v in ddict.items():
<br />AttributeError: 'NoneType' object has no attribute 'items'



### Error 95, [Traceback at line 1976](https://github.com/arita37/mlmodels_store/blob/master/log_json/log_json.py#L1976)<br />1976..Traceback (most recent call last):
<br />  File "/opt/hostedtoolcache/Python/3.6.12/x64/bin/ml_models", line 11, in <module>
<br />    load_entry_point('mlmodels', 'console_scripts', 'ml_models')()
<br />  File "https://github.com/arita37/mlmodels/tree/ff21906d63b46d89670bd3ed148b01355ca5ff0e/mlmodels/models.py", line 530, in main
<br />    fit_cli(arg)
<br />  File "https://github.com/arita37/mlmodels/tree/ff21906d63b46d89670bd3ed148b01355ca5ff0e/mlmodels/models.py", line 421, in fit_cli
<br />    model = model_create(module, model_p, data_p, compute_p)  # Exact map JSON and paramters
<br />  File "https://github.com/arita37/mlmodels/tree/ff21906d63b46d89670bd3ed148b01355ca5ff0e/mlmodels/models.py", line 113, in model_create
<br />    module.init(model_pars=model_pars, data_pars=data_pars, compute_pars=compute_pars, **kwarg)
<br />AttributeError: module 'mlmodels.model_tch.torchhub' has no attribute 'init'



### Error 96, [Traceback at line 1997](https://github.com/arita37/mlmodels_store/blob/master/log_json/log_json.py#L1997)<br />1997..Traceback (most recent call last):
<br />  File "/opt/hostedtoolcache/Python/3.6.12/x64/bin/ml_models", line 11, in <module>
<br />    load_entry_point('mlmodels', 'console_scripts', 'ml_models')()
<br />  File "https://github.com/arita37/mlmodels/tree/ff21906d63b46d89670bd3ed148b01355ca5ff0e/mlmodels/models.py", line 530, in main
<br />    fit_cli(arg)
<br />  File "https://github.com/arita37/mlmodels/tree/ff21906d63b46d89670bd3ed148b01355ca5ff0e/mlmodels/models.py", line 413, in fit_cli
<br />    model_p, data_p, compute_p, out_p = config_get_pars(config_file, arg.config_mode)
<br />  File "https://github.com/arita37/mlmodels/tree/ff21906d63b46d89670bd3ed148b01355ca5ff0e/mlmodels/models.py", line 299, in config_get_pars
<br />    out_p     = path_norm_dict( js.get("out_pars") )
<br />  File "https://github.com/arita37/mlmodels/tree/ff21906d63b46d89670bd3ed148b01355ca5ff0e/mlmodels/util.py", line 201, in path_norm_dict
<br />    for k,v in ddict.items():
<br />AttributeError: 'NoneType' object has no attribute 'items'



### Error 97, [Traceback at line 2027](https://github.com/arita37/mlmodels_store/blob/master/log_json/log_json.py#L2027)<br />2027..Traceback (most recent call last):
<br />  File "/opt/hostedtoolcache/Python/3.6.12/x64/bin/ml_models", line 11, in <module>
<br />    load_entry_point('mlmodels', 'console_scripts', 'ml_models')()
<br />  File "https://github.com/arita37/mlmodels/tree/ff21906d63b46d89670bd3ed148b01355ca5ff0e/mlmodels/models.py", line 530, in main
<br />    fit_cli(arg)
<br />  File "https://github.com/arita37/mlmodels/tree/ff21906d63b46d89670bd3ed148b01355ca5ff0e/mlmodels/models.py", line 421, in fit_cli
<br />    model = model_create(module, model_p, data_p, compute_p)  # Exact map JSON and paramters
<br />  File "https://github.com/arita37/mlmodels/tree/ff21906d63b46d89670bd3ed148b01355ca5ff0e/mlmodels/models.py", line 113, in model_create
<br />    module.init(model_pars=model_pars, data_pars=data_pars, compute_pars=compute_pars, **kwarg)
<br />AttributeError: module 'mlmodels.model_tch.torchhub' has no attribute 'init'



### Error 98, [Traceback at line 2048](https://github.com/arita37/mlmodels_store/blob/master/log_json/log_json.py#L2048)<br />2048..Traceback (most recent call last):
<br />  File "/opt/hostedtoolcache/Python/3.6.12/x64/bin/ml_models", line 11, in <module>
<br />    load_entry_point('mlmodels', 'console_scripts', 'ml_models')()
<br />  File "https://github.com/arita37/mlmodels/tree/ff21906d63b46d89670bd3ed148b01355ca5ff0e/mlmodels/models.py", line 530, in main
<br />    fit_cli(arg)
<br />  File "https://github.com/arita37/mlmodels/tree/ff21906d63b46d89670bd3ed148b01355ca5ff0e/mlmodels/models.py", line 413, in fit_cli
<br />    model_p, data_p, compute_p, out_p = config_get_pars(config_file, arg.config_mode)
<br />  File "https://github.com/arita37/mlmodels/tree/ff21906d63b46d89670bd3ed148b01355ca5ff0e/mlmodels/models.py", line 299, in config_get_pars
<br />    out_p     = path_norm_dict( js.get("out_pars") )
<br />  File "https://github.com/arita37/mlmodels/tree/ff21906d63b46d89670bd3ed148b01355ca5ff0e/mlmodels/util.py", line 201, in path_norm_dict
<br />    for k,v in ddict.items():
<br />AttributeError: 'NoneType' object has no attribute 'items'



### Error 99, [Traceback at line 2078](https://github.com/arita37/mlmodels_store/blob/master/log_json/log_json.py#L2078)<br />2078..Traceback (most recent call last):
<br />  File "/opt/hostedtoolcache/Python/3.6.12/x64/bin/ml_models", line 11, in <module>
<br />    load_entry_point('mlmodels', 'console_scripts', 'ml_models')()
<br />  File "https://github.com/arita37/mlmodels/tree/ff21906d63b46d89670bd3ed148b01355ca5ff0e/mlmodels/models.py", line 530, in main
<br />    fit_cli(arg)
<br />  File "https://github.com/arita37/mlmodels/tree/ff21906d63b46d89670bd3ed148b01355ca5ff0e/mlmodels/models.py", line 421, in fit_cli
<br />    model = model_create(module, model_p, data_p, compute_p)  # Exact map JSON and paramters
<br />  File "https://github.com/arita37/mlmodels/tree/ff21906d63b46d89670bd3ed148b01355ca5ff0e/mlmodels/models.py", line 113, in model_create
<br />    module.init(model_pars=model_pars, data_pars=data_pars, compute_pars=compute_pars, **kwarg)
<br />AttributeError: module 'mlmodels.model_tch.torchhub' has no attribute 'init'



### Error 100, [Traceback at line 2099](https://github.com/arita37/mlmodels_store/blob/master/log_json/log_json.py#L2099)<br />2099..Traceback (most recent call last):
<br />  File "/opt/hostedtoolcache/Python/3.6.12/x64/bin/ml_models", line 11, in <module>
<br />    load_entry_point('mlmodels', 'console_scripts', 'ml_models')()
<br />  File "https://github.com/arita37/mlmodels/tree/ff21906d63b46d89670bd3ed148b01355ca5ff0e/mlmodels/models.py", line 530, in main
<br />    fit_cli(arg)
<br />  File "https://github.com/arita37/mlmodels/tree/ff21906d63b46d89670bd3ed148b01355ca5ff0e/mlmodels/models.py", line 413, in fit_cli
<br />    model_p, data_p, compute_p, out_p = config_get_pars(config_file, arg.config_mode)
<br />  File "https://github.com/arita37/mlmodels/tree/ff21906d63b46d89670bd3ed148b01355ca5ff0e/mlmodels/models.py", line 299, in config_get_pars
<br />    out_p     = path_norm_dict( js.get("out_pars") )
<br />  File "https://github.com/arita37/mlmodels/tree/ff21906d63b46d89670bd3ed148b01355ca5ff0e/mlmodels/util.py", line 201, in path_norm_dict
<br />    for k,v in ddict.items():
<br />AttributeError: 'NoneType' object has no attribute 'items'



### Error 101, [Traceback at line 2129](https://github.com/arita37/mlmodels_store/blob/master/log_json/log_json.py#L2129)<br />2129..Traceback (most recent call last):
<br />  File "/opt/hostedtoolcache/Python/3.6.12/x64/bin/ml_models", line 11, in <module>
<br />    load_entry_point('mlmodels', 'console_scripts', 'ml_models')()
<br />  File "https://github.com/arita37/mlmodels/tree/ff21906d63b46d89670bd3ed148b01355ca5ff0e/mlmodels/models.py", line 530, in main
<br />    fit_cli(arg)
<br />  File "https://github.com/arita37/mlmodels/tree/ff21906d63b46d89670bd3ed148b01355ca5ff0e/mlmodels/models.py", line 421, in fit_cli
<br />    model = model_create(module, model_p, data_p, compute_p)  # Exact map JSON and paramters
<br />  File "https://github.com/arita37/mlmodels/tree/ff21906d63b46d89670bd3ed148b01355ca5ff0e/mlmodels/models.py", line 113, in model_create
<br />    module.init(model_pars=model_pars, data_pars=data_pars, compute_pars=compute_pars, **kwarg)
<br />AttributeError: module 'mlmodels.model_tch.torchhub' has no attribute 'init'



### Error 102, [Traceback at line 2150](https://github.com/arita37/mlmodels_store/blob/master/log_json/log_json.py#L2150)<br />2150..Traceback (most recent call last):
<br />  File "/opt/hostedtoolcache/Python/3.6.12/x64/bin/ml_models", line 11, in <module>
<br />    load_entry_point('mlmodels', 'console_scripts', 'ml_models')()
<br />  File "https://github.com/arita37/mlmodels/tree/ff21906d63b46d89670bd3ed148b01355ca5ff0e/mlmodels/models.py", line 530, in main
<br />    fit_cli(arg)
<br />  File "https://github.com/arita37/mlmodels/tree/ff21906d63b46d89670bd3ed148b01355ca5ff0e/mlmodels/models.py", line 413, in fit_cli
<br />    model_p, data_p, compute_p, out_p = config_get_pars(config_file, arg.config_mode)
<br />  File "https://github.com/arita37/mlmodels/tree/ff21906d63b46d89670bd3ed148b01355ca5ff0e/mlmodels/models.py", line 299, in config_get_pars
<br />    out_p     = path_norm_dict( js.get("out_pars") )
<br />  File "https://github.com/arita37/mlmodels/tree/ff21906d63b46d89670bd3ed148b01355ca5ff0e/mlmodels/util.py", line 201, in path_norm_dict
<br />    for k,v in ddict.items():
<br />AttributeError: 'NoneType' object has no attribute 'items'



### Error 103, [Traceback at line 2180](https://github.com/arita37/mlmodels_store/blob/master/log_json/log_json.py#L2180)<br />2180..Traceback (most recent call last):
<br />  File "/opt/hostedtoolcache/Python/3.6.12/x64/bin/ml_models", line 11, in <module>
<br />    load_entry_point('mlmodels', 'console_scripts', 'ml_models')()
<br />  File "https://github.com/arita37/mlmodels/tree/ff21906d63b46d89670bd3ed148b01355ca5ff0e/mlmodels/models.py", line 530, in main
<br />    fit_cli(arg)
<br />  File "https://github.com/arita37/mlmodels/tree/ff21906d63b46d89670bd3ed148b01355ca5ff0e/mlmodels/models.py", line 421, in fit_cli
<br />    model = model_create(module, model_p, data_p, compute_p)  # Exact map JSON and paramters
<br />  File "https://github.com/arita37/mlmodels/tree/ff21906d63b46d89670bd3ed148b01355ca5ff0e/mlmodels/models.py", line 113, in model_create
<br />    module.init(model_pars=model_pars, data_pars=data_pars, compute_pars=compute_pars, **kwarg)
<br />AttributeError: module 'mlmodels.model_tch.torchhub' has no attribute 'init'



### Error 104, [Traceback at line 2201](https://github.com/arita37/mlmodels_store/blob/master/log_json/log_json.py#L2201)<br />2201..Traceback (most recent call last):
<br />  File "/opt/hostedtoolcache/Python/3.6.12/x64/bin/ml_models", line 11, in <module>
<br />    load_entry_point('mlmodels', 'console_scripts', 'ml_models')()
<br />  File "https://github.com/arita37/mlmodels/tree/ff21906d63b46d89670bd3ed148b01355ca5ff0e/mlmodels/models.py", line 530, in main
<br />    fit_cli(arg)
<br />  File "https://github.com/arita37/mlmodels/tree/ff21906d63b46d89670bd3ed148b01355ca5ff0e/mlmodels/models.py", line 413, in fit_cli
<br />    model_p, data_p, compute_p, out_p = config_get_pars(config_file, arg.config_mode)
<br />  File "https://github.com/arita37/mlmodels/tree/ff21906d63b46d89670bd3ed148b01355ca5ff0e/mlmodels/models.py", line 299, in config_get_pars
<br />    out_p     = path_norm_dict( js.get("out_pars") )
<br />  File "https://github.com/arita37/mlmodels/tree/ff21906d63b46d89670bd3ed148b01355ca5ff0e/mlmodels/util.py", line 201, in path_norm_dict
<br />    for k,v in ddict.items():
<br />AttributeError: 'NoneType' object has no attribute 'items'



### Error 105, [Traceback at line 2231](https://github.com/arita37/mlmodels_store/blob/master/log_json/log_json.py#L2231)<br />2231..Traceback (most recent call last):
<br />  File "/opt/hostedtoolcache/Python/3.6.12/x64/bin/ml_models", line 11, in <module>
<br />    load_entry_point('mlmodels', 'console_scripts', 'ml_models')()
<br />  File "https://github.com/arita37/mlmodels/tree/ff21906d63b46d89670bd3ed148b01355ca5ff0e/mlmodels/models.py", line 530, in main
<br />    fit_cli(arg)
<br />  File "https://github.com/arita37/mlmodels/tree/ff21906d63b46d89670bd3ed148b01355ca5ff0e/mlmodels/models.py", line 421, in fit_cli
<br />    model = model_create(module, model_p, data_p, compute_p)  # Exact map JSON and paramters
<br />  File "https://github.com/arita37/mlmodels/tree/ff21906d63b46d89670bd3ed148b01355ca5ff0e/mlmodels/models.py", line 113, in model_create
<br />    module.init(model_pars=model_pars, data_pars=data_pars, compute_pars=compute_pars, **kwarg)
<br />AttributeError: module 'mlmodels.model_tch.torchhub' has no attribute 'init'



### Error 106, [Traceback at line 2252](https://github.com/arita37/mlmodels_store/blob/master/log_json/log_json.py#L2252)<br />2252..Traceback (most recent call last):
<br />  File "/opt/hostedtoolcache/Python/3.6.12/x64/bin/ml_models", line 11, in <module>
<br />    load_entry_point('mlmodels', 'console_scripts', 'ml_models')()
<br />  File "https://github.com/arita37/mlmodels/tree/ff21906d63b46d89670bd3ed148b01355ca5ff0e/mlmodels/models.py", line 530, in main
<br />    fit_cli(arg)
<br />  File "https://github.com/arita37/mlmodels/tree/ff21906d63b46d89670bd3ed148b01355ca5ff0e/mlmodels/models.py", line 413, in fit_cli
<br />    model_p, data_p, compute_p, out_p = config_get_pars(config_file, arg.config_mode)
<br />  File "https://github.com/arita37/mlmodels/tree/ff21906d63b46d89670bd3ed148b01355ca5ff0e/mlmodels/models.py", line 299, in config_get_pars
<br />    out_p     = path_norm_dict( js.get("out_pars") )
<br />  File "https://github.com/arita37/mlmodels/tree/ff21906d63b46d89670bd3ed148b01355ca5ff0e/mlmodels/util.py", line 201, in path_norm_dict
<br />    for k,v in ddict.items():
<br />AttributeError: 'NoneType' object has no attribute 'items'



### Error 107, [Traceback at line 2282](https://github.com/arita37/mlmodels_store/blob/master/log_json/log_json.py#L2282)<br />2282..Traceback (most recent call last):
<br />  File "/opt/hostedtoolcache/Python/3.6.12/x64/bin/ml_models", line 11, in <module>
<br />    load_entry_point('mlmodels', 'console_scripts', 'ml_models')()
<br />  File "https://github.com/arita37/mlmodels/tree/ff21906d63b46d89670bd3ed148b01355ca5ff0e/mlmodels/models.py", line 530, in main
<br />    fit_cli(arg)
<br />  File "https://github.com/arita37/mlmodels/tree/ff21906d63b46d89670bd3ed148b01355ca5ff0e/mlmodels/models.py", line 421, in fit_cli
<br />    model = model_create(module, model_p, data_p, compute_p)  # Exact map JSON and paramters
<br />  File "https://github.com/arita37/mlmodels/tree/ff21906d63b46d89670bd3ed148b01355ca5ff0e/mlmodels/models.py", line 113, in model_create
<br />    module.init(model_pars=model_pars, data_pars=data_pars, compute_pars=compute_pars, **kwarg)
<br />AttributeError: module 'mlmodels.model_tch.torchhub' has no attribute 'init'



### Error 108, [Traceback at line 2303](https://github.com/arita37/mlmodels_store/blob/master/log_json/log_json.py#L2303)<br />2303..Traceback (most recent call last):
<br />  File "/opt/hostedtoolcache/Python/3.6.12/x64/bin/ml_models", line 11, in <module>
<br />    load_entry_point('mlmodels', 'console_scripts', 'ml_models')()
<br />  File "https://github.com/arita37/mlmodels/tree/ff21906d63b46d89670bd3ed148b01355ca5ff0e/mlmodels/models.py", line 530, in main
<br />    fit_cli(arg)
<br />  File "https://github.com/arita37/mlmodels/tree/ff21906d63b46d89670bd3ed148b01355ca5ff0e/mlmodels/models.py", line 413, in fit_cli
<br />    model_p, data_p, compute_p, out_p = config_get_pars(config_file, arg.config_mode)
<br />  File "https://github.com/arita37/mlmodels/tree/ff21906d63b46d89670bd3ed148b01355ca5ff0e/mlmodels/models.py", line 299, in config_get_pars
<br />    out_p     = path_norm_dict( js.get("out_pars") )
<br />  File "https://github.com/arita37/mlmodels/tree/ff21906d63b46d89670bd3ed148b01355ca5ff0e/mlmodels/util.py", line 201, in path_norm_dict
<br />    for k,v in ddict.items():
<br />AttributeError: 'NoneType' object has no attribute 'items'



### Error 109, [Traceback at line 2333](https://github.com/arita37/mlmodels_store/blob/master/log_json/log_json.py#L2333)<br />2333..Traceback (most recent call last):
<br />  File "/opt/hostedtoolcache/Python/3.6.12/x64/bin/ml_models", line 11, in <module>
<br />    load_entry_point('mlmodels', 'console_scripts', 'ml_models')()
<br />  File "https://github.com/arita37/mlmodels/tree/ff21906d63b46d89670bd3ed148b01355ca5ff0e/mlmodels/models.py", line 530, in main
<br />    fit_cli(arg)
<br />  File "https://github.com/arita37/mlmodels/tree/ff21906d63b46d89670bd3ed148b01355ca5ff0e/mlmodels/models.py", line 421, in fit_cli
<br />    model = model_create(module, model_p, data_p, compute_p)  # Exact map JSON and paramters
<br />  File "https://github.com/arita37/mlmodels/tree/ff21906d63b46d89670bd3ed148b01355ca5ff0e/mlmodels/models.py", line 113, in model_create
<br />    module.init(model_pars=model_pars, data_pars=data_pars, compute_pars=compute_pars, **kwarg)
<br />AttributeError: module 'mlmodels.model_tch.torchhub' has no attribute 'init'



### Error 110, [Traceback at line 2354](https://github.com/arita37/mlmodels_store/blob/master/log_json/log_json.py#L2354)<br />2354..Traceback (most recent call last):
<br />  File "/opt/hostedtoolcache/Python/3.6.12/x64/bin/ml_models", line 11, in <module>
<br />    load_entry_point('mlmodels', 'console_scripts', 'ml_models')()
<br />  File "https://github.com/arita37/mlmodels/tree/ff21906d63b46d89670bd3ed148b01355ca5ff0e/mlmodels/models.py", line 530, in main
<br />    fit_cli(arg)
<br />  File "https://github.com/arita37/mlmodels/tree/ff21906d63b46d89670bd3ed148b01355ca5ff0e/mlmodels/models.py", line 413, in fit_cli
<br />    model_p, data_p, compute_p, out_p = config_get_pars(config_file, arg.config_mode)
<br />  File "https://github.com/arita37/mlmodels/tree/ff21906d63b46d89670bd3ed148b01355ca5ff0e/mlmodels/models.py", line 299, in config_get_pars
<br />    out_p     = path_norm_dict( js.get("out_pars") )
<br />  File "https://github.com/arita37/mlmodels/tree/ff21906d63b46d89670bd3ed148b01355ca5ff0e/mlmodels/util.py", line 201, in path_norm_dict
<br />    for k,v in ddict.items():
<br />AttributeError: 'NoneType' object has no attribute 'items'



### Error 111, [Traceback at line 2384](https://github.com/arita37/mlmodels_store/blob/master/log_json/log_json.py#L2384)<br />2384..Traceback (most recent call last):
<br />  File "/opt/hostedtoolcache/Python/3.6.12/x64/bin/ml_models", line 11, in <module>
<br />    load_entry_point('mlmodels', 'console_scripts', 'ml_models')()
<br />  File "https://github.com/arita37/mlmodels/tree/ff21906d63b46d89670bd3ed148b01355ca5ff0e/mlmodels/models.py", line 530, in main
<br />    fit_cli(arg)
<br />  File "https://github.com/arita37/mlmodels/tree/ff21906d63b46d89670bd3ed148b01355ca5ff0e/mlmodels/models.py", line 421, in fit_cli
<br />    model = model_create(module, model_p, data_p, compute_p)  # Exact map JSON and paramters
<br />  File "https://github.com/arita37/mlmodels/tree/ff21906d63b46d89670bd3ed148b01355ca5ff0e/mlmodels/models.py", line 113, in model_create
<br />    module.init(model_pars=model_pars, data_pars=data_pars, compute_pars=compute_pars, **kwarg)
<br />AttributeError: module 'mlmodels.model_tch.torchhub' has no attribute 'init'



### Error 112, [Traceback at line 2405](https://github.com/arita37/mlmodels_store/blob/master/log_json/log_json.py#L2405)<br />2405..Traceback (most recent call last):
<br />  File "/opt/hostedtoolcache/Python/3.6.12/x64/bin/ml_models", line 11, in <module>
<br />    load_entry_point('mlmodels', 'console_scripts', 'ml_models')()
<br />  File "https://github.com/arita37/mlmodels/tree/ff21906d63b46d89670bd3ed148b01355ca5ff0e/mlmodels/models.py", line 530, in main
<br />    fit_cli(arg)
<br />  File "https://github.com/arita37/mlmodels/tree/ff21906d63b46d89670bd3ed148b01355ca5ff0e/mlmodels/models.py", line 413, in fit_cli
<br />    model_p, data_p, compute_p, out_p = config_get_pars(config_file, arg.config_mode)
<br />  File "https://github.com/arita37/mlmodels/tree/ff21906d63b46d89670bd3ed148b01355ca5ff0e/mlmodels/models.py", line 299, in config_get_pars
<br />    out_p     = path_norm_dict( js.get("out_pars") )
<br />  File "https://github.com/arita37/mlmodels/tree/ff21906d63b46d89670bd3ed148b01355ca5ff0e/mlmodels/util.py", line 201, in path_norm_dict
<br />    for k,v in ddict.items():
<br />AttributeError: 'NoneType' object has no attribute 'items'



### Error 113, [Traceback at line 2435](https://github.com/arita37/mlmodels_store/blob/master/log_json/log_json.py#L2435)<br />2435..Traceback (most recent call last):
<br />  File "/opt/hostedtoolcache/Python/3.6.12/x64/bin/ml_models", line 11, in <module>
<br />    load_entry_point('mlmodels', 'console_scripts', 'ml_models')()
<br />  File "https://github.com/arita37/mlmodels/tree/ff21906d63b46d89670bd3ed148b01355ca5ff0e/mlmodels/models.py", line 530, in main
<br />    fit_cli(arg)
<br />  File "https://github.com/arita37/mlmodels/tree/ff21906d63b46d89670bd3ed148b01355ca5ff0e/mlmodels/models.py", line 421, in fit_cli
<br />    model = model_create(module, model_p, data_p, compute_p)  # Exact map JSON and paramters
<br />  File "https://github.com/arita37/mlmodels/tree/ff21906d63b46d89670bd3ed148b01355ca5ff0e/mlmodels/models.py", line 113, in model_create
<br />    module.init(model_pars=model_pars, data_pars=data_pars, compute_pars=compute_pars, **kwarg)
<br />AttributeError: module 'mlmodels.model_tch.torchhub' has no attribute 'init'



### Error 114, [Traceback at line 2456](https://github.com/arita37/mlmodels_store/blob/master/log_json/log_json.py#L2456)<br />2456..Traceback (most recent call last):
<br />  File "/opt/hostedtoolcache/Python/3.6.12/x64/bin/ml_models", line 11, in <module>
<br />    load_entry_point('mlmodels', 'console_scripts', 'ml_models')()
<br />  File "https://github.com/arita37/mlmodels/tree/ff21906d63b46d89670bd3ed148b01355ca5ff0e/mlmodels/models.py", line 530, in main
<br />    fit_cli(arg)
<br />  File "https://github.com/arita37/mlmodels/tree/ff21906d63b46d89670bd3ed148b01355ca5ff0e/mlmodels/models.py", line 413, in fit_cli
<br />    model_p, data_p, compute_p, out_p = config_get_pars(config_file, arg.config_mode)
<br />  File "https://github.com/arita37/mlmodels/tree/ff21906d63b46d89670bd3ed148b01355ca5ff0e/mlmodels/models.py", line 299, in config_get_pars
<br />    out_p     = path_norm_dict( js.get("out_pars") )
<br />  File "https://github.com/arita37/mlmodels/tree/ff21906d63b46d89670bd3ed148b01355ca5ff0e/mlmodels/util.py", line 201, in path_norm_dict
<br />    for k,v in ddict.items():
<br />AttributeError: 'NoneType' object has no attribute 'items'



### Error 115, [Traceback at line 2486](https://github.com/arita37/mlmodels_store/blob/master/log_json/log_json.py#L2486)<br />2486..Traceback (most recent call last):
<br />  File "/opt/hostedtoolcache/Python/3.6.12/x64/bin/ml_models", line 11, in <module>
<br />    load_entry_point('mlmodels', 'console_scripts', 'ml_models')()
<br />  File "https://github.com/arita37/mlmodels/tree/ff21906d63b46d89670bd3ed148b01355ca5ff0e/mlmodels/models.py", line 530, in main
<br />    fit_cli(arg)
<br />  File "https://github.com/arita37/mlmodels/tree/ff21906d63b46d89670bd3ed148b01355ca5ff0e/mlmodels/models.py", line 421, in fit_cli
<br />    model = model_create(module, model_p, data_p, compute_p)  # Exact map JSON and paramters
<br />  File "https://github.com/arita37/mlmodels/tree/ff21906d63b46d89670bd3ed148b01355ca5ff0e/mlmodels/models.py", line 113, in model_create
<br />    module.init(model_pars=model_pars, data_pars=data_pars, compute_pars=compute_pars, **kwarg)
<br />AttributeError: module 'mlmodels.model_tch.torchhub' has no attribute 'init'



### Error 116, [Traceback at line 2507](https://github.com/arita37/mlmodels_store/blob/master/log_json/log_json.py#L2507)<br />2507..Traceback (most recent call last):
<br />  File "/opt/hostedtoolcache/Python/3.6.12/x64/bin/ml_models", line 11, in <module>
<br />    load_entry_point('mlmodels', 'console_scripts', 'ml_models')()
<br />  File "https://github.com/arita37/mlmodels/tree/ff21906d63b46d89670bd3ed148b01355ca5ff0e/mlmodels/models.py", line 530, in main
<br />    fit_cli(arg)
<br />  File "https://github.com/arita37/mlmodels/tree/ff21906d63b46d89670bd3ed148b01355ca5ff0e/mlmodels/models.py", line 413, in fit_cli
<br />    model_p, data_p, compute_p, out_p = config_get_pars(config_file, arg.config_mode)
<br />  File "https://github.com/arita37/mlmodels/tree/ff21906d63b46d89670bd3ed148b01355ca5ff0e/mlmodels/models.py", line 299, in config_get_pars
<br />    out_p     = path_norm_dict( js.get("out_pars") )
<br />  File "https://github.com/arita37/mlmodels/tree/ff21906d63b46d89670bd3ed148b01355ca5ff0e/mlmodels/util.py", line 201, in path_norm_dict
<br />    for k,v in ddict.items():
<br />AttributeError: 'NoneType' object has no attribute 'items'



### Error 117, [Traceback at line 2537](https://github.com/arita37/mlmodels_store/blob/master/log_json/log_json.py#L2537)<br />2537..Traceback (most recent call last):
<br />  File "/opt/hostedtoolcache/Python/3.6.12/x64/bin/ml_models", line 11, in <module>
<br />    load_entry_point('mlmodels', 'console_scripts', 'ml_models')()
<br />  File "https://github.com/arita37/mlmodels/tree/ff21906d63b46d89670bd3ed148b01355ca5ff0e/mlmodels/models.py", line 530, in main
<br />    fit_cli(arg)
<br />  File "https://github.com/arita37/mlmodels/tree/ff21906d63b46d89670bd3ed148b01355ca5ff0e/mlmodels/models.py", line 421, in fit_cli
<br />    model = model_create(module, model_p, data_p, compute_p)  # Exact map JSON and paramters
<br />  File "https://github.com/arita37/mlmodels/tree/ff21906d63b46d89670bd3ed148b01355ca5ff0e/mlmodels/models.py", line 113, in model_create
<br />    module.init(model_pars=model_pars, data_pars=data_pars, compute_pars=compute_pars, **kwarg)
<br />AttributeError: module 'mlmodels.model_tch.torchhub' has no attribute 'init'



### Error 118, [Traceback at line 2558](https://github.com/arita37/mlmodels_store/blob/master/log_json/log_json.py#L2558)<br />2558..Traceback (most recent call last):
<br />  File "/opt/hostedtoolcache/Python/3.6.12/x64/bin/ml_models", line 11, in <module>
<br />    load_entry_point('mlmodels', 'console_scripts', 'ml_models')()
<br />  File "https://github.com/arita37/mlmodels/tree/ff21906d63b46d89670bd3ed148b01355ca5ff0e/mlmodels/models.py", line 530, in main
<br />    fit_cli(arg)
<br />  File "https://github.com/arita37/mlmodels/tree/ff21906d63b46d89670bd3ed148b01355ca5ff0e/mlmodels/models.py", line 413, in fit_cli
<br />    model_p, data_p, compute_p, out_p = config_get_pars(config_file, arg.config_mode)
<br />  File "https://github.com/arita37/mlmodels/tree/ff21906d63b46d89670bd3ed148b01355ca5ff0e/mlmodels/models.py", line 299, in config_get_pars
<br />    out_p     = path_norm_dict( js.get("out_pars") )
<br />  File "https://github.com/arita37/mlmodels/tree/ff21906d63b46d89670bd3ed148b01355ca5ff0e/mlmodels/util.py", line 201, in path_norm_dict
<br />    for k,v in ddict.items():
<br />AttributeError: 'NoneType' object has no attribute 'items'



### Error 119, [Traceback at line 2588](https://github.com/arita37/mlmodels_store/blob/master/log_json/log_json.py#L2588)<br />2588..Traceback (most recent call last):
<br />  File "/opt/hostedtoolcache/Python/3.6.12/x64/bin/ml_models", line 11, in <module>
<br />    load_entry_point('mlmodels', 'console_scripts', 'ml_models')()
<br />  File "https://github.com/arita37/mlmodels/tree/ff21906d63b46d89670bd3ed148b01355ca5ff0e/mlmodels/models.py", line 530, in main
<br />    fit_cli(arg)
<br />  File "https://github.com/arita37/mlmodels/tree/ff21906d63b46d89670bd3ed148b01355ca5ff0e/mlmodels/models.py", line 421, in fit_cli
<br />    model = model_create(module, model_p, data_p, compute_p)  # Exact map JSON and paramters
<br />  File "https://github.com/arita37/mlmodels/tree/ff21906d63b46d89670bd3ed148b01355ca5ff0e/mlmodels/models.py", line 113, in model_create
<br />    module.init(model_pars=model_pars, data_pars=data_pars, compute_pars=compute_pars, **kwarg)
<br />AttributeError: module 'mlmodels.model_tch.torchhub' has no attribute 'init'



### Error 120, [Traceback at line 2609](https://github.com/arita37/mlmodels_store/blob/master/log_json/log_json.py#L2609)<br />2609..Traceback (most recent call last):
<br />  File "/opt/hostedtoolcache/Python/3.6.12/x64/bin/ml_models", line 11, in <module>
<br />    load_entry_point('mlmodels', 'console_scripts', 'ml_models')()
<br />  File "https://github.com/arita37/mlmodels/tree/ff21906d63b46d89670bd3ed148b01355ca5ff0e/mlmodels/models.py", line 530, in main
<br />    fit_cli(arg)
<br />  File "https://github.com/arita37/mlmodels/tree/ff21906d63b46d89670bd3ed148b01355ca5ff0e/mlmodels/models.py", line 413, in fit_cli
<br />    model_p, data_p, compute_p, out_p = config_get_pars(config_file, arg.config_mode)
<br />  File "https://github.com/arita37/mlmodels/tree/ff21906d63b46d89670bd3ed148b01355ca5ff0e/mlmodels/models.py", line 299, in config_get_pars
<br />    out_p     = path_norm_dict( js.get("out_pars") )
<br />  File "https://github.com/arita37/mlmodels/tree/ff21906d63b46d89670bd3ed148b01355ca5ff0e/mlmodels/util.py", line 201, in path_norm_dict
<br />    for k,v in ddict.items():
<br />AttributeError: 'NoneType' object has no attribute 'items'



### Error 121, [Traceback at line 2639](https://github.com/arita37/mlmodels_store/blob/master/log_json/log_json.py#L2639)<br />2639..Traceback (most recent call last):
<br />  File "/opt/hostedtoolcache/Python/3.6.12/x64/bin/ml_models", line 11, in <module>
<br />    load_entry_point('mlmodels', 'console_scripts', 'ml_models')()
<br />  File "https://github.com/arita37/mlmodels/tree/ff21906d63b46d89670bd3ed148b01355ca5ff0e/mlmodels/models.py", line 530, in main
<br />    fit_cli(arg)
<br />  File "https://github.com/arita37/mlmodels/tree/ff21906d63b46d89670bd3ed148b01355ca5ff0e/mlmodels/models.py", line 421, in fit_cli
<br />    model = model_create(module, model_p, data_p, compute_p)  # Exact map JSON and paramters
<br />  File "https://github.com/arita37/mlmodels/tree/ff21906d63b46d89670bd3ed148b01355ca5ff0e/mlmodels/models.py", line 113, in model_create
<br />    module.init(model_pars=model_pars, data_pars=data_pars, compute_pars=compute_pars, **kwarg)
<br />AttributeError: module 'mlmodels.model_tch.torchhub' has no attribute 'init'



### Error 122, [Traceback at line 2660](https://github.com/arita37/mlmodels_store/blob/master/log_json/log_json.py#L2660)<br />2660..Traceback (most recent call last):
<br />  File "/opt/hostedtoolcache/Python/3.6.12/x64/bin/ml_models", line 11, in <module>
<br />    load_entry_point('mlmodels', 'console_scripts', 'ml_models')()
<br />  File "https://github.com/arita37/mlmodels/tree/ff21906d63b46d89670bd3ed148b01355ca5ff0e/mlmodels/models.py", line 530, in main
<br />    fit_cli(arg)
<br />  File "https://github.com/arita37/mlmodels/tree/ff21906d63b46d89670bd3ed148b01355ca5ff0e/mlmodels/models.py", line 413, in fit_cli
<br />    model_p, data_p, compute_p, out_p = config_get_pars(config_file, arg.config_mode)
<br />  File "https://github.com/arita37/mlmodels/tree/ff21906d63b46d89670bd3ed148b01355ca5ff0e/mlmodels/models.py", line 299, in config_get_pars
<br />    out_p     = path_norm_dict( js.get("out_pars") )
<br />  File "https://github.com/arita37/mlmodels/tree/ff21906d63b46d89670bd3ed148b01355ca5ff0e/mlmodels/util.py", line 201, in path_norm_dict
<br />    for k,v in ddict.items():
<br />AttributeError: 'NoneType' object has no attribute 'items'



### Error 123, [Traceback at line 2690](https://github.com/arita37/mlmodels_store/blob/master/log_json/log_json.py#L2690)<br />2690..Traceback (most recent call last):
<br />  File "/opt/hostedtoolcache/Python/3.6.12/x64/bin/ml_models", line 11, in <module>
<br />    load_entry_point('mlmodels', 'console_scripts', 'ml_models')()
<br />  File "https://github.com/arita37/mlmodels/tree/ff21906d63b46d89670bd3ed148b01355ca5ff0e/mlmodels/models.py", line 530, in main
<br />    fit_cli(arg)
<br />  File "https://github.com/arita37/mlmodels/tree/ff21906d63b46d89670bd3ed148b01355ca5ff0e/mlmodels/models.py", line 421, in fit_cli
<br />    model = model_create(module, model_p, data_p, compute_p)  # Exact map JSON and paramters
<br />  File "https://github.com/arita37/mlmodels/tree/ff21906d63b46d89670bd3ed148b01355ca5ff0e/mlmodels/models.py", line 113, in model_create
<br />    module.init(model_pars=model_pars, data_pars=data_pars, compute_pars=compute_pars, **kwarg)
<br />AttributeError: module 'mlmodels.model_tch.torchhub' has no attribute 'init'



### Error 124, [Traceback at line 2711](https://github.com/arita37/mlmodels_store/blob/master/log_json/log_json.py#L2711)<br />2711..Traceback (most recent call last):
<br />  File "/opt/hostedtoolcache/Python/3.6.12/x64/bin/ml_models", line 11, in <module>
<br />    load_entry_point('mlmodels', 'console_scripts', 'ml_models')()
<br />  File "https://github.com/arita37/mlmodels/tree/ff21906d63b46d89670bd3ed148b01355ca5ff0e/mlmodels/models.py", line 530, in main
<br />    fit_cli(arg)
<br />  File "https://github.com/arita37/mlmodels/tree/ff21906d63b46d89670bd3ed148b01355ca5ff0e/mlmodels/models.py", line 413, in fit_cli
<br />    model_p, data_p, compute_p, out_p = config_get_pars(config_file, arg.config_mode)
<br />  File "https://github.com/arita37/mlmodels/tree/ff21906d63b46d89670bd3ed148b01355ca5ff0e/mlmodels/models.py", line 299, in config_get_pars
<br />    out_p     = path_norm_dict( js.get("out_pars") )
<br />  File "https://github.com/arita37/mlmodels/tree/ff21906d63b46d89670bd3ed148b01355ca5ff0e/mlmodels/util.py", line 201, in path_norm_dict
<br />    for k,v in ddict.items():
<br />AttributeError: 'NoneType' object has no attribute 'items'



### Error 125, [Traceback at line 2741](https://github.com/arita37/mlmodels_store/blob/master/log_json/log_json.py#L2741)<br />2741..Traceback (most recent call last):
<br />  File "https://github.com/arita37/mlmodels/tree/ff21906d63b46d89670bd3ed148b01355ca5ff0e/mlmodels/models.py", line 72, in module_load
<br />    module = import_module(f"mlmodels.{model_name}")
<br />  File "/opt/hostedtoolcache/Python/3.6.12/x64/lib/python3.6/importlib/__init__.py", line 126, in import_module
<br />    return _bootstrap._gcd_import(name[level:], package, level)
<br />  File "<frozen importlib._bootstrap>", line 994, in _gcd_import
<br />  File "<frozen importlib._bootstrap>", line 971, in _find_and_load
<br />  File "<frozen importlib._bootstrap>", line 955, in _find_and_load_unlocked
<br />  File "<frozen importlib._bootstrap>", line 665, in _load_unlocked
<br />  File "<frozen importlib._bootstrap_external>", line 678, in exec_module
<br />  File "<frozen importlib._bootstrap>", line 219, in _call_with_frames_removed
<br />  File "https://github.com/arita37/mlmodels/tree/ff21906d63b46d89670bd3ed148b01355ca5ff0e/mlmodels/model_tch/textcnn.py", line 24, in <module>
<br />    import torchtext
<br />  File "/opt/hostedtoolcache/Python/3.6.12/x64/lib/python3.6/site-packages/torchtext/__init__.py", line 42, in <module>
<br />    _init_extension()
<br />  File "/opt/hostedtoolcache/Python/3.6.12/x64/lib/python3.6/site-packages/torchtext/__init__.py", line 38, in _init_extension
<br />    torch.ops.load_library(ext_specs.origin)
<br />  File "/opt/hostedtoolcache/Python/3.6.12/x64/lib/python3.6/site-packages/torch/_ops.py", line 106, in load_library
<br />    ctypes.CDLL(path)
<br />  File "/opt/hostedtoolcache/Python/3.6.12/x64/lib/python3.6/ctypes/__init__.py", line 348, in __init__
<br />    self._handle = _dlopen(self._name, mode)
<br />OSError: libtorch_cpu.so: cannot open shared object file: No such file or directory



### Error 126, [Traceback at line 2766](https://github.com/arita37/mlmodels_store/blob/master/log_json/log_json.py#L2766)<br />2766..Traceback (most recent call last):
<br />  File "https://github.com/arita37/mlmodels/tree/ff21906d63b46d89670bd3ed148b01355ca5ff0e/mlmodels/models.py", line 84, in module_load
<br />    model_name = str(Path(model_uri).parts[-2]) + "." + str(model_name)
<br />IndexError: tuple index out of range



### Error 127, [Traceback at line 2773](https://github.com/arita37/mlmodels_store/blob/master/log_json/log_json.py#L2773)<br />2773..Traceback (most recent call last):
<br />  File "/opt/hostedtoolcache/Python/3.6.12/x64/bin/ml_models", line 11, in <module>
<br />    load_entry_point('mlmodels', 'console_scripts', 'ml_models')()
<br />  File "https://github.com/arita37/mlmodels/tree/ff21906d63b46d89670bd3ed148b01355ca5ff0e/mlmodels/models.py", line 530, in main
<br />    fit_cli(arg)
<br />  File "https://github.com/arita37/mlmodels/tree/ff21906d63b46d89670bd3ed148b01355ca5ff0e/mlmodels/models.py", line 420, in fit_cli
<br />    module = module_load(model_uri)  # '1_lstm.py
<br />  File "https://github.com/arita37/mlmodels/tree/ff21906d63b46d89670bd3ed148b01355ca5ff0e/mlmodels/models.py", line 89, in module_load
<br />    raise NameError(f"Module {model_name} notfound, {e1}, {e2}")
<br />NameError: Module model_tch.textcnn notfound, libtorch_cpu.so: cannot open shared object file: No such file or directory, tuple index out of range



### Error 128, [Traceback at line 2794](https://github.com/arita37/mlmodels_store/blob/master/log_json/log_json.py#L2794)<br />2794..Traceback (most recent call last):
<br />  File "/opt/hostedtoolcache/Python/3.6.12/x64/bin/ml_models", line 11, in <module>
<br />    load_entry_point('mlmodels', 'console_scripts', 'ml_models')()
<br />  File "https://github.com/arita37/mlmodels/tree/ff21906d63b46d89670bd3ed148b01355ca5ff0e/mlmodels/models.py", line 530, in main
<br />    fit_cli(arg)
<br />  File "https://github.com/arita37/mlmodels/tree/ff21906d63b46d89670bd3ed148b01355ca5ff0e/mlmodels/models.py", line 413, in fit_cli
<br />    model_p, data_p, compute_p, out_p = config_get_pars(config_file, arg.config_mode)
<br />  File "https://github.com/arita37/mlmodels/tree/ff21906d63b46d89670bd3ed148b01355ca5ff0e/mlmodels/models.py", line 297, in config_get_pars
<br />    data_p    = path_norm_dict( js.get("data_pars") )
<br />  File "https://github.com/arita37/mlmodels/tree/ff21906d63b46d89670bd3ed148b01355ca5ff0e/mlmodels/util.py", line 201, in path_norm_dict
<br />    for k,v in ddict.items():
<br />AttributeError: 'NoneType' object has no attribute 'items'



### Error 129, [Traceback at line 2825](https://github.com/arita37/mlmodels_store/blob/master/log_json/log_json.py#L2825)<br />2825..Traceback (most recent call last):
<br />  File "/opt/hostedtoolcache/Python/3.6.12/x64/bin/ml_models", line 11, in <module>
<br />    load_entry_point('mlmodels', 'console_scripts', 'ml_models')()
<br />  File "https://github.com/arita37/mlmodels/tree/ff21906d63b46d89670bd3ed148b01355ca5ff0e/mlmodels/models.py", line 530, in main
<br />    fit_cli(arg)
<br />  File "https://github.com/arita37/mlmodels/tree/ff21906d63b46d89670bd3ed148b01355ca5ff0e/mlmodels/models.py", line 421, in fit_cli
<br />    model = model_create(module, model_p, data_p, compute_p)  # Exact map JSON and paramters
<br />  File "https://github.com/arita37/mlmodels/tree/ff21906d63b46d89670bd3ed148b01355ca5ff0e/mlmodels/models.py", line 113, in model_create
<br />    module.init(model_pars=model_pars, data_pars=data_pars, compute_pars=compute_pars, **kwarg)
<br />AttributeError: module 'mlmodels.model_keras.textcnn' has no attribute 'init'



### Error 130, [Traceback at line 2846](https://github.com/arita37/mlmodels_store/blob/master/log_json/log_json.py#L2846)<br />2846..Traceback (most recent call last):
<br />  File "/opt/hostedtoolcache/Python/3.6.12/x64/bin/ml_models", line 11, in <module>
<br />    load_entry_point('mlmodels', 'console_scripts', 'ml_models')()
<br />  File "https://github.com/arita37/mlmodels/tree/ff21906d63b46d89670bd3ed148b01355ca5ff0e/mlmodels/models.py", line 530, in main
<br />    fit_cli(arg)
<br />  File "https://github.com/arita37/mlmodels/tree/ff21906d63b46d89670bd3ed148b01355ca5ff0e/mlmodels/models.py", line 413, in fit_cli
<br />    model_p, data_p, compute_p, out_p = config_get_pars(config_file, arg.config_mode)
<br />  File "https://github.com/arita37/mlmodels/tree/ff21906d63b46d89670bd3ed148b01355ca5ff0e/mlmodels/models.py", line 299, in config_get_pars
<br />    out_p     = path_norm_dict( js.get("out_pars") )
<br />  File "https://github.com/arita37/mlmodels/tree/ff21906d63b46d89670bd3ed148b01355ca5ff0e/mlmodels/util.py", line 201, in path_norm_dict
<br />    for k,v in ddict.items():
<br />AttributeError: 'NoneType' object has no attribute 'items'



### Error 131, [Traceback at line 2877](https://github.com/arita37/mlmodels_store/blob/master/log_json/log_json.py#L2877)<br />2877..Traceback (most recent call last):
<br />  File "/opt/hostedtoolcache/Python/3.6.12/x64/bin/ml_models", line 11, in <module>
<br />    load_entry_point('mlmodels', 'console_scripts', 'ml_models')()
<br />  File "https://github.com/arita37/mlmodels/tree/ff21906d63b46d89670bd3ed148b01355ca5ff0e/mlmodels/models.py", line 530, in main
<br />    fit_cli(arg)
<br />  File "https://github.com/arita37/mlmodels/tree/ff21906d63b46d89670bd3ed148b01355ca5ff0e/mlmodels/models.py", line 421, in fit_cli
<br />    model = model_create(module, model_p, data_p, compute_p)  # Exact map JSON and paramters
<br />  File "https://github.com/arita37/mlmodels/tree/ff21906d63b46d89670bd3ed148b01355ca5ff0e/mlmodels/models.py", line 113, in model_create
<br />    module.init(model_pars=model_pars, data_pars=data_pars, compute_pars=compute_pars, **kwarg)
<br />AttributeError: module 'mlmodels.model_keras.namentity_crm_bilstm' has no attribute 'init'



### Error 132, [Traceback at line 2898](https://github.com/arita37/mlmodels_store/blob/master/log_json/log_json.py#L2898)<br />2898..Traceback (most recent call last):
<br />  File "/opt/hostedtoolcache/Python/3.6.12/x64/bin/ml_models", line 11, in <module>
<br />    load_entry_point('mlmodels', 'console_scripts', 'ml_models')()
<br />  File "https://github.com/arita37/mlmodels/tree/ff21906d63b46d89670bd3ed148b01355ca5ff0e/mlmodels/models.py", line 530, in main
<br />    fit_cli(arg)
<br />  File "https://github.com/arita37/mlmodels/tree/ff21906d63b46d89670bd3ed148b01355ca5ff0e/mlmodels/models.py", line 413, in fit_cli
<br />    model_p, data_p, compute_p, out_p = config_get_pars(config_file, arg.config_mode)
<br />  File "https://github.com/arita37/mlmodels/tree/ff21906d63b46d89670bd3ed148b01355ca5ff0e/mlmodels/models.py", line 299, in config_get_pars
<br />    out_p     = path_norm_dict( js.get("out_pars") )
<br />  File "https://github.com/arita37/mlmodels/tree/ff21906d63b46d89670bd3ed148b01355ca5ff0e/mlmodels/util.py", line 201, in path_norm_dict
<br />    for k,v in ddict.items():
<br />AttributeError: 'NoneType' object has no attribute 'items'



### Error 133, [Traceback at line 2928](https://github.com/arita37/mlmodels_store/blob/master/log_json/log_json.py#L2928)<br />2928..Traceback (most recent call last):
<br />  File "https://github.com/arita37/mlmodels/tree/ff21906d63b46d89670bd3ed148b01355ca5ff0e/mlmodels/models.py", line 72, in module_load
<br />    module = import_module(f"mlmodels.{model_name}")
<br />  File "/opt/hostedtoolcache/Python/3.6.12/x64/lib/python3.6/importlib/__init__.py", line 126, in import_module
<br />    return _bootstrap._gcd_import(name[level:], package, level)
<br />  File "<frozen importlib._bootstrap>", line 994, in _gcd_import
<br />  File "<frozen importlib._bootstrap>", line 971, in _find_and_load
<br />  File "<frozen importlib._bootstrap>", line 955, in _find_and_load_unlocked
<br />  File "<frozen importlib._bootstrap>", line 665, in _load_unlocked
<br />  File "<frozen importlib._bootstrap_external>", line 678, in exec_module
<br />  File "<frozen importlib._bootstrap>", line 219, in _call_with_frames_removed
<br />  File "https://github.com/arita37/mlmodels/tree/ff21906d63b46d89670bd3ed148b01355ca5ff0e/mlmodels/model_keras/Autokeras.py", line 12, in <module>
<br />    import autokeras as ak
<br />ModuleNotFoundError: No module named 'autokeras'



### Error 134, [Traceback at line 2945](https://github.com/arita37/mlmodels_store/blob/master/log_json/log_json.py#L2945)<br />2945..Traceback (most recent call last):
<br />  File "https://github.com/arita37/mlmodels/tree/ff21906d63b46d89670bd3ed148b01355ca5ff0e/mlmodels/models.py", line 84, in module_load
<br />    model_name = str(Path(model_uri).parts[-2]) + "." + str(model_name)
<br />IndexError: tuple index out of range



### Error 135, [Traceback at line 2952](https://github.com/arita37/mlmodels_store/blob/master/log_json/log_json.py#L2952)<br />2952..Traceback (most recent call last):
<br />  File "/opt/hostedtoolcache/Python/3.6.12/x64/bin/ml_models", line 11, in <module>
<br />    load_entry_point('mlmodels', 'console_scripts', 'ml_models')()
<br />  File "https://github.com/arita37/mlmodels/tree/ff21906d63b46d89670bd3ed148b01355ca5ff0e/mlmodels/models.py", line 530, in main
<br />    fit_cli(arg)
<br />  File "https://github.com/arita37/mlmodels/tree/ff21906d63b46d89670bd3ed148b01355ca5ff0e/mlmodels/models.py", line 420, in fit_cli
<br />    module = module_load(model_uri)  # '1_lstm.py
<br />  File "https://github.com/arita37/mlmodels/tree/ff21906d63b46d89670bd3ed148b01355ca5ff0e/mlmodels/models.py", line 89, in module_load
<br />    raise NameError(f"Module {model_name} notfound, {e1}, {e2}")
<br />NameError: Module model_keras.Autokeras notfound, No module named 'autokeras', tuple index out of range



### Error 136, [Traceback at line 2973](https://github.com/arita37/mlmodels_store/blob/master/log_json/log_json.py#L2973)<br />2973..Traceback (most recent call last):
<br />  File "/opt/hostedtoolcache/Python/3.6.12/x64/bin/ml_models", line 11, in <module>
<br />    load_entry_point('mlmodels', 'console_scripts', 'ml_models')()
<br />  File "https://github.com/arita37/mlmodels/tree/ff21906d63b46d89670bd3ed148b01355ca5ff0e/mlmodels/models.py", line 530, in main
<br />    fit_cli(arg)
<br />  File "https://github.com/arita37/mlmodels/tree/ff21906d63b46d89670bd3ed148b01355ca5ff0e/mlmodels/models.py", line 413, in fit_cli
<br />    model_p, data_p, compute_p, out_p = config_get_pars(config_file, arg.config_mode)
<br />  File "https://github.com/arita37/mlmodels/tree/ff21906d63b46d89670bd3ed148b01355ca5ff0e/mlmodels/models.py", line 299, in config_get_pars
<br />    out_p     = path_norm_dict( js.get("out_pars") )
<br />  File "https://github.com/arita37/mlmodels/tree/ff21906d63b46d89670bd3ed148b01355ca5ff0e/mlmodels/util.py", line 201, in path_norm_dict
<br />    for k,v in ddict.items():
<br />AttributeError: 'NoneType' object has no attribute 'items'



### Error 137, [Traceback at line 3003](https://github.com/arita37/mlmodels_store/blob/master/log_json/log_json.py#L3003)<br />3003..Traceback (most recent call last):
<br />  File "https://github.com/arita37/mlmodels/tree/ff21906d63b46d89670bd3ed148b01355ca5ff0e/mlmodels/models.py", line 72, in module_load
<br />    module = import_module(f"mlmodels.{model_name}")
<br />  File "/opt/hostedtoolcache/Python/3.6.12/x64/lib/python3.6/importlib/__init__.py", line 126, in import_module
<br />    return _bootstrap._gcd_import(name[level:], package, level)
<br />  File "<frozen importlib._bootstrap>", line 994, in _gcd_import
<br />  File "<frozen importlib._bootstrap>", line 971, in _find_and_load
<br />  File "<frozen importlib._bootstrap>", line 953, in _find_and_load_unlocked
<br />ModuleNotFoundError: No module named 'mlmodels.model_keras.textvae'



### Error 138, [Traceback at line 3015](https://github.com/arita37/mlmodels_store/blob/master/log_json/log_json.py#L3015)<br />3015..Traceback (most recent call last):
<br />  File "https://github.com/arita37/mlmodels/tree/ff21906d63b46d89670bd3ed148b01355ca5ff0e/mlmodels/models.py", line 84, in module_load
<br />    model_name = str(Path(model_uri).parts[-2]) + "." + str(model_name)
<br />IndexError: tuple index out of range



### Error 139, [Traceback at line 3022](https://github.com/arita37/mlmodels_store/blob/master/log_json/log_json.py#L3022)<br />3022..Traceback (most recent call last):
<br />  File "/opt/hostedtoolcache/Python/3.6.12/x64/bin/ml_models", line 11, in <module>
<br />    load_entry_point('mlmodels', 'console_scripts', 'ml_models')()
<br />  File "https://github.com/arita37/mlmodels/tree/ff21906d63b46d89670bd3ed148b01355ca5ff0e/mlmodels/models.py", line 530, in main
<br />    fit_cli(arg)
<br />  File "https://github.com/arita37/mlmodels/tree/ff21906d63b46d89670bd3ed148b01355ca5ff0e/mlmodels/models.py", line 420, in fit_cli
<br />    module = module_load(model_uri)  # '1_lstm.py
<br />  File "https://github.com/arita37/mlmodels/tree/ff21906d63b46d89670bd3ed148b01355ca5ff0e/mlmodels/models.py", line 89, in module_load
<br />    raise NameError(f"Module {model_name} notfound, {e1}, {e2}")
<br />NameError: Module model_keras.textvae notfound, No module named 'mlmodels.model_keras.textvae', tuple index out of range



### Error 140, [Traceback at line 3043](https://github.com/arita37/mlmodels_store/blob/master/log_json/log_json.py#L3043)<br />3043..Traceback (most recent call last):
<br />  File "/opt/hostedtoolcache/Python/3.6.12/x64/bin/ml_models", line 11, in <module>
<br />    load_entry_point('mlmodels', 'console_scripts', 'ml_models')()
<br />  File "https://github.com/arita37/mlmodels/tree/ff21906d63b46d89670bd3ed148b01355ca5ff0e/mlmodels/models.py", line 530, in main
<br />    fit_cli(arg)
<br />  File "https://github.com/arita37/mlmodels/tree/ff21906d63b46d89670bd3ed148b01355ca5ff0e/mlmodels/models.py", line 413, in fit_cli
<br />    model_p, data_p, compute_p, out_p = config_get_pars(config_file, arg.config_mode)
<br />  File "https://github.com/arita37/mlmodels/tree/ff21906d63b46d89670bd3ed148b01355ca5ff0e/mlmodels/models.py", line 299, in config_get_pars
<br />    out_p     = path_norm_dict( js.get("out_pars") )
<br />  File "https://github.com/arita37/mlmodels/tree/ff21906d63b46d89670bd3ed148b01355ca5ff0e/mlmodels/util.py", line 201, in path_norm_dict
<br />    for k,v in ddict.items():
<br />AttributeError: 'NoneType' object has no attribute 'items'



### Error 141, [Traceback at line 3071](https://github.com/arita37/mlmodels_store/blob/master/log_json/log_json.py#L3071)<br />3071..Traceback (most recent call last):
<br />  File "/opt/hostedtoolcache/Python/3.6.12/x64/bin/ml_models", line 11, in <module>
<br />    load_entry_point('mlmodels', 'console_scripts', 'ml_models')()
<br />  File "https://github.com/arita37/mlmodels/tree/ff21906d63b46d89670bd3ed148b01355ca5ff0e/mlmodels/models.py", line 530, in main
<br />    fit_cli(arg)
<br />  File "https://github.com/arita37/mlmodels/tree/ff21906d63b46d89670bd3ed148b01355ca5ff0e/mlmodels/models.py", line 415, in fit_cli
<br />    path      = out_p['path']
<br />KeyError: 'path'



### Error 142, [Traceback at line 3090](https://github.com/arita37/mlmodels_store/blob/master/log_json/log_json.py#L3090)<br />3090..Traceback (most recent call last):
<br />  File "/opt/hostedtoolcache/Python/3.6.12/x64/bin/ml_models", line 11, in <module>
<br />    load_entry_point('mlmodels', 'console_scripts', 'ml_models')()
<br />  File "https://github.com/arita37/mlmodels/tree/ff21906d63b46d89670bd3ed148b01355ca5ff0e/mlmodels/models.py", line 530, in main
<br />    fit_cli(arg)
<br />  File "https://github.com/arita37/mlmodels/tree/ff21906d63b46d89670bd3ed148b01355ca5ff0e/mlmodels/models.py", line 413, in fit_cli
<br />    model_p, data_p, compute_p, out_p = config_get_pars(config_file, arg.config_mode)
<br />  File "https://github.com/arita37/mlmodels/tree/ff21906d63b46d89670bd3ed148b01355ca5ff0e/mlmodels/models.py", line 299, in config_get_pars
<br />    out_p     = path_norm_dict( js.get("out_pars") )
<br />  File "https://github.com/arita37/mlmodels/tree/ff21906d63b46d89670bd3ed148b01355ca5ff0e/mlmodels/util.py", line 201, in path_norm_dict
<br />    for k,v in ddict.items():
<br />AttributeError: 'NoneType' object has no attribute 'items'
