
  test_json_all /home/runner/work/mlmodels/mlmodels/mlmodels/config/test_config.json Namespace(config_file='/home/runner/work/mlmodels/mlmodels/mlmodels/config/test_config.json', config_mode='test', do='test_json_all', folder=None, log_file=None, name='ml_store', save_folder='ztest/') 

  ml_test --do test_json_all 





 ********************************************************************************************************************************************

 ******** TAG ::  {'github_repo_url': 'https://github.com/arita37/mlmodels/tree/e150e697a137dd0bef43d4d59bcd286198f46522', 'url_branch_file': 'https://github.com/arita37/mlmodels/blob/dev/', 'repo': 'arita37/mlmodels', 'branch': 'dev', 'sha': 'e150e697a137dd0bef43d4d59bcd286198f46522', 'workflow': 'test_json'}

 ******** GITHUB_WOKFLOW : https://github.com/arita37/mlmodels/actions?query=workflow%3Atest_json

 ******** GITHUB_REPO_BRANCH : https://github.com/arita37/mlmodels/tree/dev/

 ******** GITHUB_REPO_URL : https://github.com/arita37/mlmodels/tree/e150e697a137dd0bef43d4d59bcd286198f46522

 ******** GITHUB_COMMIT_URL : https://github.com/arita37/mlmodels/commit/e150e697a137dd0bef43d4d59bcd286198f46522

 ******** Click here for Online DEBUGGER : https://gitpod.io/#https://github.com/arita37/mlmodels/tree/e150e697a137dd0bef43d4d59bcd286198f46522

 ************************************************************************************************************************

  /home/runner/work/mlmodels/mlmodels/mlmodels/ 

  /home/runner/work/mlmodels/mlmodels/mlmodels/dataset/json/ 

  ############ List of files ################################ 
List of JSON Files ['/home/runner/work/mlmodels/mlmodels/mlmodels/dataset/json/benchmark_timeseries/test01/gluonts_deepar.json', '/home/runner/work/mlmodels/mlmodels/mlmodels/dataset/json/benchmark_timeseries/test01/armdn.json', '/home/runner/work/mlmodels/mlmodels/mlmodels/dataset/json/benchmark_timeseries/test01/fbprophet.json', '/home/runner/work/mlmodels/mlmodels/mlmodels/dataset/json/benchmark_timeseries/test01/nbeats.json', '/home/runner/work/mlmodels/mlmodels/mlmodels/dataset/json/benchmark_timeseries/test02/model_list.json', '/home/runner/work/mlmodels/mlmodels/mlmodels/dataset/json/benchmark_timeseries/test02/model_list_gluon_only.json', '/home/runner/work/mlmodels/mlmodels/mlmodels/dataset/json/refactor/notused/hyper_lightgbm_titanic.json', '/home/runner/work/mlmodels/mlmodels/mlmodels/dataset/json/refactor/notused/03_nbeats_dataloader.json', '/home/runner/work/mlmodels/mlmodels/mlmodels/dataset/json/refactor/notused/namentity_crm_bilstm_dataloader.json', '/home/runner/work/mlmodels/mlmodels/mlmodels/dataset/json/refactor/notused/lightgbm_titanic.json', '/home/runner/work/mlmodels/mlmodels/mlmodels/dataset/json/refactor/notused/sklearn_titanic_svm.json', '/home/runner/work/mlmodels/mlmodels/mlmodels/dataset/json/refactor/notused/hyper_lightgbm_glass.json', '/home/runner/work/mlmodels/mlmodels/mlmodels/dataset/json/refactor/notused/hyper_titanic_randomForest.json', '/home/runner/work/mlmodels/mlmodels/mlmodels/dataset/json/refactor/notused/fbprophet.json', '/home/runner/work/mlmodels/mlmodels/mlmodels/dataset/json/refactor/notused/gluon_automl.json', '/home/runner/work/mlmodels/mlmodels/mlmodels/dataset/json/refactor/notused/sklearn_titanic_randomForest.json', '/home/runner/work/mlmodels/mlmodels/mlmodels/dataset/json/refactor/notused/1_lstm_dataloader.json', '/home/runner/work/mlmodels/mlmodels/mlmodels/dataset/json/benchmark_cnn/zold/resnet18_fashion_mnist.json', '/home/runner/work/mlmodels/mlmodels/mlmodels/dataset/json/benchmark_cnn/zold/resnet50_benchmark_mnist.json', '/home/runner/work/mlmodels/mlmodels/mlmodels/dataset/json/benchmark_cnn/zold/resnet34_benchmark_mnist.json', '/home/runner/work/mlmodels/mlmodels/mlmodels/dataset/json/benchmark_cnn/zold/resnet18_benchmark_mnist.json', '/home/runner/work/mlmodels/mlmodels/mlmodels/dataset/json/benchmark_cnn/mnist/resnet152_benchmark_MNIST.json', '/home/runner/work/mlmodels/mlmodels/mlmodels/dataset/json/benchmark_cnn/mnist/shufflenet_v2_x1_0_benchmark_MNIST.json', '/home/runner/work/mlmodels/mlmodels/mlmodels/dataset/json/benchmark_cnn/mnist/resnext50_32x4d_benchmark_MNIST.json', '/home/runner/work/mlmodels/mlmodels/mlmodels/dataset/json/benchmark_cnn/mnist/resnext101_32x8d_benchmark_MNIST.json', '/home/runner/work/mlmodels/mlmodels/mlmodels/dataset/json/benchmark_cnn/mnist/resnet50_benchmark_MNIST.json', '/home/runner/work/mlmodels/mlmodels/mlmodels/dataset/json/benchmark_cnn/mnist/wide_resnet101_2_benchmark_MNIST.json', '/home/runner/work/mlmodels/mlmodels/mlmodels/dataset/json/benchmark_cnn/mnist/resnet101_benchmark_MNIST.json', '/home/runner/work/mlmodels/mlmodels/mlmodels/dataset/json/benchmark_cnn/mnist/wide_resnet50_2_benchmark_MNIST.json', '/home/runner/work/mlmodels/mlmodels/mlmodels/dataset/json/benchmark_cnn/mnist/resnet18_benchmark_MNIST.json', '/home/runner/work/mlmodels/mlmodels/mlmodels/dataset/json/benchmark_cnn/mnist/shufflenet_v2_x0_5_benchmark_MNIST.json', '/home/runner/work/mlmodels/mlmodels/mlmodels/dataset/json/benchmark_cnn/mnist/resnet34_benchmark_MNIST.json', '/home/runner/work/mlmodels/mlmodels/mlmodels/dataset/json/benchmark_cnn/fashion_mnist/shufflenet_v2_x0_5_benchmark_FashionMNIST.json', '/home/runner/work/mlmodels/mlmodels/mlmodels/dataset/json/benchmark_cnn/fashion_mnist/resnet152_benchmark_FashionMNIST.json', '/home/runner/work/mlmodels/mlmodels/mlmodels/dataset/json/benchmark_cnn/fashion_mnist/resnet18_benchmark_FashionMNIST.json', '/home/runner/work/mlmodels/mlmodels/mlmodels/dataset/json/benchmark_cnn/fashion_mnist/resnet34_benchmark_FashionMNIST.json', '/home/runner/work/mlmodels/mlmodels/mlmodels/dataset/json/benchmark_cnn/fashion_mnist/resnext50_32x4d_benchmark_FashionMNIST.json', '/home/runner/work/mlmodels/mlmodels/mlmodels/dataset/json/benchmark_cnn/fashion_mnist/wide_resnet101_2_benchmark_FashionMNIST.json', '/home/runner/work/mlmodels/mlmodels/mlmodels/dataset/json/benchmark_cnn/fashion_mnist/shufflenet_v2_x1_0_benchmark_FashionMNIST.json', '/home/runner/work/mlmodels/mlmodels/mlmodels/dataset/json/benchmark_cnn/fashion_mnist/wide_resnet50_2_benchmark_FashionMNIST.json', '/home/runner/work/mlmodels/mlmodels/mlmodels/dataset/json/benchmark_cnn/fashion_mnist/resnext101_32x8d_benchmark_FashionMNIST.json', '/home/runner/work/mlmodels/mlmodels/mlmodels/dataset/json/benchmark_cnn/fashion_mnist/resnet101_benchmark_FashionMNIST.json', '/home/runner/work/mlmodels/mlmodels/mlmodels/dataset/json/benchmark_cnn/fashion_mnist/resnet50_benchmark_FashionMNIST.json', '/home/runner/work/mlmodels/mlmodels/mlmodels/dataset/json/benchmark_text_classification/jsons/textcnn_tch.json', '/home/runner/work/mlmodels/mlmodels/mlmodels/dataset/json/benchmark_text_classification/jsons/textcnn_keras.json', '/home/runner/work/mlmodels/mlmodels/mlmodels/dataset/json/benchmark_text_classification/jsons/namentity_crm_bilstm.json', '/home/runner/work/mlmodels/mlmodels/mlmodels/dataset/json/benchmark_text_classification/jsons/autokeras_classifier.json', '/home/runner/work/mlmodels/mlmodels/mlmodels/dataset/json/benchmark_text_classification/jsons/textvae.json', '/home/runner/work/mlmodels/mlmodels/mlmodels/dataset/json/benchmark_text_classification/jsons/transformer_classifier.json']

  


 ************ JSON File /home/runner/work/mlmodels/mlmodels/mlmodels/dataset/json/benchmark_timeseries/test01/gluonts_deepar.json 





 ********************************************************************************************************************************************

  ml_models --do fit --config_file /home/runner/work/mlmodels/mlmodels/mlmodels/dataset/json/benchmark_timeseries/test01/gluonts_deepar.json  --config_mode test  
fit

  ##### Load JSON /home/runner/work/mlmodels/mlmodels/mlmodels/dataset/json/benchmark_timeseries/test01/gluonts_deepar.json 
Traceback (most recent call last):
  File "/opt/hostedtoolcache/Python/3.6.12/x64/bin/ml_models", line 11, in <module>
    load_entry_point('mlmodels', 'console_scripts', 'ml_models')()
  File "/home/runner/work/mlmodels/mlmodels/mlmodels/models.py", line 530, in main
    fit_cli(arg)
  File "/home/runner/work/mlmodels/mlmodels/mlmodels/models.py", line 414, in fit_cli
    model_uri = model_p['model_uri']
KeyError: 'model_uri'

  


 ************ JSON File /home/runner/work/mlmodels/mlmodels/mlmodels/dataset/json/benchmark_timeseries/test01/armdn.json 





 ********************************************************************************************************************************************

  ml_models --do fit --config_file /home/runner/work/mlmodels/mlmodels/mlmodels/dataset/json/benchmark_timeseries/test01/armdn.json  --config_mode test  
fit

  ##### Load JSON /home/runner/work/mlmodels/mlmodels/mlmodels/dataset/json/benchmark_timeseries/test01/armdn.json 
Traceback (most recent call last):
  File "/opt/hostedtoolcache/Python/3.6.12/x64/bin/ml_models", line 11, in <module>
    load_entry_point('mlmodels', 'console_scripts', 'ml_models')()
  File "/home/runner/work/mlmodels/mlmodels/mlmodels/models.py", line 530, in main
    fit_cli(arg)
  File "/home/runner/work/mlmodels/mlmodels/mlmodels/models.py", line 415, in fit_cli
    path      = out_p['path']
KeyError: 'path'

  


 ************ JSON File /home/runner/work/mlmodels/mlmodels/mlmodels/dataset/json/benchmark_timeseries/test01/fbprophet.json 





 ********************************************************************************************************************************************

  ml_models --do fit --config_file /home/runner/work/mlmodels/mlmodels/mlmodels/dataset/json/benchmark_timeseries/test01/fbprophet.json  --config_mode test  
fit

  ##### Load JSON /home/runner/work/mlmodels/mlmodels/mlmodels/dataset/json/benchmark_timeseries/test01/fbprophet.json 
Traceback (most recent call last):
  File "/opt/hostedtoolcache/Python/3.6.12/x64/bin/ml_models", line 11, in <module>
    load_entry_point('mlmodels', 'console_scripts', 'ml_models')()
  File "/home/runner/work/mlmodels/mlmodels/mlmodels/models.py", line 530, in main
    fit_cli(arg)
  File "/home/runner/work/mlmodels/mlmodels/mlmodels/models.py", line 415, in fit_cli
    path      = out_p['path']
KeyError: 'path'

  


 ************ JSON File /home/runner/work/mlmodels/mlmodels/mlmodels/dataset/json/benchmark_timeseries/test01/nbeats.json 





 ********************************************************************************************************************************************

  ml_models --do fit --config_file /home/runner/work/mlmodels/mlmodels/mlmodels/dataset/json/benchmark_timeseries/test01/nbeats.json  --config_mode test  
fit

  ##### Load JSON /home/runner/work/mlmodels/mlmodels/mlmodels/dataset/json/benchmark_timeseries/test01/nbeats.json 
Traceback (most recent call last):
  File "/opt/hostedtoolcache/Python/3.6.12/x64/bin/ml_models", line 11, in <module>
    load_entry_point('mlmodels', 'console_scripts', 'ml_models')()
  File "/home/runner/work/mlmodels/mlmodels/mlmodels/models.py", line 530, in main
    fit_cli(arg)
  File "/home/runner/work/mlmodels/mlmodels/mlmodels/models.py", line 415, in fit_cli
    path      = out_p['path']
KeyError: 'path'





 ********************************************************************************************************************************************

  ml_models --do fit --config_file /home/runner/work/mlmodels/mlmodels/mlmodels/dataset/json/benchmark_timeseries/test01/nbeats.json  --config_mode prod  
fit

  ##### Load JSON /home/runner/work/mlmodels/mlmodels/mlmodels/dataset/json/benchmark_timeseries/test01/nbeats.json 
Traceback (most recent call last):
  File "/opt/hostedtoolcache/Python/3.6.12/x64/bin/ml_models", line 11, in <module>
    load_entry_point('mlmodels', 'console_scripts', 'ml_models')()
  File "/home/runner/work/mlmodels/mlmodels/mlmodels/models.py", line 530, in main
    fit_cli(arg)
  File "/home/runner/work/mlmodels/mlmodels/mlmodels/models.py", line 413, in fit_cli
    model_p, data_p, compute_p, out_p = config_get_pars(config_file, arg.config_mode)
  File "/home/runner/work/mlmodels/mlmodels/mlmodels/models.py", line 297, in config_get_pars
    data_p    = path_norm_dict( js.get("data_pars") )
  File "/home/runner/work/mlmodels/mlmodels/mlmodels/util.py", line 201, in path_norm_dict
    for k,v in ddict.items():
AttributeError: 'NoneType' object has no attribute 'items'

  


 ************ JSON File /home/runner/work/mlmodels/mlmodels/mlmodels/dataset/json/benchmark_timeseries/test02/model_list.json 





 ********************************************************************************************************************************************

  ml_models --do fit --config_file /home/runner/work/mlmodels/mlmodels/mlmodels/dataset/json/benchmark_timeseries/test02/model_list.json  --config_mode fb_prophet  
fit

  ##### Load JSON /home/runner/work/mlmodels/mlmodels/mlmodels/dataset/json/benchmark_timeseries/test02/model_list.json 
Traceback (most recent call last):
  File "/opt/hostedtoolcache/Python/3.6.12/x64/bin/ml_models", line 11, in <module>
    load_entry_point('mlmodels', 'console_scripts', 'ml_models')()
  File "/home/runner/work/mlmodels/mlmodels/mlmodels/models.py", line 530, in main
    fit_cli(arg)
  File "/home/runner/work/mlmodels/mlmodels/mlmodels/models.py", line 415, in fit_cli
    path      = out_p['path']
KeyError: 'path'





 ********************************************************************************************************************************************

  ml_models --do fit --config_file /home/runner/work/mlmodels/mlmodels/mlmodels/dataset/json/benchmark_timeseries/test02/model_list.json  --config_mode armdn  
fit

  ##### Load JSON /home/runner/work/mlmodels/mlmodels/mlmodels/dataset/json/benchmark_timeseries/test02/model_list.json 
Traceback (most recent call last):
  File "/opt/hostedtoolcache/Python/3.6.12/x64/bin/ml_models", line 11, in <module>
    load_entry_point('mlmodels', 'console_scripts', 'ml_models')()
  File "/home/runner/work/mlmodels/mlmodels/mlmodels/models.py", line 530, in main
    fit_cli(arg)
  File "/home/runner/work/mlmodels/mlmodels/mlmodels/models.py", line 415, in fit_cli
    path      = out_p['path']
KeyError: 'path'





 ********************************************************************************************************************************************

  ml_models --do fit --config_file /home/runner/work/mlmodels/mlmodels/mlmodels/dataset/json/benchmark_timeseries/test02/model_list.json  --config_mode nbeats  
fit

  ##### Load JSON /home/runner/work/mlmodels/mlmodels/mlmodels/dataset/json/benchmark_timeseries/test02/model_list.json 
Traceback (most recent call last):
  File "/opt/hostedtoolcache/Python/3.6.12/x64/bin/ml_models", line 11, in <module>
    load_entry_point('mlmodels', 'console_scripts', 'ml_models')()
  File "/home/runner/work/mlmodels/mlmodels/mlmodels/models.py", line 530, in main
    fit_cli(arg)
  File "/home/runner/work/mlmodels/mlmodels/mlmodels/models.py", line 415, in fit_cli
    path      = out_p['path']
KeyError: 'path'





 ********************************************************************************************************************************************

  ml_models --do fit --config_file /home/runner/work/mlmodels/mlmodels/mlmodels/dataset/json/benchmark_timeseries/test02/model_list.json  --config_mode deepar  
fit

  ##### Load JSON /home/runner/work/mlmodels/mlmodels/mlmodels/dataset/json/benchmark_timeseries/test02/model_list.json 

  ##### Init model_gluon.gluonts_model {'path': '/home/runner/work/mlmodels/mlmodels/mlmodels/ztest/model_gluon/gluonts_deepar/', 'model_uri': 'model_gluon.gluonts_model'} 
Traceback (most recent call last):
  File "/home/runner/work/mlmodels/mlmodels/mlmodels/models.py", line 72, in module_load
    module = import_module(f"mlmodels.{model_name}")
  File "/opt/hostedtoolcache/Python/3.6.12/x64/lib/python3.6/importlib/__init__.py", line 126, in import_module
    return _bootstrap._gcd_import(name[level:], package, level)
  File "<frozen importlib._bootstrap>", line 994, in _gcd_import
  File "<frozen importlib._bootstrap>", line 971, in _find_and_load
  File "<frozen importlib._bootstrap>", line 955, in _find_and_load_unlocked
  File "<frozen importlib._bootstrap>", line 665, in _load_unlocked
  File "<frozen importlib._bootstrap_external>", line 674, in exec_module
  File "<frozen importlib._bootstrap_external>", line 781, in get_code
  File "<frozen importlib._bootstrap_external>", line 741, in source_to_code
  File "<frozen importlib._bootstrap>", line 219, in _call_with_frames_removed
  File "/home/runner/work/mlmodels/mlmodels/mlmodels/model_gluon/gluonts_model.py", line 203
    if d ==  "single_dataframe" :
                                ^
SyntaxError: invalid syntax

During handling of the above exception, another exception occurred:

Traceback (most recent call last):
  File "/home/runner/work/mlmodels/mlmodels/mlmodels/models.py", line 84, in module_load
    model_name = str(Path(model_uri).parts[-2]) + "." + str(model_name)
IndexError: tuple index out of range

During handling of the above exception, another exception occurred:

Traceback (most recent call last):
  File "/opt/hostedtoolcache/Python/3.6.12/x64/bin/ml_models", line 11, in <module>
    load_entry_point('mlmodels', 'console_scripts', 'ml_models')()
  File "/home/runner/work/mlmodels/mlmodels/mlmodels/models.py", line 530, in main
    fit_cli(arg)
  File "/home/runner/work/mlmodels/mlmodels/mlmodels/models.py", line 420, in fit_cli
    module = module_load(model_uri)  # '1_lstm.py
  File "/home/runner/work/mlmodels/mlmodels/mlmodels/models.py", line 89, in module_load
    raise NameError(f"Module {model_name} notfound, {e1}, {e2}")
NameError: Module model_gluon notfound, invalid syntax (gluonts_model.py, line 203), tuple index out of range





 ********************************************************************************************************************************************

  ml_models --do fit --config_file /home/runner/work/mlmodels/mlmodels/mlmodels/dataset/json/benchmark_timeseries/test02/model_list.json  --config_mode deepfactor  
fit

  ##### Load JSON /home/runner/work/mlmodels/mlmodels/mlmodels/dataset/json/benchmark_timeseries/test02/model_list.json 

  ##### Init model_gluon.gluonts_model {'path': '/home/runner/work/mlmodels/mlmodels/mlmodels/ztest/model_gluon/gluonts_deepfactor/', 'model_uri': 'model_gluon.gluonts_model'} 
Traceback (most recent call last):
  File "/home/runner/work/mlmodels/mlmodels/mlmodels/models.py", line 72, in module_load
    module = import_module(f"mlmodels.{model_name}")
  File "/opt/hostedtoolcache/Python/3.6.12/x64/lib/python3.6/importlib/__init__.py", line 126, in import_module
    return _bootstrap._gcd_import(name[level:], package, level)
  File "<frozen importlib._bootstrap>", line 994, in _gcd_import
  File "<frozen importlib._bootstrap>", line 971, in _find_and_load
  File "<frozen importlib._bootstrap>", line 955, in _find_and_load_unlocked
  File "<frozen importlib._bootstrap>", line 665, in _load_unlocked
  File "<frozen importlib._bootstrap_external>", line 674, in exec_module
  File "<frozen importlib._bootstrap_external>", line 781, in get_code
  File "<frozen importlib._bootstrap_external>", line 741, in source_to_code
  File "<frozen importlib._bootstrap>", line 219, in _call_with_frames_removed
  File "/home/runner/work/mlmodels/mlmodels/mlmodels/model_gluon/gluonts_model.py", line 203
    if d ==  "single_dataframe" :
                                ^
SyntaxError: invalid syntax

During handling of the above exception, another exception occurred:

Traceback (most recent call last):
  File "/home/runner/work/mlmodels/mlmodels/mlmodels/models.py", line 84, in module_load
    model_name = str(Path(model_uri).parts[-2]) + "." + str(model_name)
IndexError: tuple index out of range

During handling of the above exception, another exception occurred:

Traceback (most recent call last):
  File "/opt/hostedtoolcache/Python/3.6.12/x64/bin/ml_models", line 11, in <module>
    load_entry_point('mlmodels', 'console_scripts', 'ml_models')()
  File "/home/runner/work/mlmodels/mlmodels/mlmodels/models.py", line 530, in main
    fit_cli(arg)
  File "/home/runner/work/mlmodels/mlmodels/mlmodels/models.py", line 420, in fit_cli
    module = module_load(model_uri)  # '1_lstm.py
  File "/home/runner/work/mlmodels/mlmodels/mlmodels/models.py", line 89, in module_load
    raise NameError(f"Module {model_name} notfound, {e1}, {e2}")
NameError: Module model_gluon notfound, invalid syntax (gluonts_model.py, line 203), tuple index out of range





 ********************************************************************************************************************************************

  ml_models --do fit --config_file /home/runner/work/mlmodels/mlmodels/mlmodels/dataset/json/benchmark_timeseries/test02/model_list.json  --config_mode wavenet  
fit

  ##### Load JSON /home/runner/work/mlmodels/mlmodels/mlmodels/dataset/json/benchmark_timeseries/test02/model_list.json 

  ##### Init model_gluon.gluonts_model {'path': '/home/runner/work/mlmodels/mlmodels/mlmodels/ztest/model_gluon/gluonts_wavenet/', 'model_uri': 'model_gluon.gluonts_model'} 
Traceback (most recent call last):
  File "/home/runner/work/mlmodels/mlmodels/mlmodels/models.py", line 72, in module_load
    module = import_module(f"mlmodels.{model_name}")
  File "/opt/hostedtoolcache/Python/3.6.12/x64/lib/python3.6/importlib/__init__.py", line 126, in import_module
    return _bootstrap._gcd_import(name[level:], package, level)
  File "<frozen importlib._bootstrap>", line 994, in _gcd_import
  File "<frozen importlib._bootstrap>", line 971, in _find_and_load
  File "<frozen importlib._bootstrap>", line 955, in _find_and_load_unlocked
  File "<frozen importlib._bootstrap>", line 665, in _load_unlocked
  File "<frozen importlib._bootstrap_external>", line 674, in exec_module
  File "<frozen importlib._bootstrap_external>", line 781, in get_code
  File "<frozen importlib._bootstrap_external>", line 741, in source_to_code
  File "<frozen importlib._bootstrap>", line 219, in _call_with_frames_removed
  File "/home/runner/work/mlmodels/mlmodels/mlmodels/model_gluon/gluonts_model.py", line 203
    if d ==  "single_dataframe" :
                                ^
SyntaxError: invalid syntax

During handling of the above exception, another exception occurred:

Traceback (most recent call last):
  File "/home/runner/work/mlmodels/mlmodels/mlmodels/models.py", line 84, in module_load
    model_name = str(Path(model_uri).parts[-2]) + "." + str(model_name)
IndexError: tuple index out of range

During handling of the above exception, another exception occurred:

Traceback (most recent call last):
  File "/opt/hostedtoolcache/Python/3.6.12/x64/bin/ml_models", line 11, in <module>
    load_entry_point('mlmodels', 'console_scripts', 'ml_models')()
  File "/home/runner/work/mlmodels/mlmodels/mlmodels/models.py", line 530, in main
    fit_cli(arg)
  File "/home/runner/work/mlmodels/mlmodels/mlmodels/models.py", line 420, in fit_cli
    module = module_load(model_uri)  # '1_lstm.py
  File "/home/runner/work/mlmodels/mlmodels/mlmodels/models.py", line 89, in module_load
    raise NameError(f"Module {model_name} notfound, {e1}, {e2}")
NameError: Module model_gluon notfound, invalid syntax (gluonts_model.py, line 203), tuple index out of range





 ********************************************************************************************************************************************

  ml_models --do fit --config_file /home/runner/work/mlmodels/mlmodels/mlmodels/dataset/json/benchmark_timeseries/test02/model_list.json  --config_mode transformer  
fit

  ##### Load JSON /home/runner/work/mlmodels/mlmodels/mlmodels/dataset/json/benchmark_timeseries/test02/model_list.json 

  ##### Init model_gluon.gluonts_model {'path': '/home/runner/work/mlmodels/mlmodels/mlmodels/ztest/model_gluon/gluonts_transformer/', 'model_uri': 'model_gluon.gluonts_model'} 
Traceback (most recent call last):
  File "/home/runner/work/mlmodels/mlmodels/mlmodels/models.py", line 72, in module_load
    module = import_module(f"mlmodels.{model_name}")
  File "/opt/hostedtoolcache/Python/3.6.12/x64/lib/python3.6/importlib/__init__.py", line 126, in import_module
    return _bootstrap._gcd_import(name[level:], package, level)
  File "<frozen importlib._bootstrap>", line 994, in _gcd_import
  File "<frozen importlib._bootstrap>", line 971, in _find_and_load
  File "<frozen importlib._bootstrap>", line 955, in _find_and_load_unlocked
  File "<frozen importlib._bootstrap>", line 665, in _load_unlocked
  File "<frozen importlib._bootstrap_external>", line 674, in exec_module
  File "<frozen importlib._bootstrap_external>", line 781, in get_code
  File "<frozen importlib._bootstrap_external>", line 741, in source_to_code
  File "<frozen importlib._bootstrap>", line 219, in _call_with_frames_removed
  File "/home/runner/work/mlmodels/mlmodels/mlmodels/model_gluon/gluonts_model.py", line 203
    if d ==  "single_dataframe" :
                                ^
SyntaxError: invalid syntax

During handling of the above exception, another exception occurred:

Traceback (most recent call last):
  File "/home/runner/work/mlmodels/mlmodels/mlmodels/models.py", line 84, in module_load
    model_name = str(Path(model_uri).parts[-2]) + "." + str(model_name)
IndexError: tuple index out of range

During handling of the above exception, another exception occurred:

Traceback (most recent call last):
  File "/opt/hostedtoolcache/Python/3.6.12/x64/bin/ml_models", line 11, in <module>
    load_entry_point('mlmodels', 'console_scripts', 'ml_models')()
  File "/home/runner/work/mlmodels/mlmodels/mlmodels/models.py", line 530, in main
    fit_cli(arg)
  File "/home/runner/work/mlmodels/mlmodels/mlmodels/models.py", line 420, in fit_cli
    module = module_load(model_uri)  # '1_lstm.py
  File "/home/runner/work/mlmodels/mlmodels/mlmodels/models.py", line 89, in module_load
    raise NameError(f"Module {model_name} notfound, {e1}, {e2}")
NameError: Module model_gluon notfound, invalid syntax (gluonts_model.py, line 203), tuple index out of range





 ********************************************************************************************************************************************

  ml_models --do fit --config_file /home/runner/work/mlmodels/mlmodels/mlmodels/dataset/json/benchmark_timeseries/test02/model_list.json  --config_mode deepstate  
fit

  ##### Load JSON /home/runner/work/mlmodels/mlmodels/mlmodels/dataset/json/benchmark_timeseries/test02/model_list.json 

  ##### Init model_gluon.gluonts_model {'path': '/home/runner/work/mlmodels/mlmodels/mlmodels/ztest/model_gluon/gluonts_deepstate/', 'model_uri': 'model_gluon.gluonts_model'} 
Traceback (most recent call last):
  File "/home/runner/work/mlmodels/mlmodels/mlmodels/models.py", line 72, in module_load
    module = import_module(f"mlmodels.{model_name}")
  File "/opt/hostedtoolcache/Python/3.6.12/x64/lib/python3.6/importlib/__init__.py", line 126, in import_module
    return _bootstrap._gcd_import(name[level:], package, level)
  File "<frozen importlib._bootstrap>", line 994, in _gcd_import
  File "<frozen importlib._bootstrap>", line 971, in _find_and_load
  File "<frozen importlib._bootstrap>", line 955, in _find_and_load_unlocked
  File "<frozen importlib._bootstrap>", line 665, in _load_unlocked
  File "<frozen importlib._bootstrap_external>", line 674, in exec_module
  File "<frozen importlib._bootstrap_external>", line 781, in get_code
  File "<frozen importlib._bootstrap_external>", line 741, in source_to_code
  File "<frozen importlib._bootstrap>", line 219, in _call_with_frames_removed
  File "/home/runner/work/mlmodels/mlmodels/mlmodels/model_gluon/gluonts_model.py", line 203
    if d ==  "single_dataframe" :
                                ^
SyntaxError: invalid syntax

During handling of the above exception, another exception occurred:

Traceback (most recent call last):
  File "/home/runner/work/mlmodels/mlmodels/mlmodels/models.py", line 84, in module_load
    model_name = str(Path(model_uri).parts[-2]) + "." + str(model_name)
IndexError: tuple index out of range

During handling of the above exception, another exception occurred:

Traceback (most recent call last):
  File "/opt/hostedtoolcache/Python/3.6.12/x64/bin/ml_models", line 11, in <module>
    load_entry_point('mlmodels', 'console_scripts', 'ml_models')()
  File "/home/runner/work/mlmodels/mlmodels/mlmodels/models.py", line 530, in main
    fit_cli(arg)
  File "/home/runner/work/mlmodels/mlmodels/mlmodels/models.py", line 420, in fit_cli
    module = module_load(model_uri)  # '1_lstm.py
  File "/home/runner/work/mlmodels/mlmodels/mlmodels/models.py", line 89, in module_load
    raise NameError(f"Module {model_name} notfound, {e1}, {e2}")
NameError: Module model_gluon notfound, invalid syntax (gluonts_model.py, line 203), tuple index out of range





 ********************************************************************************************************************************************

  ml_models --do fit --config_file /home/runner/work/mlmodels/mlmodels/mlmodels/dataset/json/benchmark_timeseries/test02/model_list.json  --config_mode gp_forecaster  
fit

  ##### Load JSON /home/runner/work/mlmodels/mlmodels/mlmodels/dataset/json/benchmark_timeseries/test02/model_list.json 

  ##### Init model_gluon.gluonts_model {'path': '/home/runner/work/mlmodels/mlmodels/mlmodels/ztest/model_gluon/gluonts_gpforecaster/', 'model_uri': 'model_gluon.gluonts_model'} 
Traceback (most recent call last):
  File "/home/runner/work/mlmodels/mlmodels/mlmodels/models.py", line 72, in module_load
    module = import_module(f"mlmodels.{model_name}")
  File "/opt/hostedtoolcache/Python/3.6.12/x64/lib/python3.6/importlib/__init__.py", line 126, in import_module
    return _bootstrap._gcd_import(name[level:], package, level)
  File "<frozen importlib._bootstrap>", line 994, in _gcd_import
  File "<frozen importlib._bootstrap>", line 971, in _find_and_load
  File "<frozen importlib._bootstrap>", line 955, in _find_and_load_unlocked
  File "<frozen importlib._bootstrap>", line 665, in _load_unlocked
  File "<frozen importlib._bootstrap_external>", line 674, in exec_module
  File "<frozen importlib._bootstrap_external>", line 781, in get_code
  File "<frozen importlib._bootstrap_external>", line 741, in source_to_code
  File "<frozen importlib._bootstrap>", line 219, in _call_with_frames_removed
  File "/home/runner/work/mlmodels/mlmodels/mlmodels/model_gluon/gluonts_model.py", line 203
    if d ==  "single_dataframe" :
                                ^
SyntaxError: invalid syntax

During handling of the above exception, another exception occurred:

Traceback (most recent call last):
  File "/home/runner/work/mlmodels/mlmodels/mlmodels/models.py", line 84, in module_load
    model_name = str(Path(model_uri).parts[-2]) + "." + str(model_name)
IndexError: tuple index out of range

During handling of the above exception, another exception occurred:

Traceback (most recent call last):
  File "/opt/hostedtoolcache/Python/3.6.12/x64/bin/ml_models", line 11, in <module>
    load_entry_point('mlmodels', 'console_scripts', 'ml_models')()
  File "/home/runner/work/mlmodels/mlmodels/mlmodels/models.py", line 530, in main
    fit_cli(arg)
  File "/home/runner/work/mlmodels/mlmodels/mlmodels/models.py", line 420, in fit_cli
    module = module_load(model_uri)  # '1_lstm.py
  File "/home/runner/work/mlmodels/mlmodels/mlmodels/models.py", line 89, in module_load
    raise NameError(f"Module {model_name} notfound, {e1}, {e2}")
NameError: Module model_gluon notfound, invalid syntax (gluonts_model.py, line 203), tuple index out of range





 ********************************************************************************************************************************************

  ml_models --do fit --config_file /home/runner/work/mlmodels/mlmodels/mlmodels/dataset/json/benchmark_timeseries/test02/model_list.json  --config_mode feedforward  
fit

  ##### Load JSON /home/runner/work/mlmodels/mlmodels/mlmodels/dataset/json/benchmark_timeseries/test02/model_list.json 

  ##### Init model_gluon.gluonts_model {'path': '/home/runner/work/mlmodels/mlmodels/mlmodels/ztest/model_gluon/gluonts_feedforward/', 'model_uri': 'model_gluon.gluonts_model'} 
Traceback (most recent call last):
  File "/home/runner/work/mlmodels/mlmodels/mlmodels/models.py", line 72, in module_load
    module = import_module(f"mlmodels.{model_name}")
  File "/opt/hostedtoolcache/Python/3.6.12/x64/lib/python3.6/importlib/__init__.py", line 126, in import_module
    return _bootstrap._gcd_import(name[level:], package, level)
  File "<frozen importlib._bootstrap>", line 994, in _gcd_import
  File "<frozen importlib._bootstrap>", line 971, in _find_and_load
  File "<frozen importlib._bootstrap>", line 955, in _find_and_load_unlocked
  File "<frozen importlib._bootstrap>", line 665, in _load_unlocked
  File "<frozen importlib._bootstrap_external>", line 674, in exec_module
  File "<frozen importlib._bootstrap_external>", line 781, in get_code
  File "<frozen importlib._bootstrap_external>", line 741, in source_to_code
  File "<frozen importlib._bootstrap>", line 219, in _call_with_frames_removed
  File "/home/runner/work/mlmodels/mlmodels/mlmodels/model_gluon/gluonts_model.py", line 203
    if d ==  "single_dataframe" :
                                ^
SyntaxError: invalid syntax

During handling of the above exception, another exception occurred:

Traceback (most recent call last):
  File "/home/runner/work/mlmodels/mlmodels/mlmodels/models.py", line 84, in module_load
    model_name = str(Path(model_uri).parts[-2]) + "." + str(model_name)
IndexError: tuple index out of range

During handling of the above exception, another exception occurred:

Traceback (most recent call last):
  File "/opt/hostedtoolcache/Python/3.6.12/x64/bin/ml_models", line 11, in <module>
    load_entry_point('mlmodels', 'console_scripts', 'ml_models')()
  File "/home/runner/work/mlmodels/mlmodels/mlmodels/models.py", line 530, in main
    fit_cli(arg)
  File "/home/runner/work/mlmodels/mlmodels/mlmodels/models.py", line 420, in fit_cli
    module = module_load(model_uri)  # '1_lstm.py
  File "/home/runner/work/mlmodels/mlmodels/mlmodels/models.py", line 89, in module_load
    raise NameError(f"Module {model_name} notfound, {e1}, {e2}")
NameError: Module model_gluon notfound, invalid syntax (gluonts_model.py, line 203), tuple index out of range





 ********************************************************************************************************************************************

  ml_models --do fit --config_file /home/runner/work/mlmodels/mlmodels/mlmodels/dataset/json/benchmark_timeseries/test02/model_list.json  --config_mode seq2seq  
fit

  ##### Load JSON /home/runner/work/mlmodels/mlmodels/mlmodels/dataset/json/benchmark_timeseries/test02/model_list.json 

  ##### Init model_gluon.gluonts_model {'path': '/home/runner/work/mlmodels/mlmodels/mlmodels/ztest/model_gluon/gluonts_seq2seq/', 'model_uri': 'model_gluon.gluonts_model'} 
Traceback (most recent call last):
  File "/home/runner/work/mlmodels/mlmodels/mlmodels/models.py", line 72, in module_load
    module = import_module(f"mlmodels.{model_name}")
  File "/opt/hostedtoolcache/Python/3.6.12/x64/lib/python3.6/importlib/__init__.py", line 126, in import_module
    return _bootstrap._gcd_import(name[level:], package, level)
  File "<frozen importlib._bootstrap>", line 994, in _gcd_import
  File "<frozen importlib._bootstrap>", line 971, in _find_and_load
  File "<frozen importlib._bootstrap>", line 955, in _find_and_load_unlocked
  File "<frozen importlib._bootstrap>", line 665, in _load_unlocked
  File "<frozen importlib._bootstrap_external>", line 674, in exec_module
  File "<frozen importlib._bootstrap_external>", line 781, in get_code
  File "<frozen importlib._bootstrap_external>", line 741, in source_to_code
  File "<frozen importlib._bootstrap>", line 219, in _call_with_frames_removed
  File "/home/runner/work/mlmodels/mlmodels/mlmodels/model_gluon/gluonts_model.py", line 203
    if d ==  "single_dataframe" :
                                ^
SyntaxError: invalid syntax

During handling of the above exception, another exception occurred:

Traceback (most recent call last):
  File "/home/runner/work/mlmodels/mlmodels/mlmodels/models.py", line 84, in module_load
    model_name = str(Path(model_uri).parts[-2]) + "." + str(model_name)
IndexError: tuple index out of range

During handling of the above exception, another exception occurred:

Traceback (most recent call last):
  File "/opt/hostedtoolcache/Python/3.6.12/x64/bin/ml_models", line 11, in <module>
    load_entry_point('mlmodels', 'console_scripts', 'ml_models')()
  File "/home/runner/work/mlmodels/mlmodels/mlmodels/models.py", line 530, in main
    fit_cli(arg)
  File "/home/runner/work/mlmodels/mlmodels/mlmodels/models.py", line 420, in fit_cli
    module = module_load(model_uri)  # '1_lstm.py
  File "/home/runner/work/mlmodels/mlmodels/mlmodels/models.py", line 89, in module_load
    raise NameError(f"Module {model_name} notfound, {e1}, {e2}")
NameError: Module model_gluon notfound, invalid syntax (gluonts_model.py, line 203), tuple index out of range

  


 ************ JSON File /home/runner/work/mlmodels/mlmodels/mlmodels/dataset/json/benchmark_timeseries/test02/model_list_gluon_only.json 





 ********************************************************************************************************************************************

  ml_models --do fit --config_file /home/runner/work/mlmodels/mlmodels/mlmodels/dataset/json/benchmark_timeseries/test02/model_list_gluon_only.json  --config_mode deepar  
fit

  ##### Load JSON /home/runner/work/mlmodels/mlmodels/mlmodels/dataset/json/benchmark_timeseries/test02/model_list_gluon_only.json 

  ##### Init model_gluon.gluonts_model {'path': '/home/runner/work/mlmodels/mlmodels/mlmodels/ztest/model_gluon/gluonts_deepar/', 'model_uri': 'model_gluon.gluonts_model'} 
Traceback (most recent call last):
  File "/home/runner/work/mlmodels/mlmodels/mlmodels/models.py", line 72, in module_load
    module = import_module(f"mlmodels.{model_name}")
  File "/opt/hostedtoolcache/Python/3.6.12/x64/lib/python3.6/importlib/__init__.py", line 126, in import_module
    return _bootstrap._gcd_import(name[level:], package, level)
  File "<frozen importlib._bootstrap>", line 994, in _gcd_import
  File "<frozen importlib._bootstrap>", line 971, in _find_and_load
  File "<frozen importlib._bootstrap>", line 955, in _find_and_load_unlocked
  File "<frozen importlib._bootstrap>", line 665, in _load_unlocked
  File "<frozen importlib._bootstrap_external>", line 674, in exec_module
  File "<frozen importlib._bootstrap_external>", line 781, in get_code
  File "<frozen importlib._bootstrap_external>", line 741, in source_to_code
  File "<frozen importlib._bootstrap>", line 219, in _call_with_frames_removed
  File "/home/runner/work/mlmodels/mlmodels/mlmodels/model_gluon/gluonts_model.py", line 203
    if d ==  "single_dataframe" :
                                ^
SyntaxError: invalid syntax

During handling of the above exception, another exception occurred:

Traceback (most recent call last):
  File "/home/runner/work/mlmodels/mlmodels/mlmodels/models.py", line 84, in module_load
    model_name = str(Path(model_uri).parts[-2]) + "." + str(model_name)
IndexError: tuple index out of range

During handling of the above exception, another exception occurred:

Traceback (most recent call last):
  File "/opt/hostedtoolcache/Python/3.6.12/x64/bin/ml_models", line 11, in <module>
    load_entry_point('mlmodels', 'console_scripts', 'ml_models')()
  File "/home/runner/work/mlmodels/mlmodels/mlmodels/models.py", line 530, in main
    fit_cli(arg)
  File "/home/runner/work/mlmodels/mlmodels/mlmodels/models.py", line 420, in fit_cli
    module = module_load(model_uri)  # '1_lstm.py
  File "/home/runner/work/mlmodels/mlmodels/mlmodels/models.py", line 89, in module_load
    raise NameError(f"Module {model_name} notfound, {e1}, {e2}")
NameError: Module model_gluon notfound, invalid syntax (gluonts_model.py, line 203), tuple index out of range





 ********************************************************************************************************************************************

  ml_models --do fit --config_file /home/runner/work/mlmodels/mlmodels/mlmodels/dataset/json/benchmark_timeseries/test02/model_list_gluon_only.json  --config_mode deepfactor  
fit

  ##### Load JSON /home/runner/work/mlmodels/mlmodels/mlmodels/dataset/json/benchmark_timeseries/test02/model_list_gluon_only.json 

  ##### Init model_gluon.gluonts_model {'path': '/home/runner/work/mlmodels/mlmodels/mlmodels/ztest/model_gluon/gluonts_deepfactor/', 'model_uri': 'model_gluon.gluonts_model'} 
Traceback (most recent call last):
  File "/home/runner/work/mlmodels/mlmodels/mlmodels/models.py", line 72, in module_load
    module = import_module(f"mlmodels.{model_name}")
  File "/opt/hostedtoolcache/Python/3.6.12/x64/lib/python3.6/importlib/__init__.py", line 126, in import_module
    return _bootstrap._gcd_import(name[level:], package, level)
  File "<frozen importlib._bootstrap>", line 994, in _gcd_import
  File "<frozen importlib._bootstrap>", line 971, in _find_and_load
  File "<frozen importlib._bootstrap>", line 955, in _find_and_load_unlocked
  File "<frozen importlib._bootstrap>", line 665, in _load_unlocked
  File "<frozen importlib._bootstrap_external>", line 674, in exec_module
  File "<frozen importlib._bootstrap_external>", line 781, in get_code
  File "<frozen importlib._bootstrap_external>", line 741, in source_to_code
  File "<frozen importlib._bootstrap>", line 219, in _call_with_frames_removed
  File "/home/runner/work/mlmodels/mlmodels/mlmodels/model_gluon/gluonts_model.py", line 203
    if d ==  "single_dataframe" :
                                ^
SyntaxError: invalid syntax

During handling of the above exception, another exception occurred:

Traceback (most recent call last):
  File "/home/runner/work/mlmodels/mlmodels/mlmodels/models.py", line 84, in module_load
    model_name = str(Path(model_uri).parts[-2]) + "." + str(model_name)
IndexError: tuple index out of range

During handling of the above exception, another exception occurred:

Traceback (most recent call last):
  File "/opt/hostedtoolcache/Python/3.6.12/x64/bin/ml_models", line 11, in <module>
    load_entry_point('mlmodels', 'console_scripts', 'ml_models')()
  File "/home/runner/work/mlmodels/mlmodels/mlmodels/models.py", line 530, in main
    fit_cli(arg)
  File "/home/runner/work/mlmodels/mlmodels/mlmodels/models.py", line 420, in fit_cli
    module = module_load(model_uri)  # '1_lstm.py
  File "/home/runner/work/mlmodels/mlmodels/mlmodels/models.py", line 89, in module_load
    raise NameError(f"Module {model_name} notfound, {e1}, {e2}")
NameError: Module model_gluon notfound, invalid syntax (gluonts_model.py, line 203), tuple index out of range





 ********************************************************************************************************************************************

  ml_models --do fit --config_file /home/runner/work/mlmodels/mlmodels/mlmodels/dataset/json/benchmark_timeseries/test02/model_list_gluon_only.json  --config_mode wavenet  
fit

  ##### Load JSON /home/runner/work/mlmodels/mlmodels/mlmodels/dataset/json/benchmark_timeseries/test02/model_list_gluon_only.json 

  ##### Init model_gluon.gluonts_model {'path': '/home/runner/work/mlmodels/mlmodels/mlmodels/ztest/model_gluon/gluonts_wavenet/', 'model_uri': 'model_gluon.gluonts_model'} 
Traceback (most recent call last):
  File "/home/runner/work/mlmodels/mlmodels/mlmodels/models.py", line 72, in module_load
    module = import_module(f"mlmodels.{model_name}")
  File "/opt/hostedtoolcache/Python/3.6.12/x64/lib/python3.6/importlib/__init__.py", line 126, in import_module
    return _bootstrap._gcd_import(name[level:], package, level)
  File "<frozen importlib._bootstrap>", line 994, in _gcd_import
  File "<frozen importlib._bootstrap>", line 971, in _find_and_load
  File "<frozen importlib._bootstrap>", line 955, in _find_and_load_unlocked
  File "<frozen importlib._bootstrap>", line 665, in _load_unlocked
  File "<frozen importlib._bootstrap_external>", line 674, in exec_module
  File "<frozen importlib._bootstrap_external>", line 781, in get_code
  File "<frozen importlib._bootstrap_external>", line 741, in source_to_code
  File "<frozen importlib._bootstrap>", line 219, in _call_with_frames_removed
  File "/home/runner/work/mlmodels/mlmodels/mlmodels/model_gluon/gluonts_model.py", line 203
    if d ==  "single_dataframe" :
                                ^
SyntaxError: invalid syntax

During handling of the above exception, another exception occurred:

Traceback (most recent call last):
  File "/home/runner/work/mlmodels/mlmodels/mlmodels/models.py", line 84, in module_load
    model_name = str(Path(model_uri).parts[-2]) + "." + str(model_name)
IndexError: tuple index out of range

During handling of the above exception, another exception occurred:

Traceback (most recent call last):
  File "/opt/hostedtoolcache/Python/3.6.12/x64/bin/ml_models", line 11, in <module>
    load_entry_point('mlmodels', 'console_scripts', 'ml_models')()
  File "/home/runner/work/mlmodels/mlmodels/mlmodels/models.py", line 530, in main
    fit_cli(arg)
  File "/home/runner/work/mlmodels/mlmodels/mlmodels/models.py", line 420, in fit_cli
    module = module_load(model_uri)  # '1_lstm.py
  File "/home/runner/work/mlmodels/mlmodels/mlmodels/models.py", line 89, in module_load
    raise NameError(f"Module {model_name} notfound, {e1}, {e2}")
NameError: Module model_gluon notfound, invalid syntax (gluonts_model.py, line 203), tuple index out of range





 ********************************************************************************************************************************************

  ml_models --do fit --config_file /home/runner/work/mlmodels/mlmodels/mlmodels/dataset/json/benchmark_timeseries/test02/model_list_gluon_only.json  --config_mode transformer  
fit

  ##### Load JSON /home/runner/work/mlmodels/mlmodels/mlmodels/dataset/json/benchmark_timeseries/test02/model_list_gluon_only.json 

  ##### Init model_gluon.gluonts_model {'path': '/home/runner/work/mlmodels/mlmodels/mlmodels/ztest/model_gluon/gluonts_transformer/', 'model_uri': 'model_gluon.gluonts_model'} 
Traceback (most recent call last):
  File "/home/runner/work/mlmodels/mlmodels/mlmodels/models.py", line 72, in module_load
    module = import_module(f"mlmodels.{model_name}")
  File "/opt/hostedtoolcache/Python/3.6.12/x64/lib/python3.6/importlib/__init__.py", line 126, in import_module
    return _bootstrap._gcd_import(name[level:], package, level)
  File "<frozen importlib._bootstrap>", line 994, in _gcd_import
  File "<frozen importlib._bootstrap>", line 971, in _find_and_load
  File "<frozen importlib._bootstrap>", line 955, in _find_and_load_unlocked
  File "<frozen importlib._bootstrap>", line 665, in _load_unlocked
  File "<frozen importlib._bootstrap_external>", line 674, in exec_module
  File "<frozen importlib._bootstrap_external>", line 781, in get_code
  File "<frozen importlib._bootstrap_external>", line 741, in source_to_code
  File "<frozen importlib._bootstrap>", line 219, in _call_with_frames_removed
  File "/home/runner/work/mlmodels/mlmodels/mlmodels/model_gluon/gluonts_model.py", line 203
    if d ==  "single_dataframe" :
                                ^
SyntaxError: invalid syntax

During handling of the above exception, another exception occurred:

Traceback (most recent call last):
  File "/home/runner/work/mlmodels/mlmodels/mlmodels/models.py", line 84, in module_load
    model_name = str(Path(model_uri).parts[-2]) + "." + str(model_name)
IndexError: tuple index out of range

During handling of the above exception, another exception occurred:

Traceback (most recent call last):
  File "/opt/hostedtoolcache/Python/3.6.12/x64/bin/ml_models", line 11, in <module>
    load_entry_point('mlmodels', 'console_scripts', 'ml_models')()
  File "/home/runner/work/mlmodels/mlmodels/mlmodels/models.py", line 530, in main
    fit_cli(arg)
  File "/home/runner/work/mlmodels/mlmodels/mlmodels/models.py", line 420, in fit_cli
    module = module_load(model_uri)  # '1_lstm.py
  File "/home/runner/work/mlmodels/mlmodels/mlmodels/models.py", line 89, in module_load
    raise NameError(f"Module {model_name} notfound, {e1}, {e2}")
NameError: Module model_gluon notfound, invalid syntax (gluonts_model.py, line 203), tuple index out of range





 ********************************************************************************************************************************************

  ml_models --do fit --config_file /home/runner/work/mlmodels/mlmodels/mlmodels/dataset/json/benchmark_timeseries/test02/model_list_gluon_only.json  --config_mode deepstate  
fit

  ##### Load JSON /home/runner/work/mlmodels/mlmodels/mlmodels/dataset/json/benchmark_timeseries/test02/model_list_gluon_only.json 

  ##### Init model_gluon.gluonts_model {'path': '/home/runner/work/mlmodels/mlmodels/mlmodels/ztest/model_gluon/gluonts_deepstate/', 'model_uri': 'model_gluon.gluonts_model'} 
Traceback (most recent call last):
  File "/home/runner/work/mlmodels/mlmodels/mlmodels/models.py", line 72, in module_load
    module = import_module(f"mlmodels.{model_name}")
  File "/opt/hostedtoolcache/Python/3.6.12/x64/lib/python3.6/importlib/__init__.py", line 126, in import_module
    return _bootstrap._gcd_import(name[level:], package, level)
  File "<frozen importlib._bootstrap>", line 994, in _gcd_import
  File "<frozen importlib._bootstrap>", line 971, in _find_and_load
  File "<frozen importlib._bootstrap>", line 955, in _find_and_load_unlocked
  File "<frozen importlib._bootstrap>", line 665, in _load_unlocked
  File "<frozen importlib._bootstrap_external>", line 674, in exec_module
  File "<frozen importlib._bootstrap_external>", line 781, in get_code
  File "<frozen importlib._bootstrap_external>", line 741, in source_to_code
  File "<frozen importlib._bootstrap>", line 219, in _call_with_frames_removed
  File "/home/runner/work/mlmodels/mlmodels/mlmodels/model_gluon/gluonts_model.py", line 203
    if d ==  "single_dataframe" :
                                ^
SyntaxError: invalid syntax

During handling of the above exception, another exception occurred:

Traceback (most recent call last):
  File "/home/runner/work/mlmodels/mlmodels/mlmodels/models.py", line 84, in module_load
    model_name = str(Path(model_uri).parts[-2]) + "." + str(model_name)
IndexError: tuple index out of range

During handling of the above exception, another exception occurred:

Traceback (most recent call last):
  File "/opt/hostedtoolcache/Python/3.6.12/x64/bin/ml_models", line 11, in <module>
    load_entry_point('mlmodels', 'console_scripts', 'ml_models')()
  File "/home/runner/work/mlmodels/mlmodels/mlmodels/models.py", line 530, in main
    fit_cli(arg)
  File "/home/runner/work/mlmodels/mlmodels/mlmodels/models.py", line 420, in fit_cli
    module = module_load(model_uri)  # '1_lstm.py
  File "/home/runner/work/mlmodels/mlmodels/mlmodels/models.py", line 89, in module_load
    raise NameError(f"Module {model_name} notfound, {e1}, {e2}")
NameError: Module model_gluon notfound, invalid syntax (gluonts_model.py, line 203), tuple index out of range





 ********************************************************************************************************************************************

  ml_models --do fit --config_file /home/runner/work/mlmodels/mlmodels/mlmodels/dataset/json/benchmark_timeseries/test02/model_list_gluon_only.json  --config_mode gp_forecaster  
fit

  ##### Load JSON /home/runner/work/mlmodels/mlmodels/mlmodels/dataset/json/benchmark_timeseries/test02/model_list_gluon_only.json 

  ##### Init model_gluon.gluonts_model {'path': '/home/runner/work/mlmodels/mlmodels/mlmodels/ztest/model_gluon/gluonts_gpforecaster/', 'model_uri': 'model_gluon.gluonts_model'} 
Traceback (most recent call last):
  File "/home/runner/work/mlmodels/mlmodels/mlmodels/models.py", line 72, in module_load
    module = import_module(f"mlmodels.{model_name}")
  File "/opt/hostedtoolcache/Python/3.6.12/x64/lib/python3.6/importlib/__init__.py", line 126, in import_module
    return _bootstrap._gcd_import(name[level:], package, level)
  File "<frozen importlib._bootstrap>", line 994, in _gcd_import
  File "<frozen importlib._bootstrap>", line 971, in _find_and_load
  File "<frozen importlib._bootstrap>", line 955, in _find_and_load_unlocked
  File "<frozen importlib._bootstrap>", line 665, in _load_unlocked
  File "<frozen importlib._bootstrap_external>", line 674, in exec_module
  File "<frozen importlib._bootstrap_external>", line 781, in get_code
  File "<frozen importlib._bootstrap_external>", line 741, in source_to_code
  File "<frozen importlib._bootstrap>", line 219, in _call_with_frames_removed
  File "/home/runner/work/mlmodels/mlmodels/mlmodels/model_gluon/gluonts_model.py", line 203
    if d ==  "single_dataframe" :
                                ^
SyntaxError: invalid syntax

During handling of the above exception, another exception occurred:

Traceback (most recent call last):
  File "/home/runner/work/mlmodels/mlmodels/mlmodels/models.py", line 84, in module_load
    model_name = str(Path(model_uri).parts[-2]) + "." + str(model_name)
IndexError: tuple index out of range

During handling of the above exception, another exception occurred:

Traceback (most recent call last):
  File "/opt/hostedtoolcache/Python/3.6.12/x64/bin/ml_models", line 11, in <module>
    load_entry_point('mlmodels', 'console_scripts', 'ml_models')()
  File "/home/runner/work/mlmodels/mlmodels/mlmodels/models.py", line 530, in main
    fit_cli(arg)
  File "/home/runner/work/mlmodels/mlmodels/mlmodels/models.py", line 420, in fit_cli
    module = module_load(model_uri)  # '1_lstm.py
  File "/home/runner/work/mlmodels/mlmodels/mlmodels/models.py", line 89, in module_load
    raise NameError(f"Module {model_name} notfound, {e1}, {e2}")
NameError: Module model_gluon notfound, invalid syntax (gluonts_model.py, line 203), tuple index out of range





 ********************************************************************************************************************************************

  ml_models --do fit --config_file /home/runner/work/mlmodels/mlmodels/mlmodels/dataset/json/benchmark_timeseries/test02/model_list_gluon_only.json  --config_mode feedforward  
fit

  ##### Load JSON /home/runner/work/mlmodels/mlmodels/mlmodels/dataset/json/benchmark_timeseries/test02/model_list_gluon_only.json 

  ##### Init model_gluon.gluonts_model {'path': '/home/runner/work/mlmodels/mlmodels/mlmodels/ztest/model_gluon/gluonts_feedforward/', 'model_uri': 'model_gluon.gluonts_model'} 
Traceback (most recent call last):
  File "/home/runner/work/mlmodels/mlmodels/mlmodels/models.py", line 72, in module_load
    module = import_module(f"mlmodels.{model_name}")
  File "/opt/hostedtoolcache/Python/3.6.12/x64/lib/python3.6/importlib/__init__.py", line 126, in import_module
    return _bootstrap._gcd_import(name[level:], package, level)
  File "<frozen importlib._bootstrap>", line 994, in _gcd_import
  File "<frozen importlib._bootstrap>", line 971, in _find_and_load
  File "<frozen importlib._bootstrap>", line 955, in _find_and_load_unlocked
  File "<frozen importlib._bootstrap>", line 665, in _load_unlocked
  File "<frozen importlib._bootstrap_external>", line 674, in exec_module
  File "<frozen importlib._bootstrap_external>", line 781, in get_code
  File "<frozen importlib._bootstrap_external>", line 741, in source_to_code
  File "<frozen importlib._bootstrap>", line 219, in _call_with_frames_removed
  File "/home/runner/work/mlmodels/mlmodels/mlmodels/model_gluon/gluonts_model.py", line 203
    if d ==  "single_dataframe" :
                                ^
SyntaxError: invalid syntax

During handling of the above exception, another exception occurred:

Traceback (most recent call last):
  File "/home/runner/work/mlmodels/mlmodels/mlmodels/models.py", line 84, in module_load
    model_name = str(Path(model_uri).parts[-2]) + "." + str(model_name)
IndexError: tuple index out of range

During handling of the above exception, another exception occurred:

Traceback (most recent call last):
  File "/opt/hostedtoolcache/Python/3.6.12/x64/bin/ml_models", line 11, in <module>
    load_entry_point('mlmodels', 'console_scripts', 'ml_models')()
  File "/home/runner/work/mlmodels/mlmodels/mlmodels/models.py", line 530, in main
    fit_cli(arg)
  File "/home/runner/work/mlmodels/mlmodels/mlmodels/models.py", line 420, in fit_cli
    module = module_load(model_uri)  # '1_lstm.py
  File "/home/runner/work/mlmodels/mlmodels/mlmodels/models.py", line 89, in module_load
    raise NameError(f"Module {model_name} notfound, {e1}, {e2}")
NameError: Module model_gluon notfound, invalid syntax (gluonts_model.py, line 203), tuple index out of range





 ********************************************************************************************************************************************

  ml_models --do fit --config_file /home/runner/work/mlmodels/mlmodels/mlmodels/dataset/json/benchmark_timeseries/test02/model_list_gluon_only.json  --config_mode seq2seq  
fit

  ##### Load JSON /home/runner/work/mlmodels/mlmodels/mlmodels/dataset/json/benchmark_timeseries/test02/model_list_gluon_only.json 

  ##### Init model_gluon.gluonts_model {'path': '/home/runner/work/mlmodels/mlmodels/mlmodels/ztest/model_gluon/gluonts_seq2seq/', 'model_uri': 'model_gluon.gluonts_model'} 
Traceback (most recent call last):
  File "/home/runner/work/mlmodels/mlmodels/mlmodels/models.py", line 72, in module_load
    module = import_module(f"mlmodels.{model_name}")
  File "/opt/hostedtoolcache/Python/3.6.12/x64/lib/python3.6/importlib/__init__.py", line 126, in import_module
    return _bootstrap._gcd_import(name[level:], package, level)
  File "<frozen importlib._bootstrap>", line 994, in _gcd_import
  File "<frozen importlib._bootstrap>", line 971, in _find_and_load
  File "<frozen importlib._bootstrap>", line 955, in _find_and_load_unlocked
  File "<frozen importlib._bootstrap>", line 665, in _load_unlocked
  File "<frozen importlib._bootstrap_external>", line 674, in exec_module
  File "<frozen importlib._bootstrap_external>", line 781, in get_code
  File "<frozen importlib._bootstrap_external>", line 741, in source_to_code
  File "<frozen importlib._bootstrap>", line 219, in _call_with_frames_removed
  File "/home/runner/work/mlmodels/mlmodels/mlmodels/model_gluon/gluonts_model.py", line 203
    if d ==  "single_dataframe" :
                                ^
SyntaxError: invalid syntax

During handling of the above exception, another exception occurred:

Traceback (most recent call last):
  File "/home/runner/work/mlmodels/mlmodels/mlmodels/models.py", line 84, in module_load
    model_name = str(Path(model_uri).parts[-2]) + "." + str(model_name)
IndexError: tuple index out of range

During handling of the above exception, another exception occurred:

Traceback (most recent call last):
  File "/opt/hostedtoolcache/Python/3.6.12/x64/bin/ml_models", line 11, in <module>
    load_entry_point('mlmodels', 'console_scripts', 'ml_models')()
  File "/home/runner/work/mlmodels/mlmodels/mlmodels/models.py", line 530, in main
    fit_cli(arg)
  File "/home/runner/work/mlmodels/mlmodels/mlmodels/models.py", line 420, in fit_cli
    module = module_load(model_uri)  # '1_lstm.py
  File "/home/runner/work/mlmodels/mlmodels/mlmodels/models.py", line 89, in module_load
    raise NameError(f"Module {model_name} notfound, {e1}, {e2}")
NameError: Module model_gluon notfound, invalid syntax (gluonts_model.py, line 203), tuple index out of range

  


 ************ JSON File /home/runner/work/mlmodels/mlmodels/mlmodels/dataset/json/refactor/notused/hyper_lightgbm_titanic.json 





 ********************************************************************************************************************************************

  ml_models --do fit --config_file /home/runner/work/mlmodels/mlmodels/mlmodels/dataset/json/refactor/notused/hyper_lightgbm_titanic.json  --config_mode test  
fit

  ##### Load JSON /home/runner/work/mlmodels/mlmodels/mlmodels/dataset/json/refactor/notused/hyper_lightgbm_titanic.json 
Traceback (most recent call last):
  File "/opt/hostedtoolcache/Python/3.6.12/x64/bin/ml_models", line 11, in <module>
    load_entry_point('mlmodels', 'console_scripts', 'ml_models')()
  File "/home/runner/work/mlmodels/mlmodels/mlmodels/models.py", line 530, in main
    fit_cli(arg)
  File "/home/runner/work/mlmodels/mlmodels/mlmodels/models.py", line 414, in fit_cli
    model_uri = model_p['model_uri']
KeyError: 'model_uri'

  


 ************ JSON File /home/runner/work/mlmodels/mlmodels/mlmodels/dataset/json/refactor/notused/03_nbeats_dataloader.json 





 ********************************************************************************************************************************************

  ml_models --do fit --config_file /home/runner/work/mlmodels/mlmodels/mlmodels/dataset/json/refactor/notused/03_nbeats_dataloader.json  --config_mode test  
fit

  ##### Load JSON /home/runner/work/mlmodels/mlmodels/mlmodels/dataset/json/refactor/notused/03_nbeats_dataloader.json 
Traceback (most recent call last):
  File "/opt/hostedtoolcache/Python/3.6.12/x64/bin/ml_models", line 11, in <module>
    load_entry_point('mlmodels', 'console_scripts', 'ml_models')()
  File "/home/runner/work/mlmodels/mlmodels/mlmodels/models.py", line 530, in main
    fit_cli(arg)
  File "/home/runner/work/mlmodels/mlmodels/mlmodels/models.py", line 414, in fit_cli
    model_uri = model_p['model_uri']
KeyError: 'model_uri'

  


 ************ JSON File /home/runner/work/mlmodels/mlmodels/mlmodels/dataset/json/refactor/notused/namentity_crm_bilstm_dataloader.json 





 ********************************************************************************************************************************************

  ml_models --do fit --config_file /home/runner/work/mlmodels/mlmodels/mlmodels/dataset/json/refactor/notused/namentity_crm_bilstm_dataloader.json  --config_mode test  
fit

  ##### Load JSON /home/runner/work/mlmodels/mlmodels/mlmodels/dataset/json/refactor/notused/namentity_crm_bilstm_dataloader.json 
Traceback (most recent call last):
  File "/opt/hostedtoolcache/Python/3.6.12/x64/bin/ml_models", line 11, in <module>
    load_entry_point('mlmodels', 'console_scripts', 'ml_models')()
  File "/home/runner/work/mlmodels/mlmodels/mlmodels/models.py", line 530, in main
    fit_cli(arg)
  File "/home/runner/work/mlmodels/mlmodels/mlmodels/models.py", line 414, in fit_cli
    model_uri = model_p['model_uri']
KeyError: 'model_uri'

  


 ************ JSON File /home/runner/work/mlmodels/mlmodels/mlmodels/dataset/json/refactor/notused/lightgbm_titanic.json 





 ********************************************************************************************************************************************

  ml_models --do fit --config_file /home/runner/work/mlmodels/mlmodels/mlmodels/dataset/json/refactor/notused/lightgbm_titanic.json  --config_mode test  
fit

  ##### Load JSON /home/runner/work/mlmodels/mlmodels/mlmodels/dataset/json/refactor/notused/lightgbm_titanic.json 
Traceback (most recent call last):
  File "/opt/hostedtoolcache/Python/3.6.12/x64/bin/ml_models", line 11, in <module>
    load_entry_point('mlmodels', 'console_scripts', 'ml_models')()
  File "/home/runner/work/mlmodels/mlmodels/mlmodels/models.py", line 530, in main
    fit_cli(arg)
  File "/home/runner/work/mlmodels/mlmodels/mlmodels/models.py", line 414, in fit_cli
    model_uri = model_p['model_uri']
KeyError: 'model_uri'

  


 ************ JSON File /home/runner/work/mlmodels/mlmodels/mlmodels/dataset/json/refactor/notused/sklearn_titanic_svm.json 





 ********************************************************************************************************************************************

  ml_models --do fit --config_file /home/runner/work/mlmodels/mlmodels/mlmodels/dataset/json/refactor/notused/sklearn_titanic_svm.json  --config_mode test  
fit

  ##### Load JSON /home/runner/work/mlmodels/mlmodels/mlmodels/dataset/json/refactor/notused/sklearn_titanic_svm.json 
Traceback (most recent call last):
  File "/opt/hostedtoolcache/Python/3.6.12/x64/bin/ml_models", line 11, in <module>
    load_entry_point('mlmodels', 'console_scripts', 'ml_models')()
  File "/home/runner/work/mlmodels/mlmodels/mlmodels/models.py", line 530, in main
    fit_cli(arg)
  File "/home/runner/work/mlmodels/mlmodels/mlmodels/models.py", line 414, in fit_cli
    model_uri = model_p['model_uri']
KeyError: 'model_uri'





 ********************************************************************************************************************************************

  ml_models --do fit --config_file /home/runner/work/mlmodels/mlmodels/mlmodels/dataset/json/refactor/notused/sklearn_titanic_svm.json  --config_mode prod  
fit

  ##### Load JSON /home/runner/work/mlmodels/mlmodels/mlmodels/dataset/json/refactor/notused/sklearn_titanic_svm.json 
Traceback (most recent call last):
  File "/opt/hostedtoolcache/Python/3.6.12/x64/bin/ml_models", line 11, in <module>
    load_entry_point('mlmodels', 'console_scripts', 'ml_models')()
  File "/home/runner/work/mlmodels/mlmodels/mlmodels/models.py", line 530, in main
    fit_cli(arg)
  File "/home/runner/work/mlmodels/mlmodels/mlmodels/models.py", line 413, in fit_cli
    model_p, data_p, compute_p, out_p = config_get_pars(config_file, arg.config_mode)
  File "/home/runner/work/mlmodels/mlmodels/mlmodels/models.py", line 299, in config_get_pars
    out_p     = path_norm_dict( js.get("out_pars") )
  File "/home/runner/work/mlmodels/mlmodels/mlmodels/util.py", line 201, in path_norm_dict
    for k,v in ddict.items():
AttributeError: 'NoneType' object has no attribute 'items'

  


 ************ JSON File /home/runner/work/mlmodels/mlmodels/mlmodels/dataset/json/refactor/notused/hyper_lightgbm_glass.json 





 ********************************************************************************************************************************************

  ml_models --do fit --config_file /home/runner/work/mlmodels/mlmodels/mlmodels/dataset/json/refactor/notused/hyper_lightgbm_glass.json  --config_mode test  
fit

  ##### Load JSON /home/runner/work/mlmodels/mlmodels/mlmodels/dataset/json/refactor/notused/hyper_lightgbm_glass.json 
Traceback (most recent call last):
  File "/opt/hostedtoolcache/Python/3.6.12/x64/bin/ml_models", line 11, in <module>
    load_entry_point('mlmodels', 'console_scripts', 'ml_models')()
  File "/home/runner/work/mlmodels/mlmodels/mlmodels/models.py", line 530, in main
    fit_cli(arg)
  File "/home/runner/work/mlmodels/mlmodels/mlmodels/models.py", line 414, in fit_cli
    model_uri = model_p['model_uri']
KeyError: 'model_uri'

  


 ************ JSON File /home/runner/work/mlmodels/mlmodels/mlmodels/dataset/json/refactor/notused/hyper_titanic_randomForest.json 





 ********************************************************************************************************************************************

  ml_models --do fit --config_file /home/runner/work/mlmodels/mlmodels/mlmodels/dataset/json/refactor/notused/hyper_titanic_randomForest.json  --config_mode test  
fit

  ##### Load JSON /home/runner/work/mlmodels/mlmodels/mlmodels/dataset/json/refactor/notused/hyper_titanic_randomForest.json 
Traceback (most recent call last):
  File "/opt/hostedtoolcache/Python/3.6.12/x64/bin/ml_models", line 11, in <module>
    load_entry_point('mlmodels', 'console_scripts', 'ml_models')()
  File "/home/runner/work/mlmodels/mlmodels/mlmodels/models.py", line 530, in main
    fit_cli(arg)
  File "/home/runner/work/mlmodels/mlmodels/mlmodels/models.py", line 414, in fit_cli
    model_uri = model_p['model_uri']
KeyError: 'model_uri'





 ********************************************************************************************************************************************

  ml_models --do fit --config_file /home/runner/work/mlmodels/mlmodels/mlmodels/dataset/json/refactor/notused/hyper_titanic_randomForest.json  --config_mode prod  
fit

  ##### Load JSON /home/runner/work/mlmodels/mlmodels/mlmodels/dataset/json/refactor/notused/hyper_titanic_randomForest.json 
Traceback (most recent call last):
  File "/opt/hostedtoolcache/Python/3.6.12/x64/bin/ml_models", line 11, in <module>
    load_entry_point('mlmodels', 'console_scripts', 'ml_models')()
  File "/home/runner/work/mlmodels/mlmodels/mlmodels/models.py", line 530, in main
    fit_cli(arg)
  File "/home/runner/work/mlmodels/mlmodels/mlmodels/models.py", line 413, in fit_cli
    model_p, data_p, compute_p, out_p = config_get_pars(config_file, arg.config_mode)
  File "/home/runner/work/mlmodels/mlmodels/mlmodels/models.py", line 299, in config_get_pars
    out_p     = path_norm_dict( js.get("out_pars") )
  File "/home/runner/work/mlmodels/mlmodels/mlmodels/util.py", line 201, in path_norm_dict
    for k,v in ddict.items():
AttributeError: 'NoneType' object has no attribute 'items'

  


 ************ JSON File /home/runner/work/mlmodels/mlmodels/mlmodels/dataset/json/refactor/notused/fbprophet.json 





 ********************************************************************************************************************************************

  ml_models --do fit --config_file /home/runner/work/mlmodels/mlmodels/mlmodels/dataset/json/refactor/notused/fbprophet.json  --config_mode test  
fit

  ##### Load JSON /home/runner/work/mlmodels/mlmodels/mlmodels/dataset/json/refactor/notused/fbprophet.json 
Traceback (most recent call last):
  File "/opt/hostedtoolcache/Python/3.6.12/x64/bin/ml_models", line 11, in <module>
    load_entry_point('mlmodels', 'console_scripts', 'ml_models')()
  File "/home/runner/work/mlmodels/mlmodels/mlmodels/models.py", line 530, in main
    fit_cli(arg)
  File "/home/runner/work/mlmodels/mlmodels/mlmodels/models.py", line 415, in fit_cli
    path      = out_p['path']
KeyError: 'path'

  


 ************ JSON File /home/runner/work/mlmodels/mlmodels/mlmodels/dataset/json/refactor/notused/gluon_automl.json 





 ********************************************************************************************************************************************

  ml_models --do fit --config_file /home/runner/work/mlmodels/mlmodels/mlmodels/dataset/json/refactor/notused/gluon_automl.json  --config_mode test  
fit

  ##### Load JSON /home/runner/work/mlmodels/mlmodels/mlmodels/dataset/json/refactor/notused/gluon_automl.json 
Traceback (most recent call last):
  File "/opt/hostedtoolcache/Python/3.6.12/x64/bin/ml_models", line 11, in <module>
    load_entry_point('mlmodels', 'console_scripts', 'ml_models')()
  File "/home/runner/work/mlmodels/mlmodels/mlmodels/models.py", line 530, in main
    fit_cli(arg)
  File "/home/runner/work/mlmodels/mlmodels/mlmodels/models.py", line 414, in fit_cli
    model_uri = model_p['model_uri']
KeyError: 'model_uri'





 ********************************************************************************************************************************************

  ml_models --do fit --config_file /home/runner/work/mlmodels/mlmodels/mlmodels/dataset/json/refactor/notused/gluon_automl.json  --config_mode prod  
fit

  ##### Load JSON /home/runner/work/mlmodels/mlmodels/mlmodels/dataset/json/refactor/notused/gluon_automl.json 
Traceback (most recent call last):
  File "/opt/hostedtoolcache/Python/3.6.12/x64/bin/ml_models", line 11, in <module>
    load_entry_point('mlmodels', 'console_scripts', 'ml_models')()
  File "/home/runner/work/mlmodels/mlmodels/mlmodels/models.py", line 530, in main
    fit_cli(arg)
  File "/home/runner/work/mlmodels/mlmodels/mlmodels/models.py", line 413, in fit_cli
    model_p, data_p, compute_p, out_p = config_get_pars(config_file, arg.config_mode)
  File "/home/runner/work/mlmodels/mlmodels/mlmodels/models.py", line 297, in config_get_pars
    data_p    = path_norm_dict( js.get("data_pars") )
  File "/home/runner/work/mlmodels/mlmodels/mlmodels/util.py", line 201, in path_norm_dict
    for k,v in ddict.items():
AttributeError: 'NoneType' object has no attribute 'items'

  


 ************ JSON File /home/runner/work/mlmodels/mlmodels/mlmodels/dataset/json/refactor/notused/sklearn_titanic_randomForest.json 





 ********************************************************************************************************************************************

  ml_models --do fit --config_file /home/runner/work/mlmodels/mlmodels/mlmodels/dataset/json/refactor/notused/sklearn_titanic_randomForest.json  --config_mode test  
fit

  ##### Load JSON /home/runner/work/mlmodels/mlmodels/mlmodels/dataset/json/refactor/notused/sklearn_titanic_randomForest.json 
Traceback (most recent call last):
  File "/opt/hostedtoolcache/Python/3.6.12/x64/bin/ml_models", line 11, in <module>
    load_entry_point('mlmodels', 'console_scripts', 'ml_models')()
  File "/home/runner/work/mlmodels/mlmodels/mlmodels/models.py", line 530, in main
    fit_cli(arg)
  File "/home/runner/work/mlmodels/mlmodels/mlmodels/models.py", line 414, in fit_cli
    model_uri = model_p['model_uri']
KeyError: 'model_uri'





 ********************************************************************************************************************************************

  ml_models --do fit --config_file /home/runner/work/mlmodels/mlmodels/mlmodels/dataset/json/refactor/notused/sklearn_titanic_randomForest.json  --config_mode prod  
fit

  ##### Load JSON /home/runner/work/mlmodels/mlmodels/mlmodels/dataset/json/refactor/notused/sklearn_titanic_randomForest.json 
Traceback (most recent call last):
  File "/opt/hostedtoolcache/Python/3.6.12/x64/bin/ml_models", line 11, in <module>
    load_entry_point('mlmodels', 'console_scripts', 'ml_models')()
  File "/home/runner/work/mlmodels/mlmodels/mlmodels/models.py", line 530, in main
    fit_cli(arg)
  File "/home/runner/work/mlmodels/mlmodels/mlmodels/models.py", line 413, in fit_cli
    model_p, data_p, compute_p, out_p = config_get_pars(config_file, arg.config_mode)
  File "/home/runner/work/mlmodels/mlmodels/mlmodels/models.py", line 299, in config_get_pars
    out_p     = path_norm_dict( js.get("out_pars") )
  File "/home/runner/work/mlmodels/mlmodels/mlmodels/util.py", line 201, in path_norm_dict
    for k,v in ddict.items():
AttributeError: 'NoneType' object has no attribute 'items'

  


 ************ JSON File /home/runner/work/mlmodels/mlmodels/mlmodels/dataset/json/refactor/notused/1_lstm_dataloader.json 





 ********************************************************************************************************************************************

  ml_models --do fit --config_file /home/runner/work/mlmodels/mlmodels/mlmodels/dataset/json/refactor/notused/1_lstm_dataloader.json  --config_mode test  
fit

  ##### Load JSON /home/runner/work/mlmodels/mlmodels/mlmodels/dataset/json/refactor/notused/1_lstm_dataloader.json 
Traceback (most recent call last):
  File "/opt/hostedtoolcache/Python/3.6.12/x64/bin/ml_models", line 11, in <module>
    load_entry_point('mlmodels', 'console_scripts', 'ml_models')()
  File "/home/runner/work/mlmodels/mlmodels/mlmodels/models.py", line 530, in main
    fit_cli(arg)
  File "/home/runner/work/mlmodels/mlmodels/mlmodels/models.py", line 414, in fit_cli
    model_uri = model_p['model_uri']
KeyError: 'model_uri'





 ********************************************************************************************************************************************

  ml_models --do fit --config_file /home/runner/work/mlmodels/mlmodels/mlmodels/dataset/json/refactor/notused/1_lstm_dataloader.json  --config_mode prod  
fit

  ##### Load JSON /home/runner/work/mlmodels/mlmodels/mlmodels/dataset/json/refactor/notused/1_lstm_dataloader.json 
Traceback (most recent call last):
  File "/opt/hostedtoolcache/Python/3.6.12/x64/bin/ml_models", line 11, in <module>
    load_entry_point('mlmodels', 'console_scripts', 'ml_models')()
  File "/home/runner/work/mlmodels/mlmodels/mlmodels/models.py", line 530, in main
    fit_cli(arg)
  File "/home/runner/work/mlmodels/mlmodels/mlmodels/models.py", line 413, in fit_cli
    model_p, data_p, compute_p, out_p = config_get_pars(config_file, arg.config_mode)
  File "/home/runner/work/mlmodels/mlmodels/mlmodels/models.py", line 299, in config_get_pars
    out_p     = path_norm_dict( js.get("out_pars") )
  File "/home/runner/work/mlmodels/mlmodels/mlmodels/util.py", line 201, in path_norm_dict
    for k,v in ddict.items():
AttributeError: 'NoneType' object has no attribute 'items'

  


 ************ JSON File /home/runner/work/mlmodels/mlmodels/mlmodels/dataset/json/benchmark_cnn/zold/resnet18_fashion_mnist.json 





 ********************************************************************************************************************************************

  ml_models --do fit --config_file /home/runner/work/mlmodels/mlmodels/mlmodels/dataset/json/benchmark_cnn/zold/resnet18_fashion_mnist.json  --config_mode test  
fit

  ##### Load JSON /home/runner/work/mlmodels/mlmodels/mlmodels/dataset/json/benchmark_cnn/zold/resnet18_fashion_mnist.json 

  ##### Init model_tch.torchhub.py {'path': '/home/runner/work/mlmodels/mlmodels/mlmodels/ztest/model_tch/torchhub/restnet18/', 'model_uri': 'model_tch.torchhub.py'} 
Traceback (most recent call last):
  File "/opt/hostedtoolcache/Python/3.6.12/x64/bin/ml_models", line 11, in <module>
    load_entry_point('mlmodels', 'console_scripts', 'ml_models')()
  File "/home/runner/work/mlmodels/mlmodels/mlmodels/models.py", line 530, in main
    fit_cli(arg)
  File "/home/runner/work/mlmodels/mlmodels/mlmodels/models.py", line 421, in fit_cli
    model = model_create(module, model_p, data_p, compute_p)  # Exact map JSON and paramters
  File "/home/runner/work/mlmodels/mlmodels/mlmodels/models.py", line 113, in model_create
    module.init(model_pars=model_pars, data_pars=data_pars, compute_pars=compute_pars, **kwarg)
AttributeError: module 'mlmodels.model_tch.torchhub' has no attribute 'init'





 ********************************************************************************************************************************************

  ml_models --do fit --config_file /home/runner/work/mlmodels/mlmodels/mlmodels/dataset/json/benchmark_cnn/zold/resnet18_fashion_mnist.json  --config_mode prod  
fit

  ##### Load JSON /home/runner/work/mlmodels/mlmodels/mlmodels/dataset/json/benchmark_cnn/zold/resnet18_fashion_mnist.json 
Traceback (most recent call last):
  File "/opt/hostedtoolcache/Python/3.6.12/x64/bin/ml_models", line 11, in <module>
    load_entry_point('mlmodels', 'console_scripts', 'ml_models')()
  File "/home/runner/work/mlmodels/mlmodels/mlmodels/models.py", line 530, in main
    fit_cli(arg)
  File "/home/runner/work/mlmodels/mlmodels/mlmodels/models.py", line 413, in fit_cli
    model_p, data_p, compute_p, out_p = config_get_pars(config_file, arg.config_mode)
  File "/home/runner/work/mlmodels/mlmodels/mlmodels/models.py", line 299, in config_get_pars
    out_p     = path_norm_dict( js.get("out_pars") )
  File "/home/runner/work/mlmodels/mlmodels/mlmodels/util.py", line 201, in path_norm_dict
    for k,v in ddict.items():
AttributeError: 'NoneType' object has no attribute 'items'

  


 ************ JSON File /home/runner/work/mlmodels/mlmodels/mlmodels/dataset/json/benchmark_cnn/zold/resnet50_benchmark_mnist.json 





 ********************************************************************************************************************************************

  ml_models --do fit --config_file /home/runner/work/mlmodels/mlmodels/mlmodels/dataset/json/benchmark_cnn/zold/resnet50_benchmark_mnist.json  --config_mode test  
fit

  ##### Load JSON /home/runner/work/mlmodels/mlmodels/mlmodels/dataset/json/benchmark_cnn/zold/resnet50_benchmark_mnist.json 

  ##### Init model_tch.torchhub.py {'path': '/home/runner/work/mlmodels/mlmodels/mlmodels/ztest/model_tch/torchhub/restnet18/', 'model_uri': 'model_tch.torchhub.py'} 
Traceback (most recent call last):
  File "/opt/hostedtoolcache/Python/3.6.12/x64/bin/ml_models", line 11, in <module>
    load_entry_point('mlmodels', 'console_scripts', 'ml_models')()
  File "/home/runner/work/mlmodels/mlmodels/mlmodels/models.py", line 530, in main
    fit_cli(arg)
  File "/home/runner/work/mlmodels/mlmodels/mlmodels/models.py", line 421, in fit_cli
    model = model_create(module, model_p, data_p, compute_p)  # Exact map JSON and paramters
  File "/home/runner/work/mlmodels/mlmodels/mlmodels/models.py", line 113, in model_create
    module.init(model_pars=model_pars, data_pars=data_pars, compute_pars=compute_pars, **kwarg)
AttributeError: module 'mlmodels.model_tch.torchhub' has no attribute 'init'





 ********************************************************************************************************************************************

  ml_models --do fit --config_file /home/runner/work/mlmodels/mlmodels/mlmodels/dataset/json/benchmark_cnn/zold/resnet50_benchmark_mnist.json  --config_mode prod  
fit

  ##### Load JSON /home/runner/work/mlmodels/mlmodels/mlmodels/dataset/json/benchmark_cnn/zold/resnet50_benchmark_mnist.json 
Traceback (most recent call last):
  File "/opt/hostedtoolcache/Python/3.6.12/x64/bin/ml_models", line 11, in <module>
    load_entry_point('mlmodels', 'console_scripts', 'ml_models')()
  File "/home/runner/work/mlmodels/mlmodels/mlmodels/models.py", line 530, in main
    fit_cli(arg)
  File "/home/runner/work/mlmodels/mlmodels/mlmodels/models.py", line 413, in fit_cli
    model_p, data_p, compute_p, out_p = config_get_pars(config_file, arg.config_mode)
  File "/home/runner/work/mlmodels/mlmodels/mlmodels/models.py", line 299, in config_get_pars
    out_p     = path_norm_dict( js.get("out_pars") )
  File "/home/runner/work/mlmodels/mlmodels/mlmodels/util.py", line 201, in path_norm_dict
    for k,v in ddict.items():
AttributeError: 'NoneType' object has no attribute 'items'

  


 ************ JSON File /home/runner/work/mlmodels/mlmodels/mlmodels/dataset/json/benchmark_cnn/zold/resnet34_benchmark_mnist.json 





 ********************************************************************************************************************************************

  ml_models --do fit --config_file /home/runner/work/mlmodels/mlmodels/mlmodels/dataset/json/benchmark_cnn/zold/resnet34_benchmark_mnist.json  --config_mode test  
fit

  ##### Load JSON /home/runner/work/mlmodels/mlmodels/mlmodels/dataset/json/benchmark_cnn/zold/resnet34_benchmark_mnist.json 

  ##### Init model_tch.torchhub.py {'path': '/home/runner/work/mlmodels/mlmodels/mlmodels/ztest/model_tch/torchhub/restnet34/', 'model_uri': 'model_tch.torchhub.py'} 
Traceback (most recent call last):
  File "/opt/hostedtoolcache/Python/3.6.12/x64/bin/ml_models", line 11, in <module>
    load_entry_point('mlmodels', 'console_scripts', 'ml_models')()
  File "/home/runner/work/mlmodels/mlmodels/mlmodels/models.py", line 530, in main
    fit_cli(arg)
  File "/home/runner/work/mlmodels/mlmodels/mlmodels/models.py", line 421, in fit_cli
    model = model_create(module, model_p, data_p, compute_p)  # Exact map JSON and paramters
  File "/home/runner/work/mlmodels/mlmodels/mlmodels/models.py", line 113, in model_create
    module.init(model_pars=model_pars, data_pars=data_pars, compute_pars=compute_pars, **kwarg)
AttributeError: module 'mlmodels.model_tch.torchhub' has no attribute 'init'





 ********************************************************************************************************************************************

  ml_models --do fit --config_file /home/runner/work/mlmodels/mlmodels/mlmodels/dataset/json/benchmark_cnn/zold/resnet34_benchmark_mnist.json  --config_mode prod  
fit

  ##### Load JSON /home/runner/work/mlmodels/mlmodels/mlmodels/dataset/json/benchmark_cnn/zold/resnet34_benchmark_mnist.json 
Traceback (most recent call last):
  File "/opt/hostedtoolcache/Python/3.6.12/x64/bin/ml_models", line 11, in <module>
    load_entry_point('mlmodels', 'console_scripts', 'ml_models')()
  File "/home/runner/work/mlmodels/mlmodels/mlmodels/models.py", line 530, in main
    fit_cli(arg)
  File "/home/runner/work/mlmodels/mlmodels/mlmodels/models.py", line 413, in fit_cli
    model_p, data_p, compute_p, out_p = config_get_pars(config_file, arg.config_mode)
  File "/home/runner/work/mlmodels/mlmodels/mlmodels/models.py", line 299, in config_get_pars
    out_p     = path_norm_dict( js.get("out_pars") )
  File "/home/runner/work/mlmodels/mlmodels/mlmodels/util.py", line 201, in path_norm_dict
    for k,v in ddict.items():
AttributeError: 'NoneType' object has no attribute 'items'

  


 ************ JSON File /home/runner/work/mlmodels/mlmodels/mlmodels/dataset/json/benchmark_cnn/zold/resnet18_benchmark_mnist.json 





 ********************************************************************************************************************************************

  ml_models --do fit --config_file /home/runner/work/mlmodels/mlmodels/mlmodels/dataset/json/benchmark_cnn/zold/resnet18_benchmark_mnist.json  --config_mode test  
fit

  ##### Load JSON /home/runner/work/mlmodels/mlmodels/mlmodels/dataset/json/benchmark_cnn/zold/resnet18_benchmark_mnist.json 

  ##### Init model_tch.torchhub.py {'path': '/home/runner/work/mlmodels/mlmodels/mlmodels/ztest/model_tch/torchhub/restnet18/', 'model_uri': 'model_tch.torchhub.py'} 
Traceback (most recent call last):
  File "/opt/hostedtoolcache/Python/3.6.12/x64/bin/ml_models", line 11, in <module>
    load_entry_point('mlmodels', 'console_scripts', 'ml_models')()
  File "/home/runner/work/mlmodels/mlmodels/mlmodels/models.py", line 530, in main
    fit_cli(arg)
  File "/home/runner/work/mlmodels/mlmodels/mlmodels/models.py", line 421, in fit_cli
    model = model_create(module, model_p, data_p, compute_p)  # Exact map JSON and paramters
  File "/home/runner/work/mlmodels/mlmodels/mlmodels/models.py", line 113, in model_create
    module.init(model_pars=model_pars, data_pars=data_pars, compute_pars=compute_pars, **kwarg)
AttributeError: module 'mlmodels.model_tch.torchhub' has no attribute 'init'





 ********************************************************************************************************************************************

  ml_models --do fit --config_file /home/runner/work/mlmodels/mlmodels/mlmodels/dataset/json/benchmark_cnn/zold/resnet18_benchmark_mnist.json  --config_mode prod  
fit

  ##### Load JSON /home/runner/work/mlmodels/mlmodels/mlmodels/dataset/json/benchmark_cnn/zold/resnet18_benchmark_mnist.json 
Traceback (most recent call last):
  File "/opt/hostedtoolcache/Python/3.6.12/x64/bin/ml_models", line 11, in <module>
    load_entry_point('mlmodels', 'console_scripts', 'ml_models')()
  File "/home/runner/work/mlmodels/mlmodels/mlmodels/models.py", line 530, in main
    fit_cli(arg)
  File "/home/runner/work/mlmodels/mlmodels/mlmodels/models.py", line 413, in fit_cli
    model_p, data_p, compute_p, out_p = config_get_pars(config_file, arg.config_mode)
  File "/home/runner/work/mlmodels/mlmodels/mlmodels/models.py", line 299, in config_get_pars
    out_p     = path_norm_dict( js.get("out_pars") )
  File "/home/runner/work/mlmodels/mlmodels/mlmodels/util.py", line 201, in path_norm_dict
    for k,v in ddict.items():
AttributeError: 'NoneType' object has no attribute 'items'

  


 ************ JSON File /home/runner/work/mlmodels/mlmodels/mlmodels/dataset/json/benchmark_cnn/mnist/resnet152_benchmark_MNIST.json 





 ********************************************************************************************************************************************

  ml_models --do fit --config_file /home/runner/work/mlmodels/mlmodels/mlmodels/dataset/json/benchmark_cnn/mnist/resnet152_benchmark_MNIST.json  --config_mode test  
fit

  ##### Load JSON /home/runner/work/mlmodels/mlmodels/mlmodels/dataset/json/benchmark_cnn/mnist/resnet152_benchmark_MNIST.json 

  ##### Init model_tch.torchhub.py {'path': '/home/runner/work/mlmodels/mlmodels/mlmodels/ztest/model_tch/torchhub/resnet152/', 'model_uri': 'model_tch.torchhub.py'} 
Traceback (most recent call last):
  File "/opt/hostedtoolcache/Python/3.6.12/x64/bin/ml_models", line 11, in <module>
    load_entry_point('mlmodels', 'console_scripts', 'ml_models')()
  File "/home/runner/work/mlmodels/mlmodels/mlmodels/models.py", line 530, in main
    fit_cli(arg)
  File "/home/runner/work/mlmodels/mlmodels/mlmodels/models.py", line 421, in fit_cli
    model = model_create(module, model_p, data_p, compute_p)  # Exact map JSON and paramters
  File "/home/runner/work/mlmodels/mlmodels/mlmodels/models.py", line 113, in model_create
    module.init(model_pars=model_pars, data_pars=data_pars, compute_pars=compute_pars, **kwarg)
AttributeError: module 'mlmodels.model_tch.torchhub' has no attribute 'init'





 ********************************************************************************************************************************************

  ml_models --do fit --config_file /home/runner/work/mlmodels/mlmodels/mlmodels/dataset/json/benchmark_cnn/mnist/resnet152_benchmark_MNIST.json  --config_mode prod  
fit

  ##### Load JSON /home/runner/work/mlmodels/mlmodels/mlmodels/dataset/json/benchmark_cnn/mnist/resnet152_benchmark_MNIST.json 
Traceback (most recent call last):
  File "/opt/hostedtoolcache/Python/3.6.12/x64/bin/ml_models", line 11, in <module>
    load_entry_point('mlmodels', 'console_scripts', 'ml_models')()
  File "/home/runner/work/mlmodels/mlmodels/mlmodels/models.py", line 530, in main
    fit_cli(arg)
  File "/home/runner/work/mlmodels/mlmodels/mlmodels/models.py", line 413, in fit_cli
    model_p, data_p, compute_p, out_p = config_get_pars(config_file, arg.config_mode)
  File "/home/runner/work/mlmodels/mlmodels/mlmodels/models.py", line 299, in config_get_pars
    out_p     = path_norm_dict( js.get("out_pars") )
  File "/home/runner/work/mlmodels/mlmodels/mlmodels/util.py", line 201, in path_norm_dict
    for k,v in ddict.items():
AttributeError: 'NoneType' object has no attribute 'items'

  


 ************ JSON File /home/runner/work/mlmodels/mlmodels/mlmodels/dataset/json/benchmark_cnn/mnist/shufflenet_v2_x1_0_benchmark_MNIST.json 





 ********************************************************************************************************************************************

  ml_models --do fit --config_file /home/runner/work/mlmodels/mlmodels/mlmodels/dataset/json/benchmark_cnn/mnist/shufflenet_v2_x1_0_benchmark_MNIST.json  --config_mode test  
fit

  ##### Load JSON /home/runner/work/mlmodels/mlmodels/mlmodels/dataset/json/benchmark_cnn/mnist/shufflenet_v2_x1_0_benchmark_MNIST.json 

  ##### Init model_tch.torchhub.py {'path': '/home/runner/work/mlmodels/mlmodels/mlmodels/ztest/model_tch/torchhub/shufflenet_v2_x1_0/', 'model_uri': 'model_tch.torchhub.py'} 
Traceback (most recent call last):
  File "/opt/hostedtoolcache/Python/3.6.12/x64/bin/ml_models", line 11, in <module>
    load_entry_point('mlmodels', 'console_scripts', 'ml_models')()
  File "/home/runner/work/mlmodels/mlmodels/mlmodels/models.py", line 530, in main
    fit_cli(arg)
  File "/home/runner/work/mlmodels/mlmodels/mlmodels/models.py", line 421, in fit_cli
    model = model_create(module, model_p, data_p, compute_p)  # Exact map JSON and paramters
  File "/home/runner/work/mlmodels/mlmodels/mlmodels/models.py", line 113, in model_create
    module.init(model_pars=model_pars, data_pars=data_pars, compute_pars=compute_pars, **kwarg)
AttributeError: module 'mlmodels.model_tch.torchhub' has no attribute 'init'





 ********************************************************************************************************************************************

  ml_models --do fit --config_file /home/runner/work/mlmodels/mlmodels/mlmodels/dataset/json/benchmark_cnn/mnist/shufflenet_v2_x1_0_benchmark_MNIST.json  --config_mode prod  
fit

  ##### Load JSON /home/runner/work/mlmodels/mlmodels/mlmodels/dataset/json/benchmark_cnn/mnist/shufflenet_v2_x1_0_benchmark_MNIST.json 
Traceback (most recent call last):
  File "/opt/hostedtoolcache/Python/3.6.12/x64/bin/ml_models", line 11, in <module>
    load_entry_point('mlmodels', 'console_scripts', 'ml_models')()
  File "/home/runner/work/mlmodels/mlmodels/mlmodels/models.py", line 530, in main
    fit_cli(arg)
  File "/home/runner/work/mlmodels/mlmodels/mlmodels/models.py", line 413, in fit_cli
    model_p, data_p, compute_p, out_p = config_get_pars(config_file, arg.config_mode)
  File "/home/runner/work/mlmodels/mlmodels/mlmodels/models.py", line 299, in config_get_pars
    out_p     = path_norm_dict( js.get("out_pars") )
  File "/home/runner/work/mlmodels/mlmodels/mlmodels/util.py", line 201, in path_norm_dict
    for k,v in ddict.items():
AttributeError: 'NoneType' object has no attribute 'items'

  


 ************ JSON File /home/runner/work/mlmodels/mlmodels/mlmodels/dataset/json/benchmark_cnn/mnist/resnext50_32x4d_benchmark_MNIST.json 





 ********************************************************************************************************************************************

  ml_models --do fit --config_file /home/runner/work/mlmodels/mlmodels/mlmodels/dataset/json/benchmark_cnn/mnist/resnext50_32x4d_benchmark_MNIST.json  --config_mode test  
fit

  ##### Load JSON /home/runner/work/mlmodels/mlmodels/mlmodels/dataset/json/benchmark_cnn/mnist/resnext50_32x4d_benchmark_MNIST.json 

  ##### Init model_tch.torchhub.py {'path': '/home/runner/work/mlmodels/mlmodels/mlmodels/ztest/model_tch/torchhub/resnext50_32x4d/', 'model_uri': 'model_tch.torchhub.py'} 
Traceback (most recent call last):
  File "/opt/hostedtoolcache/Python/3.6.12/x64/bin/ml_models", line 11, in <module>
    load_entry_point('mlmodels', 'console_scripts', 'ml_models')()
  File "/home/runner/work/mlmodels/mlmodels/mlmodels/models.py", line 530, in main
    fit_cli(arg)
  File "/home/runner/work/mlmodels/mlmodels/mlmodels/models.py", line 421, in fit_cli
    model = model_create(module, model_p, data_p, compute_p)  # Exact map JSON and paramters
  File "/home/runner/work/mlmodels/mlmodels/mlmodels/models.py", line 113, in model_create
    module.init(model_pars=model_pars, data_pars=data_pars, compute_pars=compute_pars, **kwarg)
AttributeError: module 'mlmodels.model_tch.torchhub' has no attribute 'init'





 ********************************************************************************************************************************************

  ml_models --do fit --config_file /home/runner/work/mlmodels/mlmodels/mlmodels/dataset/json/benchmark_cnn/mnist/resnext50_32x4d_benchmark_MNIST.json  --config_mode prod  
fit

  ##### Load JSON /home/runner/work/mlmodels/mlmodels/mlmodels/dataset/json/benchmark_cnn/mnist/resnext50_32x4d_benchmark_MNIST.json 
Traceback (most recent call last):
  File "/opt/hostedtoolcache/Python/3.6.12/x64/bin/ml_models", line 11, in <module>
    load_entry_point('mlmodels', 'console_scripts', 'ml_models')()
  File "/home/runner/work/mlmodels/mlmodels/mlmodels/models.py", line 530, in main
    fit_cli(arg)
  File "/home/runner/work/mlmodels/mlmodels/mlmodels/models.py", line 413, in fit_cli
    model_p, data_p, compute_p, out_p = config_get_pars(config_file, arg.config_mode)
  File "/home/runner/work/mlmodels/mlmodels/mlmodels/models.py", line 299, in config_get_pars
    out_p     = path_norm_dict( js.get("out_pars") )
  File "/home/runner/work/mlmodels/mlmodels/mlmodels/util.py", line 201, in path_norm_dict
    for k,v in ddict.items():
AttributeError: 'NoneType' object has no attribute 'items'

  


 ************ JSON File /home/runner/work/mlmodels/mlmodels/mlmodels/dataset/json/benchmark_cnn/mnist/resnext101_32x8d_benchmark_MNIST.json 





 ********************************************************************************************************************************************

  ml_models --do fit --config_file /home/runner/work/mlmodels/mlmodels/mlmodels/dataset/json/benchmark_cnn/mnist/resnext101_32x8d_benchmark_MNIST.json  --config_mode test  
fit

  ##### Load JSON /home/runner/work/mlmodels/mlmodels/mlmodels/dataset/json/benchmark_cnn/mnist/resnext101_32x8d_benchmark_MNIST.json 

  ##### Init model_tch.torchhub.py {'path': '/home/runner/work/mlmodels/mlmodels/mlmodels/ztest/model_tch/torchhub/resnext101_32x8d/', 'model_uri': 'model_tch.torchhub.py'} 
Traceback (most recent call last):
  File "/opt/hostedtoolcache/Python/3.6.12/x64/bin/ml_models", line 11, in <module>
    load_entry_point('mlmodels', 'console_scripts', 'ml_models')()
  File "/home/runner/work/mlmodels/mlmodels/mlmodels/models.py", line 530, in main
    fit_cli(arg)
  File "/home/runner/work/mlmodels/mlmodels/mlmodels/models.py", line 421, in fit_cli
    model = model_create(module, model_p, data_p, compute_p)  # Exact map JSON and paramters
  File "/home/runner/work/mlmodels/mlmodels/mlmodels/models.py", line 113, in model_create
    module.init(model_pars=model_pars, data_pars=data_pars, compute_pars=compute_pars, **kwarg)
AttributeError: module 'mlmodels.model_tch.torchhub' has no attribute 'init'





 ********************************************************************************************************************************************

  ml_models --do fit --config_file /home/runner/work/mlmodels/mlmodels/mlmodels/dataset/json/benchmark_cnn/mnist/resnext101_32x8d_benchmark_MNIST.json  --config_mode prod  
fit

  ##### Load JSON /home/runner/work/mlmodels/mlmodels/mlmodels/dataset/json/benchmark_cnn/mnist/resnext101_32x8d_benchmark_MNIST.json 
Traceback (most recent call last):
  File "/opt/hostedtoolcache/Python/3.6.12/x64/bin/ml_models", line 11, in <module>
    load_entry_point('mlmodels', 'console_scripts', 'ml_models')()
  File "/home/runner/work/mlmodels/mlmodels/mlmodels/models.py", line 530, in main
    fit_cli(arg)
  File "/home/runner/work/mlmodels/mlmodels/mlmodels/models.py", line 413, in fit_cli
    model_p, data_p, compute_p, out_p = config_get_pars(config_file, arg.config_mode)
  File "/home/runner/work/mlmodels/mlmodels/mlmodels/models.py", line 299, in config_get_pars
    out_p     = path_norm_dict( js.get("out_pars") )
  File "/home/runner/work/mlmodels/mlmodels/mlmodels/util.py", line 201, in path_norm_dict
    for k,v in ddict.items():
AttributeError: 'NoneType' object has no attribute 'items'

  


 ************ JSON File /home/runner/work/mlmodels/mlmodels/mlmodels/dataset/json/benchmark_cnn/mnist/resnet50_benchmark_MNIST.json 





 ********************************************************************************************************************************************

  ml_models --do fit --config_file /home/runner/work/mlmodels/mlmodels/mlmodels/dataset/json/benchmark_cnn/mnist/resnet50_benchmark_MNIST.json  --config_mode test  
fit

  ##### Load JSON /home/runner/work/mlmodels/mlmodels/mlmodels/dataset/json/benchmark_cnn/mnist/resnet50_benchmark_MNIST.json 

  ##### Init model_tch.torchhub.py {'path': '/home/runner/work/mlmodels/mlmodels/mlmodels/ztest/model_tch/torchhub/resnet50/', 'model_uri': 'model_tch.torchhub.py'} 
Traceback (most recent call last):
  File "/opt/hostedtoolcache/Python/3.6.12/x64/bin/ml_models", line 11, in <module>
    load_entry_point('mlmodels', 'console_scripts', 'ml_models')()
  File "/home/runner/work/mlmodels/mlmodels/mlmodels/models.py", line 530, in main
    fit_cli(arg)
  File "/home/runner/work/mlmodels/mlmodels/mlmodels/models.py", line 421, in fit_cli
    model = model_create(module, model_p, data_p, compute_p)  # Exact map JSON and paramters
  File "/home/runner/work/mlmodels/mlmodels/mlmodels/models.py", line 113, in model_create
    module.init(model_pars=model_pars, data_pars=data_pars, compute_pars=compute_pars, **kwarg)
AttributeError: module 'mlmodels.model_tch.torchhub' has no attribute 'init'





 ********************************************************************************************************************************************

  ml_models --do fit --config_file /home/runner/work/mlmodels/mlmodels/mlmodels/dataset/json/benchmark_cnn/mnist/resnet50_benchmark_MNIST.json  --config_mode prod  
fit

  ##### Load JSON /home/runner/work/mlmodels/mlmodels/mlmodels/dataset/json/benchmark_cnn/mnist/resnet50_benchmark_MNIST.json 
Traceback (most recent call last):
  File "/opt/hostedtoolcache/Python/3.6.12/x64/bin/ml_models", line 11, in <module>
    load_entry_point('mlmodels', 'console_scripts', 'ml_models')()
  File "/home/runner/work/mlmodels/mlmodels/mlmodels/models.py", line 530, in main
    fit_cli(arg)
  File "/home/runner/work/mlmodels/mlmodels/mlmodels/models.py", line 413, in fit_cli
    model_p, data_p, compute_p, out_p = config_get_pars(config_file, arg.config_mode)
  File "/home/runner/work/mlmodels/mlmodels/mlmodels/models.py", line 299, in config_get_pars
    out_p     = path_norm_dict( js.get("out_pars") )
  File "/home/runner/work/mlmodels/mlmodels/mlmodels/util.py", line 201, in path_norm_dict
    for k,v in ddict.items():
AttributeError: 'NoneType' object has no attribute 'items'

  


 ************ JSON File /home/runner/work/mlmodels/mlmodels/mlmodels/dataset/json/benchmark_cnn/mnist/wide_resnet101_2_benchmark_MNIST.json 





 ********************************************************************************************************************************************

  ml_models --do fit --config_file /home/runner/work/mlmodels/mlmodels/mlmodels/dataset/json/benchmark_cnn/mnist/wide_resnet101_2_benchmark_MNIST.json  --config_mode test  
fit

  ##### Load JSON /home/runner/work/mlmodels/mlmodels/mlmodels/dataset/json/benchmark_cnn/mnist/wide_resnet101_2_benchmark_MNIST.json 

  ##### Init model_tch.torchhub.py {'path': '/home/runner/work/mlmodels/mlmodels/mlmodels/ztest/model_tch/torchhub/wide_resnet101_2/', 'model_uri': 'model_tch.torchhub.py'} 
Traceback (most recent call last):
  File "/opt/hostedtoolcache/Python/3.6.12/x64/bin/ml_models", line 11, in <module>
    load_entry_point('mlmodels', 'console_scripts', 'ml_models')()
  File "/home/runner/work/mlmodels/mlmodels/mlmodels/models.py", line 530, in main
    fit_cli(arg)
  File "/home/runner/work/mlmodels/mlmodels/mlmodels/models.py", line 421, in fit_cli
    model = model_create(module, model_p, data_p, compute_p)  # Exact map JSON and paramters
  File "/home/runner/work/mlmodels/mlmodels/mlmodels/models.py", line 113, in model_create
    module.init(model_pars=model_pars, data_pars=data_pars, compute_pars=compute_pars, **kwarg)
AttributeError: module 'mlmodels.model_tch.torchhub' has no attribute 'init'





 ********************************************************************************************************************************************

  ml_models --do fit --config_file /home/runner/work/mlmodels/mlmodels/mlmodels/dataset/json/benchmark_cnn/mnist/wide_resnet101_2_benchmark_MNIST.json  --config_mode prod  
fit

  ##### Load JSON /home/runner/work/mlmodels/mlmodels/mlmodels/dataset/json/benchmark_cnn/mnist/wide_resnet101_2_benchmark_MNIST.json 
Traceback (most recent call last):
  File "/opt/hostedtoolcache/Python/3.6.12/x64/bin/ml_models", line 11, in <module>
    load_entry_point('mlmodels', 'console_scripts', 'ml_models')()
  File "/home/runner/work/mlmodels/mlmodels/mlmodels/models.py", line 530, in main
    fit_cli(arg)
  File "/home/runner/work/mlmodels/mlmodels/mlmodels/models.py", line 413, in fit_cli
    model_p, data_p, compute_p, out_p = config_get_pars(config_file, arg.config_mode)
  File "/home/runner/work/mlmodels/mlmodels/mlmodels/models.py", line 299, in config_get_pars
    out_p     = path_norm_dict( js.get("out_pars") )
  File "/home/runner/work/mlmodels/mlmodels/mlmodels/util.py", line 201, in path_norm_dict
    for k,v in ddict.items():
AttributeError: 'NoneType' object has no attribute 'items'

  


 ************ JSON File /home/runner/work/mlmodels/mlmodels/mlmodels/dataset/json/benchmark_cnn/mnist/resnet101_benchmark_MNIST.json 





 ********************************************************************************************************************************************

  ml_models --do fit --config_file /home/runner/work/mlmodels/mlmodels/mlmodels/dataset/json/benchmark_cnn/mnist/resnet101_benchmark_MNIST.json  --config_mode test  
fit

  ##### Load JSON /home/runner/work/mlmodels/mlmodels/mlmodels/dataset/json/benchmark_cnn/mnist/resnet101_benchmark_MNIST.json 

  ##### Init model_tch.torchhub.py {'path': '/home/runner/work/mlmodels/mlmodels/mlmodels/ztest/model_tch/torchhub/resnet101/', 'model_uri': 'model_tch.torchhub.py'} 
Traceback (most recent call last):
  File "/opt/hostedtoolcache/Python/3.6.12/x64/bin/ml_models", line 11, in <module>
    load_entry_point('mlmodels', 'console_scripts', 'ml_models')()
  File "/home/runner/work/mlmodels/mlmodels/mlmodels/models.py", line 530, in main
    fit_cli(arg)
  File "/home/runner/work/mlmodels/mlmodels/mlmodels/models.py", line 421, in fit_cli
    model = model_create(module, model_p, data_p, compute_p)  # Exact map JSON and paramters
  File "/home/runner/work/mlmodels/mlmodels/mlmodels/models.py", line 113, in model_create
    module.init(model_pars=model_pars, data_pars=data_pars, compute_pars=compute_pars, **kwarg)
AttributeError: module 'mlmodels.model_tch.torchhub' has no attribute 'init'





 ********************************************************************************************************************************************

  ml_models --do fit --config_file /home/runner/work/mlmodels/mlmodels/mlmodels/dataset/json/benchmark_cnn/mnist/resnet101_benchmark_MNIST.json  --config_mode prod  
fit

  ##### Load JSON /home/runner/work/mlmodels/mlmodels/mlmodels/dataset/json/benchmark_cnn/mnist/resnet101_benchmark_MNIST.json 
Traceback (most recent call last):
  File "/opt/hostedtoolcache/Python/3.6.12/x64/bin/ml_models", line 11, in <module>
    load_entry_point('mlmodels', 'console_scripts', 'ml_models')()
  File "/home/runner/work/mlmodels/mlmodels/mlmodels/models.py", line 530, in main
    fit_cli(arg)
  File "/home/runner/work/mlmodels/mlmodels/mlmodels/models.py", line 413, in fit_cli
    model_p, data_p, compute_p, out_p = config_get_pars(config_file, arg.config_mode)
  File "/home/runner/work/mlmodels/mlmodels/mlmodels/models.py", line 299, in config_get_pars
    out_p     = path_norm_dict( js.get("out_pars") )
  File "/home/runner/work/mlmodels/mlmodels/mlmodels/util.py", line 201, in path_norm_dict
    for k,v in ddict.items():
AttributeError: 'NoneType' object has no attribute 'items'

  


 ************ JSON File /home/runner/work/mlmodels/mlmodels/mlmodels/dataset/json/benchmark_cnn/mnist/wide_resnet50_2_benchmark_MNIST.json 





 ********************************************************************************************************************************************

  ml_models --do fit --config_file /home/runner/work/mlmodels/mlmodels/mlmodels/dataset/json/benchmark_cnn/mnist/wide_resnet50_2_benchmark_MNIST.json  --config_mode test  
fit

  ##### Load JSON /home/runner/work/mlmodels/mlmodels/mlmodels/dataset/json/benchmark_cnn/mnist/wide_resnet50_2_benchmark_MNIST.json 

  ##### Init model_tch.torchhub.py {'path': '/home/runner/work/mlmodels/mlmodels/mlmodels/ztest/model_tch/torchhub/wide_resnet50_2/', 'model_uri': 'model_tch.torchhub.py'} 
Traceback (most recent call last):
  File "/opt/hostedtoolcache/Python/3.6.12/x64/bin/ml_models", line 11, in <module>
    load_entry_point('mlmodels', 'console_scripts', 'ml_models')()
  File "/home/runner/work/mlmodels/mlmodels/mlmodels/models.py", line 530, in main
    fit_cli(arg)
  File "/home/runner/work/mlmodels/mlmodels/mlmodels/models.py", line 421, in fit_cli
    model = model_create(module, model_p, data_p, compute_p)  # Exact map JSON and paramters
  File "/home/runner/work/mlmodels/mlmodels/mlmodels/models.py", line 113, in model_create
    module.init(model_pars=model_pars, data_pars=data_pars, compute_pars=compute_pars, **kwarg)
AttributeError: module 'mlmodels.model_tch.torchhub' has no attribute 'init'





 ********************************************************************************************************************************************

  ml_models --do fit --config_file /home/runner/work/mlmodels/mlmodels/mlmodels/dataset/json/benchmark_cnn/mnist/wide_resnet50_2_benchmark_MNIST.json  --config_mode prod  
fit

  ##### Load JSON /home/runner/work/mlmodels/mlmodels/mlmodels/dataset/json/benchmark_cnn/mnist/wide_resnet50_2_benchmark_MNIST.json 
Traceback (most recent call last):
  File "/opt/hostedtoolcache/Python/3.6.12/x64/bin/ml_models", line 11, in <module>
    load_entry_point('mlmodels', 'console_scripts', 'ml_models')()
  File "/home/runner/work/mlmodels/mlmodels/mlmodels/models.py", line 530, in main
    fit_cli(arg)
  File "/home/runner/work/mlmodels/mlmodels/mlmodels/models.py", line 413, in fit_cli
    model_p, data_p, compute_p, out_p = config_get_pars(config_file, arg.config_mode)
  File "/home/runner/work/mlmodels/mlmodels/mlmodels/models.py", line 299, in config_get_pars
    out_p     = path_norm_dict( js.get("out_pars") )
  File "/home/runner/work/mlmodels/mlmodels/mlmodels/util.py", line 201, in path_norm_dict
    for k,v in ddict.items():
AttributeError: 'NoneType' object has no attribute 'items'

  


 ************ JSON File /home/runner/work/mlmodels/mlmodels/mlmodels/dataset/json/benchmark_cnn/mnist/resnet18_benchmark_MNIST.json 





 ********************************************************************************************************************************************

  ml_models --do fit --config_file /home/runner/work/mlmodels/mlmodels/mlmodels/dataset/json/benchmark_cnn/mnist/resnet18_benchmark_MNIST.json  --config_mode test  
fit

  ##### Load JSON /home/runner/work/mlmodels/mlmodels/mlmodels/dataset/json/benchmark_cnn/mnist/resnet18_benchmark_MNIST.json 

  ##### Init model_tch.torchhub.py {'path': '/home/runner/work/mlmodels/mlmodels/mlmodels/ztest/model_tch/torchhub/resnet18/', 'model_uri': 'model_tch.torchhub.py'} 
Traceback (most recent call last):
  File "/opt/hostedtoolcache/Python/3.6.12/x64/bin/ml_models", line 11, in <module>
    load_entry_point('mlmodels', 'console_scripts', 'ml_models')()
  File "/home/runner/work/mlmodels/mlmodels/mlmodels/models.py", line 530, in main
    fit_cli(arg)
  File "/home/runner/work/mlmodels/mlmodels/mlmodels/models.py", line 421, in fit_cli
    model = model_create(module, model_p, data_p, compute_p)  # Exact map JSON and paramters
  File "/home/runner/work/mlmodels/mlmodels/mlmodels/models.py", line 113, in model_create
    module.init(model_pars=model_pars, data_pars=data_pars, compute_pars=compute_pars, **kwarg)
AttributeError: module 'mlmodels.model_tch.torchhub' has no attribute 'init'





 ********************************************************************************************************************************************

  ml_models --do fit --config_file /home/runner/work/mlmodels/mlmodels/mlmodels/dataset/json/benchmark_cnn/mnist/resnet18_benchmark_MNIST.json  --config_mode prod  
fit

  ##### Load JSON /home/runner/work/mlmodels/mlmodels/mlmodels/dataset/json/benchmark_cnn/mnist/resnet18_benchmark_MNIST.json 
Traceback (most recent call last):
  File "/opt/hostedtoolcache/Python/3.6.12/x64/bin/ml_models", line 11, in <module>
    load_entry_point('mlmodels', 'console_scripts', 'ml_models')()
  File "/home/runner/work/mlmodels/mlmodels/mlmodels/models.py", line 530, in main
    fit_cli(arg)
  File "/home/runner/work/mlmodels/mlmodels/mlmodels/models.py", line 413, in fit_cli
    model_p, data_p, compute_p, out_p = config_get_pars(config_file, arg.config_mode)
  File "/home/runner/work/mlmodels/mlmodels/mlmodels/models.py", line 299, in config_get_pars
    out_p     = path_norm_dict( js.get("out_pars") )
  File "/home/runner/work/mlmodels/mlmodels/mlmodels/util.py", line 201, in path_norm_dict
    for k,v in ddict.items():
AttributeError: 'NoneType' object has no attribute 'items'

  


 ************ JSON File /home/runner/work/mlmodels/mlmodels/mlmodels/dataset/json/benchmark_cnn/mnist/shufflenet_v2_x0_5_benchmark_MNIST.json 





 ********************************************************************************************************************************************

  ml_models --do fit --config_file /home/runner/work/mlmodels/mlmodels/mlmodels/dataset/json/benchmark_cnn/mnist/shufflenet_v2_x0_5_benchmark_MNIST.json  --config_mode test  
fit

  ##### Load JSON /home/runner/work/mlmodels/mlmodels/mlmodels/dataset/json/benchmark_cnn/mnist/shufflenet_v2_x0_5_benchmark_MNIST.json 

  ##### Init model_tch.torchhub.py {'path': '/home/runner/work/mlmodels/mlmodels/mlmodels/ztest/model_tch/torchhub/shufflenet_v2_x0_5/', 'model_uri': 'model_tch.torchhub.py'} 
Traceback (most recent call last):
  File "/opt/hostedtoolcache/Python/3.6.12/x64/bin/ml_models", line 11, in <module>
    load_entry_point('mlmodels', 'console_scripts', 'ml_models')()
  File "/home/runner/work/mlmodels/mlmodels/mlmodels/models.py", line 530, in main
    fit_cli(arg)
  File "/home/runner/work/mlmodels/mlmodels/mlmodels/models.py", line 421, in fit_cli
    model = model_create(module, model_p, data_p, compute_p)  # Exact map JSON and paramters
  File "/home/runner/work/mlmodels/mlmodels/mlmodels/models.py", line 113, in model_create
    module.init(model_pars=model_pars, data_pars=data_pars, compute_pars=compute_pars, **kwarg)
AttributeError: module 'mlmodels.model_tch.torchhub' has no attribute 'init'





 ********************************************************************************************************************************************

  ml_models --do fit --config_file /home/runner/work/mlmodels/mlmodels/mlmodels/dataset/json/benchmark_cnn/mnist/shufflenet_v2_x0_5_benchmark_MNIST.json  --config_mode prod  
fit

  ##### Load JSON /home/runner/work/mlmodels/mlmodels/mlmodels/dataset/json/benchmark_cnn/mnist/shufflenet_v2_x0_5_benchmark_MNIST.json 
Traceback (most recent call last):
  File "/opt/hostedtoolcache/Python/3.6.12/x64/bin/ml_models", line 11, in <module>
    load_entry_point('mlmodels', 'console_scripts', 'ml_models')()
  File "/home/runner/work/mlmodels/mlmodels/mlmodels/models.py", line 530, in main
    fit_cli(arg)
  File "/home/runner/work/mlmodels/mlmodels/mlmodels/models.py", line 413, in fit_cli
    model_p, data_p, compute_p, out_p = config_get_pars(config_file, arg.config_mode)
  File "/home/runner/work/mlmodels/mlmodels/mlmodels/models.py", line 299, in config_get_pars
    out_p     = path_norm_dict( js.get("out_pars") )
  File "/home/runner/work/mlmodels/mlmodels/mlmodels/util.py", line 201, in path_norm_dict
    for k,v in ddict.items():
AttributeError: 'NoneType' object has no attribute 'items'

  


 ************ JSON File /home/runner/work/mlmodels/mlmodels/mlmodels/dataset/json/benchmark_cnn/mnist/resnet34_benchmark_MNIST.json 





 ********************************************************************************************************************************************

  ml_models --do fit --config_file /home/runner/work/mlmodels/mlmodels/mlmodels/dataset/json/benchmark_cnn/mnist/resnet34_benchmark_MNIST.json  --config_mode test  
fit

  ##### Load JSON /home/runner/work/mlmodels/mlmodels/mlmodels/dataset/json/benchmark_cnn/mnist/resnet34_benchmark_MNIST.json 

  ##### Init model_tch.torchhub.py {'path': '/home/runner/work/mlmodels/mlmodels/mlmodels/ztest/model_tch/torchhub/resnet34/', 'model_uri': 'model_tch.torchhub.py'} 
Traceback (most recent call last):
  File "/opt/hostedtoolcache/Python/3.6.12/x64/bin/ml_models", line 11, in <module>
    load_entry_point('mlmodels', 'console_scripts', 'ml_models')()
  File "/home/runner/work/mlmodels/mlmodels/mlmodels/models.py", line 530, in main
    fit_cli(arg)
  File "/home/runner/work/mlmodels/mlmodels/mlmodels/models.py", line 421, in fit_cli
    model = model_create(module, model_p, data_p, compute_p)  # Exact map JSON and paramters
  File "/home/runner/work/mlmodels/mlmodels/mlmodels/models.py", line 113, in model_create
    module.init(model_pars=model_pars, data_pars=data_pars, compute_pars=compute_pars, **kwarg)
AttributeError: module 'mlmodels.model_tch.torchhub' has no attribute 'init'





 ********************************************************************************************************************************************

  ml_models --do fit --config_file /home/runner/work/mlmodels/mlmodels/mlmodels/dataset/json/benchmark_cnn/mnist/resnet34_benchmark_MNIST.json  --config_mode prod  
fit

  ##### Load JSON /home/runner/work/mlmodels/mlmodels/mlmodels/dataset/json/benchmark_cnn/mnist/resnet34_benchmark_MNIST.json 
Traceback (most recent call last):
  File "/opt/hostedtoolcache/Python/3.6.12/x64/bin/ml_models", line 11, in <module>
    load_entry_point('mlmodels', 'console_scripts', 'ml_models')()
  File "/home/runner/work/mlmodels/mlmodels/mlmodels/models.py", line 530, in main
    fit_cli(arg)
  File "/home/runner/work/mlmodels/mlmodels/mlmodels/models.py", line 413, in fit_cli
    model_p, data_p, compute_p, out_p = config_get_pars(config_file, arg.config_mode)
  File "/home/runner/work/mlmodels/mlmodels/mlmodels/models.py", line 299, in config_get_pars
    out_p     = path_norm_dict( js.get("out_pars") )
  File "/home/runner/work/mlmodels/mlmodels/mlmodels/util.py", line 201, in path_norm_dict
    for k,v in ddict.items():
AttributeError: 'NoneType' object has no attribute 'items'

  


 ************ JSON File /home/runner/work/mlmodels/mlmodels/mlmodels/dataset/json/benchmark_cnn/fashion_mnist/shufflenet_v2_x0_5_benchmark_FashionMNIST.json 





 ********************************************************************************************************************************************

  ml_models --do fit --config_file /home/runner/work/mlmodels/mlmodels/mlmodels/dataset/json/benchmark_cnn/fashion_mnist/shufflenet_v2_x0_5_benchmark_FashionMNIST.json  --config_mode test  
fit

  ##### Load JSON /home/runner/work/mlmodels/mlmodels/mlmodels/dataset/json/benchmark_cnn/fashion_mnist/shufflenet_v2_x0_5_benchmark_FashionMNIST.json 

  ##### Init model_tch.torchhub.py {'path': '/home/runner/work/mlmodels/mlmodels/mlmodels/ztest/model_tch/torchhub/shufflenet_v2_x0_5/', 'model_uri': 'model_tch.torchhub.py'} 
Traceback (most recent call last):
  File "/opt/hostedtoolcache/Python/3.6.12/x64/bin/ml_models", line 11, in <module>
    load_entry_point('mlmodels', 'console_scripts', 'ml_models')()
  File "/home/runner/work/mlmodels/mlmodels/mlmodels/models.py", line 530, in main
    fit_cli(arg)
  File "/home/runner/work/mlmodels/mlmodels/mlmodels/models.py", line 421, in fit_cli
    model = model_create(module, model_p, data_p, compute_p)  # Exact map JSON and paramters
  File "/home/runner/work/mlmodels/mlmodels/mlmodels/models.py", line 113, in model_create
    module.init(model_pars=model_pars, data_pars=data_pars, compute_pars=compute_pars, **kwarg)
AttributeError: module 'mlmodels.model_tch.torchhub' has no attribute 'init'





 ********************************************************************************************************************************************

  ml_models --do fit --config_file /home/runner/work/mlmodels/mlmodels/mlmodels/dataset/json/benchmark_cnn/fashion_mnist/shufflenet_v2_x0_5_benchmark_FashionMNIST.json  --config_mode prod  
fit

  ##### Load JSON /home/runner/work/mlmodels/mlmodels/mlmodels/dataset/json/benchmark_cnn/fashion_mnist/shufflenet_v2_x0_5_benchmark_FashionMNIST.json 
Traceback (most recent call last):
  File "/opt/hostedtoolcache/Python/3.6.12/x64/bin/ml_models", line 11, in <module>
    load_entry_point('mlmodels', 'console_scripts', 'ml_models')()
  File "/home/runner/work/mlmodels/mlmodels/mlmodels/models.py", line 530, in main
    fit_cli(arg)
  File "/home/runner/work/mlmodels/mlmodels/mlmodels/models.py", line 413, in fit_cli
    model_p, data_p, compute_p, out_p = config_get_pars(config_file, arg.config_mode)
  File "/home/runner/work/mlmodels/mlmodels/mlmodels/models.py", line 299, in config_get_pars
    out_p     = path_norm_dict( js.get("out_pars") )
  File "/home/runner/work/mlmodels/mlmodels/mlmodels/util.py", line 201, in path_norm_dict
    for k,v in ddict.items():
AttributeError: 'NoneType' object has no attribute 'items'

  


 ************ JSON File /home/runner/work/mlmodels/mlmodels/mlmodels/dataset/json/benchmark_cnn/fashion_mnist/resnet152_benchmark_FashionMNIST.json 





 ********************************************************************************************************************************************

  ml_models --do fit --config_file /home/runner/work/mlmodels/mlmodels/mlmodels/dataset/json/benchmark_cnn/fashion_mnist/resnet152_benchmark_FashionMNIST.json  --config_mode test  
fit

  ##### Load JSON /home/runner/work/mlmodels/mlmodels/mlmodels/dataset/json/benchmark_cnn/fashion_mnist/resnet152_benchmark_FashionMNIST.json 

  ##### Init model_tch.torchhub.py {'path': '/home/runner/work/mlmodels/mlmodels/mlmodels/ztest/model_tch/torchhub/resnet152/', 'model_uri': 'model_tch.torchhub.py'} 
Traceback (most recent call last):
  File "/opt/hostedtoolcache/Python/3.6.12/x64/bin/ml_models", line 11, in <module>
    load_entry_point('mlmodels', 'console_scripts', 'ml_models')()
  File "/home/runner/work/mlmodels/mlmodels/mlmodels/models.py", line 530, in main
    fit_cli(arg)
  File "/home/runner/work/mlmodels/mlmodels/mlmodels/models.py", line 421, in fit_cli
    model = model_create(module, model_p, data_p, compute_p)  # Exact map JSON and paramters
  File "/home/runner/work/mlmodels/mlmodels/mlmodels/models.py", line 113, in model_create
    module.init(model_pars=model_pars, data_pars=data_pars, compute_pars=compute_pars, **kwarg)
AttributeError: module 'mlmodels.model_tch.torchhub' has no attribute 'init'





 ********************************************************************************************************************************************

  ml_models --do fit --config_file /home/runner/work/mlmodels/mlmodels/mlmodels/dataset/json/benchmark_cnn/fashion_mnist/resnet152_benchmark_FashionMNIST.json  --config_mode prod  
fit

  ##### Load JSON /home/runner/work/mlmodels/mlmodels/mlmodels/dataset/json/benchmark_cnn/fashion_mnist/resnet152_benchmark_FashionMNIST.json 
Traceback (most recent call last):
  File "/opt/hostedtoolcache/Python/3.6.12/x64/bin/ml_models", line 11, in <module>
    load_entry_point('mlmodels', 'console_scripts', 'ml_models')()
  File "/home/runner/work/mlmodels/mlmodels/mlmodels/models.py", line 530, in main
    fit_cli(arg)
  File "/home/runner/work/mlmodels/mlmodels/mlmodels/models.py", line 413, in fit_cli
    model_p, data_p, compute_p, out_p = config_get_pars(config_file, arg.config_mode)
  File "/home/runner/work/mlmodels/mlmodels/mlmodels/models.py", line 299, in config_get_pars
    out_p     = path_norm_dict( js.get("out_pars") )
  File "/home/runner/work/mlmodels/mlmodels/mlmodels/util.py", line 201, in path_norm_dict
    for k,v in ddict.items():
AttributeError: 'NoneType' object has no attribute 'items'

  


 ************ JSON File /home/runner/work/mlmodels/mlmodels/mlmodels/dataset/json/benchmark_cnn/fashion_mnist/resnet18_benchmark_FashionMNIST.json 





 ********************************************************************************************************************************************

  ml_models --do fit --config_file /home/runner/work/mlmodels/mlmodels/mlmodels/dataset/json/benchmark_cnn/fashion_mnist/resnet18_benchmark_FashionMNIST.json  --config_mode test  
fit

  ##### Load JSON /home/runner/work/mlmodels/mlmodels/mlmodels/dataset/json/benchmark_cnn/fashion_mnist/resnet18_benchmark_FashionMNIST.json 

  ##### Init model_tch.torchhub.py {'path': '/home/runner/work/mlmodels/mlmodels/mlmodels/ztest/model_tch/torchhub/resnet18/', 'model_uri': 'model_tch.torchhub.py'} 
Traceback (most recent call last):
  File "/opt/hostedtoolcache/Python/3.6.12/x64/bin/ml_models", line 11, in <module>
    load_entry_point('mlmodels', 'console_scripts', 'ml_models')()
  File "/home/runner/work/mlmodels/mlmodels/mlmodels/models.py", line 530, in main
    fit_cli(arg)
  File "/home/runner/work/mlmodels/mlmodels/mlmodels/models.py", line 421, in fit_cli
    model = model_create(module, model_p, data_p, compute_p)  # Exact map JSON and paramters
  File "/home/runner/work/mlmodels/mlmodels/mlmodels/models.py", line 113, in model_create
    module.init(model_pars=model_pars, data_pars=data_pars, compute_pars=compute_pars, **kwarg)
AttributeError: module 'mlmodels.model_tch.torchhub' has no attribute 'init'





 ********************************************************************************************************************************************

  ml_models --do fit --config_file /home/runner/work/mlmodels/mlmodels/mlmodels/dataset/json/benchmark_cnn/fashion_mnist/resnet18_benchmark_FashionMNIST.json  --config_mode prod  
fit

  ##### Load JSON /home/runner/work/mlmodels/mlmodels/mlmodels/dataset/json/benchmark_cnn/fashion_mnist/resnet18_benchmark_FashionMNIST.json 
Traceback (most recent call last):
  File "/opt/hostedtoolcache/Python/3.6.12/x64/bin/ml_models", line 11, in <module>
    load_entry_point('mlmodels', 'console_scripts', 'ml_models')()
  File "/home/runner/work/mlmodels/mlmodels/mlmodels/models.py", line 530, in main
    fit_cli(arg)
  File "/home/runner/work/mlmodels/mlmodels/mlmodels/models.py", line 413, in fit_cli
    model_p, data_p, compute_p, out_p = config_get_pars(config_file, arg.config_mode)
  File "/home/runner/work/mlmodels/mlmodels/mlmodels/models.py", line 299, in config_get_pars
    out_p     = path_norm_dict( js.get("out_pars") )
  File "/home/runner/work/mlmodels/mlmodels/mlmodels/util.py", line 201, in path_norm_dict
    for k,v in ddict.items():
AttributeError: 'NoneType' object has no attribute 'items'

  


 ************ JSON File /home/runner/work/mlmodels/mlmodels/mlmodels/dataset/json/benchmark_cnn/fashion_mnist/resnet34_benchmark_FashionMNIST.json 





 ********************************************************************************************************************************************

  ml_models --do fit --config_file /home/runner/work/mlmodels/mlmodels/mlmodels/dataset/json/benchmark_cnn/fashion_mnist/resnet34_benchmark_FashionMNIST.json  --config_mode test  
fit

  ##### Load JSON /home/runner/work/mlmodels/mlmodels/mlmodels/dataset/json/benchmark_cnn/fashion_mnist/resnet34_benchmark_FashionMNIST.json 

  ##### Init model_tch.torchhub.py {'path': '/home/runner/work/mlmodels/mlmodels/mlmodels/ztest/model_tch/torchhub/resnet34/', 'model_uri': 'model_tch.torchhub.py'} 
Traceback (most recent call last):
  File "/opt/hostedtoolcache/Python/3.6.12/x64/bin/ml_models", line 11, in <module>
    load_entry_point('mlmodels', 'console_scripts', 'ml_models')()
  File "/home/runner/work/mlmodels/mlmodels/mlmodels/models.py", line 530, in main
    fit_cli(arg)
  File "/home/runner/work/mlmodels/mlmodels/mlmodels/models.py", line 421, in fit_cli
    model = model_create(module, model_p, data_p, compute_p)  # Exact map JSON and paramters
  File "/home/runner/work/mlmodels/mlmodels/mlmodels/models.py", line 113, in model_create
    module.init(model_pars=model_pars, data_pars=data_pars, compute_pars=compute_pars, **kwarg)
AttributeError: module 'mlmodels.model_tch.torchhub' has no attribute 'init'





 ********************************************************************************************************************************************

  ml_models --do fit --config_file /home/runner/work/mlmodels/mlmodels/mlmodels/dataset/json/benchmark_cnn/fashion_mnist/resnet34_benchmark_FashionMNIST.json  --config_mode prod  
fit

  ##### Load JSON /home/runner/work/mlmodels/mlmodels/mlmodels/dataset/json/benchmark_cnn/fashion_mnist/resnet34_benchmark_FashionMNIST.json 
Traceback (most recent call last):
  File "/opt/hostedtoolcache/Python/3.6.12/x64/bin/ml_models", line 11, in <module>
    load_entry_point('mlmodels', 'console_scripts', 'ml_models')()
  File "/home/runner/work/mlmodels/mlmodels/mlmodels/models.py", line 530, in main
    fit_cli(arg)
  File "/home/runner/work/mlmodels/mlmodels/mlmodels/models.py", line 413, in fit_cli
    model_p, data_p, compute_p, out_p = config_get_pars(config_file, arg.config_mode)
  File "/home/runner/work/mlmodels/mlmodels/mlmodels/models.py", line 299, in config_get_pars
    out_p     = path_norm_dict( js.get("out_pars") )
  File "/home/runner/work/mlmodels/mlmodels/mlmodels/util.py", line 201, in path_norm_dict
    for k,v in ddict.items():
AttributeError: 'NoneType' object has no attribute 'items'

  


 ************ JSON File /home/runner/work/mlmodels/mlmodels/mlmodels/dataset/json/benchmark_cnn/fashion_mnist/resnext50_32x4d_benchmark_FashionMNIST.json 





 ********************************************************************************************************************************************

  ml_models --do fit --config_file /home/runner/work/mlmodels/mlmodels/mlmodels/dataset/json/benchmark_cnn/fashion_mnist/resnext50_32x4d_benchmark_FashionMNIST.json  --config_mode test  
fit

  ##### Load JSON /home/runner/work/mlmodels/mlmodels/mlmodels/dataset/json/benchmark_cnn/fashion_mnist/resnext50_32x4d_benchmark_FashionMNIST.json 

  ##### Init model_tch.torchhub.py {'path': '/home/runner/work/mlmodels/mlmodels/mlmodels/ztest/model_tch/torchhub/resnext50_32x4d/', 'model_uri': 'model_tch.torchhub.py'} 
Traceback (most recent call last):
  File "/opt/hostedtoolcache/Python/3.6.12/x64/bin/ml_models", line 11, in <module>
    load_entry_point('mlmodels', 'console_scripts', 'ml_models')()
  File "/home/runner/work/mlmodels/mlmodels/mlmodels/models.py", line 530, in main
    fit_cli(arg)
  File "/home/runner/work/mlmodels/mlmodels/mlmodels/models.py", line 421, in fit_cli
    model = model_create(module, model_p, data_p, compute_p)  # Exact map JSON and paramters
  File "/home/runner/work/mlmodels/mlmodels/mlmodels/models.py", line 113, in model_create
    module.init(model_pars=model_pars, data_pars=data_pars, compute_pars=compute_pars, **kwarg)
AttributeError: module 'mlmodels.model_tch.torchhub' has no attribute 'init'





 ********************************************************************************************************************************************

  ml_models --do fit --config_file /home/runner/work/mlmodels/mlmodels/mlmodels/dataset/json/benchmark_cnn/fashion_mnist/resnext50_32x4d_benchmark_FashionMNIST.json  --config_mode prod  
fit

  ##### Load JSON /home/runner/work/mlmodels/mlmodels/mlmodels/dataset/json/benchmark_cnn/fashion_mnist/resnext50_32x4d_benchmark_FashionMNIST.json 
Traceback (most recent call last):
  File "/opt/hostedtoolcache/Python/3.6.12/x64/bin/ml_models", line 11, in <module>
    load_entry_point('mlmodels', 'console_scripts', 'ml_models')()
  File "/home/runner/work/mlmodels/mlmodels/mlmodels/models.py", line 530, in main
    fit_cli(arg)
  File "/home/runner/work/mlmodels/mlmodels/mlmodels/models.py", line 413, in fit_cli
    model_p, data_p, compute_p, out_p = config_get_pars(config_file, arg.config_mode)
  File "/home/runner/work/mlmodels/mlmodels/mlmodels/models.py", line 299, in config_get_pars
    out_p     = path_norm_dict( js.get("out_pars") )
  File "/home/runner/work/mlmodels/mlmodels/mlmodels/util.py", line 201, in path_norm_dict
    for k,v in ddict.items():
AttributeError: 'NoneType' object has no attribute 'items'

  


 ************ JSON File /home/runner/work/mlmodels/mlmodels/mlmodels/dataset/json/benchmark_cnn/fashion_mnist/wide_resnet101_2_benchmark_FashionMNIST.json 





 ********************************************************************************************************************************************

  ml_models --do fit --config_file /home/runner/work/mlmodels/mlmodels/mlmodels/dataset/json/benchmark_cnn/fashion_mnist/wide_resnet101_2_benchmark_FashionMNIST.json  --config_mode test  
fit

  ##### Load JSON /home/runner/work/mlmodels/mlmodels/mlmodels/dataset/json/benchmark_cnn/fashion_mnist/wide_resnet101_2_benchmark_FashionMNIST.json 

  ##### Init model_tch.torchhub.py {'path': '/home/runner/work/mlmodels/mlmodels/mlmodels/ztest/model_tch/torchhub/wide_resnet101_2/', 'model_uri': 'model_tch.torchhub.py'} 
Traceback (most recent call last):
  File "/opt/hostedtoolcache/Python/3.6.12/x64/bin/ml_models", line 11, in <module>
    load_entry_point('mlmodels', 'console_scripts', 'ml_models')()
  File "/home/runner/work/mlmodels/mlmodels/mlmodels/models.py", line 530, in main
    fit_cli(arg)
  File "/home/runner/work/mlmodels/mlmodels/mlmodels/models.py", line 421, in fit_cli
    model = model_create(module, model_p, data_p, compute_p)  # Exact map JSON and paramters
  File "/home/runner/work/mlmodels/mlmodels/mlmodels/models.py", line 113, in model_create
    module.init(model_pars=model_pars, data_pars=data_pars, compute_pars=compute_pars, **kwarg)
AttributeError: module 'mlmodels.model_tch.torchhub' has no attribute 'init'





 ********************************************************************************************************************************************

  ml_models --do fit --config_file /home/runner/work/mlmodels/mlmodels/mlmodels/dataset/json/benchmark_cnn/fashion_mnist/wide_resnet101_2_benchmark_FashionMNIST.json  --config_mode prod  
fit

  ##### Load JSON /home/runner/work/mlmodels/mlmodels/mlmodels/dataset/json/benchmark_cnn/fashion_mnist/wide_resnet101_2_benchmark_FashionMNIST.json 
Traceback (most recent call last):
  File "/opt/hostedtoolcache/Python/3.6.12/x64/bin/ml_models", line 11, in <module>
    load_entry_point('mlmodels', 'console_scripts', 'ml_models')()
  File "/home/runner/work/mlmodels/mlmodels/mlmodels/models.py", line 530, in main
    fit_cli(arg)
  File "/home/runner/work/mlmodels/mlmodels/mlmodels/models.py", line 413, in fit_cli
    model_p, data_p, compute_p, out_p = config_get_pars(config_file, arg.config_mode)
  File "/home/runner/work/mlmodels/mlmodels/mlmodels/models.py", line 299, in config_get_pars
    out_p     = path_norm_dict( js.get("out_pars") )
  File "/home/runner/work/mlmodels/mlmodels/mlmodels/util.py", line 201, in path_norm_dict
    for k,v in ddict.items():
AttributeError: 'NoneType' object has no attribute 'items'

  


 ************ JSON File /home/runner/work/mlmodels/mlmodels/mlmodels/dataset/json/benchmark_cnn/fashion_mnist/shufflenet_v2_x1_0_benchmark_FashionMNIST.json 





 ********************************************************************************************************************************************

  ml_models --do fit --config_file /home/runner/work/mlmodels/mlmodels/mlmodels/dataset/json/benchmark_cnn/fashion_mnist/shufflenet_v2_x1_0_benchmark_FashionMNIST.json  --config_mode test  
fit

  ##### Load JSON /home/runner/work/mlmodels/mlmodels/mlmodels/dataset/json/benchmark_cnn/fashion_mnist/shufflenet_v2_x1_0_benchmark_FashionMNIST.json 

  ##### Init model_tch.torchhub.py {'path': '/home/runner/work/mlmodels/mlmodels/mlmodels/ztest/model_tch/torchhub/shufflenet_v2_x1_0/', 'model_uri': 'model_tch.torchhub.py'} 
Traceback (most recent call last):
  File "/opt/hostedtoolcache/Python/3.6.12/x64/bin/ml_models", line 11, in <module>
    load_entry_point('mlmodels', 'console_scripts', 'ml_models')()
  File "/home/runner/work/mlmodels/mlmodels/mlmodels/models.py", line 530, in main
    fit_cli(arg)
  File "/home/runner/work/mlmodels/mlmodels/mlmodels/models.py", line 421, in fit_cli
    model = model_create(module, model_p, data_p, compute_p)  # Exact map JSON and paramters
  File "/home/runner/work/mlmodels/mlmodels/mlmodels/models.py", line 113, in model_create
    module.init(model_pars=model_pars, data_pars=data_pars, compute_pars=compute_pars, **kwarg)
AttributeError: module 'mlmodels.model_tch.torchhub' has no attribute 'init'





 ********************************************************************************************************************************************

  ml_models --do fit --config_file /home/runner/work/mlmodels/mlmodels/mlmodels/dataset/json/benchmark_cnn/fashion_mnist/shufflenet_v2_x1_0_benchmark_FashionMNIST.json  --config_mode prod  
fit

  ##### Load JSON /home/runner/work/mlmodels/mlmodels/mlmodels/dataset/json/benchmark_cnn/fashion_mnist/shufflenet_v2_x1_0_benchmark_FashionMNIST.json 
Traceback (most recent call last):
  File "/opt/hostedtoolcache/Python/3.6.12/x64/bin/ml_models", line 11, in <module>
    load_entry_point('mlmodels', 'console_scripts', 'ml_models')()
  File "/home/runner/work/mlmodels/mlmodels/mlmodels/models.py", line 530, in main
    fit_cli(arg)
  File "/home/runner/work/mlmodels/mlmodels/mlmodels/models.py", line 413, in fit_cli
    model_p, data_p, compute_p, out_p = config_get_pars(config_file, arg.config_mode)
  File "/home/runner/work/mlmodels/mlmodels/mlmodels/models.py", line 299, in config_get_pars
    out_p     = path_norm_dict( js.get("out_pars") )
  File "/home/runner/work/mlmodels/mlmodels/mlmodels/util.py", line 201, in path_norm_dict
    for k,v in ddict.items():
AttributeError: 'NoneType' object has no attribute 'items'

  


 ************ JSON File /home/runner/work/mlmodels/mlmodels/mlmodels/dataset/json/benchmark_cnn/fashion_mnist/wide_resnet50_2_benchmark_FashionMNIST.json 





 ********************************************************************************************************************************************

  ml_models --do fit --config_file /home/runner/work/mlmodels/mlmodels/mlmodels/dataset/json/benchmark_cnn/fashion_mnist/wide_resnet50_2_benchmark_FashionMNIST.json  --config_mode test  
fit

  ##### Load JSON /home/runner/work/mlmodels/mlmodels/mlmodels/dataset/json/benchmark_cnn/fashion_mnist/wide_resnet50_2_benchmark_FashionMNIST.json 

  ##### Init model_tch.torchhub.py {'path': '/home/runner/work/mlmodels/mlmodels/mlmodels/ztest/model_tch/torchhub/wide_resnet50_2/', 'model_uri': 'model_tch.torchhub.py'} 
Traceback (most recent call last):
  File "/opt/hostedtoolcache/Python/3.6.12/x64/bin/ml_models", line 11, in <module>
    load_entry_point('mlmodels', 'console_scripts', 'ml_models')()
  File "/home/runner/work/mlmodels/mlmodels/mlmodels/models.py", line 530, in main
    fit_cli(arg)
  File "/home/runner/work/mlmodels/mlmodels/mlmodels/models.py", line 421, in fit_cli
    model = model_create(module, model_p, data_p, compute_p)  # Exact map JSON and paramters
  File "/home/runner/work/mlmodels/mlmodels/mlmodels/models.py", line 113, in model_create
    module.init(model_pars=model_pars, data_pars=data_pars, compute_pars=compute_pars, **kwarg)
AttributeError: module 'mlmodels.model_tch.torchhub' has no attribute 'init'





 ********************************************************************************************************************************************

  ml_models --do fit --config_file /home/runner/work/mlmodels/mlmodels/mlmodels/dataset/json/benchmark_cnn/fashion_mnist/wide_resnet50_2_benchmark_FashionMNIST.json  --config_mode prod  
fit

  ##### Load JSON /home/runner/work/mlmodels/mlmodels/mlmodels/dataset/json/benchmark_cnn/fashion_mnist/wide_resnet50_2_benchmark_FashionMNIST.json 
Traceback (most recent call last):
  File "/opt/hostedtoolcache/Python/3.6.12/x64/bin/ml_models", line 11, in <module>
    load_entry_point('mlmodels', 'console_scripts', 'ml_models')()
  File "/home/runner/work/mlmodels/mlmodels/mlmodels/models.py", line 530, in main
    fit_cli(arg)
  File "/home/runner/work/mlmodels/mlmodels/mlmodels/models.py", line 413, in fit_cli
    model_p, data_p, compute_p, out_p = config_get_pars(config_file, arg.config_mode)
  File "/home/runner/work/mlmodels/mlmodels/mlmodels/models.py", line 299, in config_get_pars
    out_p     = path_norm_dict( js.get("out_pars") )
  File "/home/runner/work/mlmodels/mlmodels/mlmodels/util.py", line 201, in path_norm_dict
    for k,v in ddict.items():
AttributeError: 'NoneType' object has no attribute 'items'

  


 ************ JSON File /home/runner/work/mlmodels/mlmodels/mlmodels/dataset/json/benchmark_cnn/fashion_mnist/resnext101_32x8d_benchmark_FashionMNIST.json 





 ********************************************************************************************************************************************

  ml_models --do fit --config_file /home/runner/work/mlmodels/mlmodels/mlmodels/dataset/json/benchmark_cnn/fashion_mnist/resnext101_32x8d_benchmark_FashionMNIST.json  --config_mode test  
fit

  ##### Load JSON /home/runner/work/mlmodels/mlmodels/mlmodels/dataset/json/benchmark_cnn/fashion_mnist/resnext101_32x8d_benchmark_FashionMNIST.json 

  ##### Init model_tch.torchhub.py {'path': '/home/runner/work/mlmodels/mlmodels/mlmodels/ztest/model_tch/torchhub/resnext101_32x8d/', 'model_uri': 'model_tch.torchhub.py'} 
Traceback (most recent call last):
  File "/opt/hostedtoolcache/Python/3.6.12/x64/bin/ml_models", line 11, in <module>
    load_entry_point('mlmodels', 'console_scripts', 'ml_models')()
  File "/home/runner/work/mlmodels/mlmodels/mlmodels/models.py", line 530, in main
    fit_cli(arg)
  File "/home/runner/work/mlmodels/mlmodels/mlmodels/models.py", line 421, in fit_cli
    model = model_create(module, model_p, data_p, compute_p)  # Exact map JSON and paramters
  File "/home/runner/work/mlmodels/mlmodels/mlmodels/models.py", line 113, in model_create
    module.init(model_pars=model_pars, data_pars=data_pars, compute_pars=compute_pars, **kwarg)
AttributeError: module 'mlmodels.model_tch.torchhub' has no attribute 'init'





 ********************************************************************************************************************************************

  ml_models --do fit --config_file /home/runner/work/mlmodels/mlmodels/mlmodels/dataset/json/benchmark_cnn/fashion_mnist/resnext101_32x8d_benchmark_FashionMNIST.json  --config_mode prod  
fit

  ##### Load JSON /home/runner/work/mlmodels/mlmodels/mlmodels/dataset/json/benchmark_cnn/fashion_mnist/resnext101_32x8d_benchmark_FashionMNIST.json 
Traceback (most recent call last):
  File "/opt/hostedtoolcache/Python/3.6.12/x64/bin/ml_models", line 11, in <module>
    load_entry_point('mlmodels', 'console_scripts', 'ml_models')()
  File "/home/runner/work/mlmodels/mlmodels/mlmodels/models.py", line 530, in main
    fit_cli(arg)
  File "/home/runner/work/mlmodels/mlmodels/mlmodels/models.py", line 413, in fit_cli
    model_p, data_p, compute_p, out_p = config_get_pars(config_file, arg.config_mode)
  File "/home/runner/work/mlmodels/mlmodels/mlmodels/models.py", line 299, in config_get_pars
    out_p     = path_norm_dict( js.get("out_pars") )
  File "/home/runner/work/mlmodels/mlmodels/mlmodels/util.py", line 201, in path_norm_dict
    for k,v in ddict.items():
AttributeError: 'NoneType' object has no attribute 'items'

  


 ************ JSON File /home/runner/work/mlmodels/mlmodels/mlmodels/dataset/json/benchmark_cnn/fashion_mnist/resnet101_benchmark_FashionMNIST.json 





 ********************************************************************************************************************************************

  ml_models --do fit --config_file /home/runner/work/mlmodels/mlmodels/mlmodels/dataset/json/benchmark_cnn/fashion_mnist/resnet101_benchmark_FashionMNIST.json  --config_mode test  
fit

  ##### Load JSON /home/runner/work/mlmodels/mlmodels/mlmodels/dataset/json/benchmark_cnn/fashion_mnist/resnet101_benchmark_FashionMNIST.json 

  ##### Init model_tch.torchhub.py {'path': '/home/runner/work/mlmodels/mlmodels/mlmodels/ztest/model_tch/torchhub/resnet101/', 'model_uri': 'model_tch.torchhub.py'} 
Traceback (most recent call last):
  File "/opt/hostedtoolcache/Python/3.6.12/x64/bin/ml_models", line 11, in <module>
    load_entry_point('mlmodels', 'console_scripts', 'ml_models')()
  File "/home/runner/work/mlmodels/mlmodels/mlmodels/models.py", line 530, in main
    fit_cli(arg)
  File "/home/runner/work/mlmodels/mlmodels/mlmodels/models.py", line 421, in fit_cli
    model = model_create(module, model_p, data_p, compute_p)  # Exact map JSON and paramters
  File "/home/runner/work/mlmodels/mlmodels/mlmodels/models.py", line 113, in model_create
    module.init(model_pars=model_pars, data_pars=data_pars, compute_pars=compute_pars, **kwarg)
AttributeError: module 'mlmodels.model_tch.torchhub' has no attribute 'init'





 ********************************************************************************************************************************************

  ml_models --do fit --config_file /home/runner/work/mlmodels/mlmodels/mlmodels/dataset/json/benchmark_cnn/fashion_mnist/resnet101_benchmark_FashionMNIST.json  --config_mode prod  
fit

  ##### Load JSON /home/runner/work/mlmodels/mlmodels/mlmodels/dataset/json/benchmark_cnn/fashion_mnist/resnet101_benchmark_FashionMNIST.json 
Traceback (most recent call last):
  File "/opt/hostedtoolcache/Python/3.6.12/x64/bin/ml_models", line 11, in <module>
    load_entry_point('mlmodels', 'console_scripts', 'ml_models')()
  File "/home/runner/work/mlmodels/mlmodels/mlmodels/models.py", line 530, in main
    fit_cli(arg)
  File "/home/runner/work/mlmodels/mlmodels/mlmodels/models.py", line 413, in fit_cli
    model_p, data_p, compute_p, out_p = config_get_pars(config_file, arg.config_mode)
  File "/home/runner/work/mlmodels/mlmodels/mlmodels/models.py", line 299, in config_get_pars
    out_p     = path_norm_dict( js.get("out_pars") )
  File "/home/runner/work/mlmodels/mlmodels/mlmodels/util.py", line 201, in path_norm_dict
    for k,v in ddict.items():
AttributeError: 'NoneType' object has no attribute 'items'

  


 ************ JSON File /home/runner/work/mlmodels/mlmodels/mlmodels/dataset/json/benchmark_cnn/fashion_mnist/resnet50_benchmark_FashionMNIST.json 





 ********************************************************************************************************************************************

  ml_models --do fit --config_file /home/runner/work/mlmodels/mlmodels/mlmodels/dataset/json/benchmark_cnn/fashion_mnist/resnet50_benchmark_FashionMNIST.json  --config_mode test  
fit

  ##### Load JSON /home/runner/work/mlmodels/mlmodels/mlmodels/dataset/json/benchmark_cnn/fashion_mnist/resnet50_benchmark_FashionMNIST.json 

  ##### Init model_tch.torchhub.py {'path': '/home/runner/work/mlmodels/mlmodels/mlmodels/ztest/model_tch/torchhub/resnet50/', 'model_uri': 'model_tch.torchhub.py'} 
Traceback (most recent call last):
  File "/opt/hostedtoolcache/Python/3.6.12/x64/bin/ml_models", line 11, in <module>
    load_entry_point('mlmodels', 'console_scripts', 'ml_models')()
  File "/home/runner/work/mlmodels/mlmodels/mlmodels/models.py", line 530, in main
    fit_cli(arg)
  File "/home/runner/work/mlmodels/mlmodels/mlmodels/models.py", line 421, in fit_cli
    model = model_create(module, model_p, data_p, compute_p)  # Exact map JSON and paramters
  File "/home/runner/work/mlmodels/mlmodels/mlmodels/models.py", line 113, in model_create
    module.init(model_pars=model_pars, data_pars=data_pars, compute_pars=compute_pars, **kwarg)
AttributeError: module 'mlmodels.model_tch.torchhub' has no attribute 'init'





 ********************************************************************************************************************************************

  ml_models --do fit --config_file /home/runner/work/mlmodels/mlmodels/mlmodels/dataset/json/benchmark_cnn/fashion_mnist/resnet50_benchmark_FashionMNIST.json  --config_mode prod  
fit

  ##### Load JSON /home/runner/work/mlmodels/mlmodels/mlmodels/dataset/json/benchmark_cnn/fashion_mnist/resnet50_benchmark_FashionMNIST.json 
Traceback (most recent call last):
  File "/opt/hostedtoolcache/Python/3.6.12/x64/bin/ml_models", line 11, in <module>
    load_entry_point('mlmodels', 'console_scripts', 'ml_models')()
  File "/home/runner/work/mlmodels/mlmodels/mlmodels/models.py", line 530, in main
    fit_cli(arg)
  File "/home/runner/work/mlmodels/mlmodels/mlmodels/models.py", line 413, in fit_cli
    model_p, data_p, compute_p, out_p = config_get_pars(config_file, arg.config_mode)
  File "/home/runner/work/mlmodels/mlmodels/mlmodels/models.py", line 299, in config_get_pars
    out_p     = path_norm_dict( js.get("out_pars") )
  File "/home/runner/work/mlmodels/mlmodels/mlmodels/util.py", line 201, in path_norm_dict
    for k,v in ddict.items():
AttributeError: 'NoneType' object has no attribute 'items'

  


 ************ JSON File /home/runner/work/mlmodels/mlmodels/mlmodels/dataset/json/benchmark_text_classification/jsons/textcnn_tch.json 





 ********************************************************************************************************************************************

  ml_models --do fit --config_file /home/runner/work/mlmodels/mlmodels/mlmodels/dataset/json/benchmark_text_classification/jsons/textcnn_tch.json  --config_mode test  
fit

  ##### Load JSON /home/runner/work/mlmodels/mlmodels/mlmodels/dataset/json/benchmark_text_classification/jsons/textcnn_tch.json 

  ##### Init model_tch.textcnn.py {'path': './output/text_cnn_tch/model.h5', 'model_uri': 'model_tch.textcnn.py'} 
Traceback (most recent call last):
  File "/home/runner/work/mlmodels/mlmodels/mlmodels/models.py", line 72, in module_load
    module = import_module(f"mlmodels.{model_name}")
  File "/opt/hostedtoolcache/Python/3.6.12/x64/lib/python3.6/importlib/__init__.py", line 126, in import_module
    return _bootstrap._gcd_import(name[level:], package, level)
  File "<frozen importlib._bootstrap>", line 994, in _gcd_import
  File "<frozen importlib._bootstrap>", line 971, in _find_and_load
  File "<frozen importlib._bootstrap>", line 955, in _find_and_load_unlocked
  File "<frozen importlib._bootstrap>", line 665, in _load_unlocked
  File "<frozen importlib._bootstrap_external>", line 678, in exec_module
  File "<frozen importlib._bootstrap>", line 219, in _call_with_frames_removed
  File "/home/runner/work/mlmodels/mlmodels/mlmodels/model_tch/textcnn.py", line 24, in <module>
    import torchtext
  File "/opt/hostedtoolcache/Python/3.6.12/x64/lib/python3.6/site-packages/torchtext/__init__.py", line 42, in <module>
    _init_extension()
  File "/opt/hostedtoolcache/Python/3.6.12/x64/lib/python3.6/site-packages/torchtext/__init__.py", line 38, in _init_extension
    torch.ops.load_library(ext_specs.origin)
  File "/opt/hostedtoolcache/Python/3.6.12/x64/lib/python3.6/site-packages/torch/_ops.py", line 106, in load_library
    ctypes.CDLL(path)
  File "/opt/hostedtoolcache/Python/3.6.12/x64/lib/python3.6/ctypes/__init__.py", line 348, in __init__
    self._handle = _dlopen(self._name, mode)
OSError: libtorch_cpu.so: cannot open shared object file: No such file or directory

During handling of the above exception, another exception occurred:

Traceback (most recent call last):
  File "/home/runner/work/mlmodels/mlmodels/mlmodels/models.py", line 84, in module_load
    model_name = str(Path(model_uri).parts[-2]) + "." + str(model_name)
IndexError: tuple index out of range

During handling of the above exception, another exception occurred:

Traceback (most recent call last):
  File "/opt/hostedtoolcache/Python/3.6.12/x64/bin/ml_models", line 11, in <module>
    load_entry_point('mlmodels', 'console_scripts', 'ml_models')()
  File "/home/runner/work/mlmodels/mlmodels/mlmodels/models.py", line 530, in main
    fit_cli(arg)
  File "/home/runner/work/mlmodels/mlmodels/mlmodels/models.py", line 420, in fit_cli
    module = module_load(model_uri)  # '1_lstm.py
  File "/home/runner/work/mlmodels/mlmodels/mlmodels/models.py", line 89, in module_load
    raise NameError(f"Module {model_name} notfound, {e1}, {e2}")
NameError: Module model_tch.textcnn notfound, libtorch_cpu.so: cannot open shared object file: No such file or directory, tuple index out of range





 ********************************************************************************************************************************************

  ml_models --do fit --config_file /home/runner/work/mlmodels/mlmodels/mlmodels/dataset/json/benchmark_text_classification/jsons/textcnn_tch.json  --config_mode prod  
fit

  ##### Load JSON /home/runner/work/mlmodels/mlmodels/mlmodels/dataset/json/benchmark_text_classification/jsons/textcnn_tch.json 
Traceback (most recent call last):
  File "/opt/hostedtoolcache/Python/3.6.12/x64/bin/ml_models", line 11, in <module>
    load_entry_point('mlmodels', 'console_scripts', 'ml_models')()
  File "/home/runner/work/mlmodels/mlmodels/mlmodels/models.py", line 530, in main
    fit_cli(arg)
  File "/home/runner/work/mlmodels/mlmodels/mlmodels/models.py", line 413, in fit_cli
    model_p, data_p, compute_p, out_p = config_get_pars(config_file, arg.config_mode)
  File "/home/runner/work/mlmodels/mlmodels/mlmodels/models.py", line 297, in config_get_pars
    data_p    = path_norm_dict( js.get("data_pars") )
  File "/home/runner/work/mlmodels/mlmodels/mlmodels/util.py", line 201, in path_norm_dict
    for k,v in ddict.items():
AttributeError: 'NoneType' object has no attribute 'items'

  


 ************ JSON File /home/runner/work/mlmodels/mlmodels/mlmodels/dataset/json/benchmark_text_classification/jsons/textcnn_keras.json 





 ********************************************************************************************************************************************

  ml_models --do fit --config_file /home/runner/work/mlmodels/mlmodels/mlmodels/dataset/json/benchmark_text_classification/jsons/textcnn_keras.json  --config_mode test  
fit

  ##### Load JSON /home/runner/work/mlmodels/mlmodels/mlmodels/dataset/json/benchmark_text_classification/jsons/textcnn_keras.json 

  ##### Init model_keras.textcnn.py {'path': './output/textcnn_keras//model.h5', 'model_uri': 'model_keras.textcnn.py'} 
Using TensorFlow backend.
Traceback (most recent call last):
  File "/opt/hostedtoolcache/Python/3.6.12/x64/bin/ml_models", line 11, in <module>
    load_entry_point('mlmodels', 'console_scripts', 'ml_models')()
  File "/home/runner/work/mlmodels/mlmodels/mlmodels/models.py", line 530, in main
    fit_cli(arg)
  File "/home/runner/work/mlmodels/mlmodels/mlmodels/models.py", line 421, in fit_cli
    model = model_create(module, model_p, data_p, compute_p)  # Exact map JSON and paramters
  File "/home/runner/work/mlmodels/mlmodels/mlmodels/models.py", line 113, in model_create
    module.init(model_pars=model_pars, data_pars=data_pars, compute_pars=compute_pars, **kwarg)
AttributeError: module 'mlmodels.model_keras.textcnn' has no attribute 'init'





 ********************************************************************************************************************************************

  ml_models --do fit --config_file /home/runner/work/mlmodels/mlmodels/mlmodels/dataset/json/benchmark_text_classification/jsons/textcnn_keras.json  --config_mode prod  
fit

  ##### Load JSON /home/runner/work/mlmodels/mlmodels/mlmodels/dataset/json/benchmark_text_classification/jsons/textcnn_keras.json 
Traceback (most recent call last):
  File "/opt/hostedtoolcache/Python/3.6.12/x64/bin/ml_models", line 11, in <module>
    load_entry_point('mlmodels', 'console_scripts', 'ml_models')()
  File "/home/runner/work/mlmodels/mlmodels/mlmodels/models.py", line 530, in main
    fit_cli(arg)
  File "/home/runner/work/mlmodels/mlmodels/mlmodels/models.py", line 413, in fit_cli
    model_p, data_p, compute_p, out_p = config_get_pars(config_file, arg.config_mode)
  File "/home/runner/work/mlmodels/mlmodels/mlmodels/models.py", line 299, in config_get_pars
    out_p     = path_norm_dict( js.get("out_pars") )
  File "/home/runner/work/mlmodels/mlmodels/mlmodels/util.py", line 201, in path_norm_dict
    for k,v in ddict.items():
AttributeError: 'NoneType' object has no attribute 'items'

  


 ************ JSON File /home/runner/work/mlmodels/mlmodels/mlmodels/dataset/json/benchmark_text_classification/jsons/namentity_crm_bilstm.json 





 ********************************************************************************************************************************************

  ml_models --do fit --config_file /home/runner/work/mlmodels/mlmodels/mlmodels/dataset/json/benchmark_text_classification/jsons/namentity_crm_bilstm.json  --config_mode test  
fit

  ##### Load JSON /home/runner/work/mlmodels/mlmodels/mlmodels/dataset/json/benchmark_text_classification/jsons/namentity_crm_bilstm.json 

  ##### Init model_keras.namentity_crm_bilstm.py {'path': '/home/runner/work/mlmodels/mlmodels/mlmodels/ztest/ml_keras/namentity_crm_bilstm/', 'model_uri': 'model_keras.namentity_crm_bilstm.py'} 
Using TensorFlow backend.
Traceback (most recent call last):
  File "/opt/hostedtoolcache/Python/3.6.12/x64/bin/ml_models", line 11, in <module>
    load_entry_point('mlmodels', 'console_scripts', 'ml_models')()
  File "/home/runner/work/mlmodels/mlmodels/mlmodels/models.py", line 530, in main
    fit_cli(arg)
  File "/home/runner/work/mlmodels/mlmodels/mlmodels/models.py", line 421, in fit_cli
    model = model_create(module, model_p, data_p, compute_p)  # Exact map JSON and paramters
  File "/home/runner/work/mlmodels/mlmodels/mlmodels/models.py", line 113, in model_create
    module.init(model_pars=model_pars, data_pars=data_pars, compute_pars=compute_pars, **kwarg)
AttributeError: module 'mlmodels.model_keras.namentity_crm_bilstm' has no attribute 'init'





 ********************************************************************************************************************************************

  ml_models --do fit --config_file /home/runner/work/mlmodels/mlmodels/mlmodels/dataset/json/benchmark_text_classification/jsons/namentity_crm_bilstm.json  --config_mode prod  
fit

  ##### Load JSON /home/runner/work/mlmodels/mlmodels/mlmodels/dataset/json/benchmark_text_classification/jsons/namentity_crm_bilstm.json 
Traceback (most recent call last):
  File "/opt/hostedtoolcache/Python/3.6.12/x64/bin/ml_models", line 11, in <module>
    load_entry_point('mlmodels', 'console_scripts', 'ml_models')()
  File "/home/runner/work/mlmodels/mlmodels/mlmodels/models.py", line 530, in main
    fit_cli(arg)
  File "/home/runner/work/mlmodels/mlmodels/mlmodels/models.py", line 413, in fit_cli
    model_p, data_p, compute_p, out_p = config_get_pars(config_file, arg.config_mode)
  File "/home/runner/work/mlmodels/mlmodels/mlmodels/models.py", line 299, in config_get_pars
    out_p     = path_norm_dict( js.get("out_pars") )
  File "/home/runner/work/mlmodels/mlmodels/mlmodels/util.py", line 201, in path_norm_dict
    for k,v in ddict.items():
AttributeError: 'NoneType' object has no attribute 'items'

  


 ************ JSON File /home/runner/work/mlmodels/mlmodels/mlmodels/dataset/json/benchmark_text_classification/jsons/autokeras_classifier.json 





 ********************************************************************************************************************************************

  ml_models --do fit --config_file /home/runner/work/mlmodels/mlmodels/mlmodels/dataset/json/benchmark_text_classification/jsons/autokeras_classifier.json  --config_mode test  
fit

  ##### Load JSON /home/runner/work/mlmodels/mlmodels/mlmodels/dataset/json/benchmark_text_classification/jsons/autokeras_classifier.json 

  ##### Init model_keras.Autokeras.py {'path': '/home/runner/work/mlmodels/mlmodels/mlmodels/ztest/model_tch/MATCHZOO/BERT/', 'model_uri': 'model_keras.Autokeras.py'} 
Traceback (most recent call last):
  File "/home/runner/work/mlmodels/mlmodels/mlmodels/models.py", line 72, in module_load
    module = import_module(f"mlmodels.{model_name}")
  File "/opt/hostedtoolcache/Python/3.6.12/x64/lib/python3.6/importlib/__init__.py", line 126, in import_module
    return _bootstrap._gcd_import(name[level:], package, level)
  File "<frozen importlib._bootstrap>", line 994, in _gcd_import
  File "<frozen importlib._bootstrap>", line 971, in _find_and_load
  File "<frozen importlib._bootstrap>", line 955, in _find_and_load_unlocked
  File "<frozen importlib._bootstrap>", line 665, in _load_unlocked
  File "<frozen importlib._bootstrap_external>", line 678, in exec_module
  File "<frozen importlib._bootstrap>", line 219, in _call_with_frames_removed
  File "/home/runner/work/mlmodels/mlmodels/mlmodels/model_keras/Autokeras.py", line 12, in <module>
    import autokeras as ak
ModuleNotFoundError: No module named 'autokeras'

During handling of the above exception, another exception occurred:

Traceback (most recent call last):
  File "/home/runner/work/mlmodels/mlmodels/mlmodels/models.py", line 84, in module_load
    model_name = str(Path(model_uri).parts[-2]) + "." + str(model_name)
IndexError: tuple index out of range

During handling of the above exception, another exception occurred:

Traceback (most recent call last):
  File "/opt/hostedtoolcache/Python/3.6.12/x64/bin/ml_models", line 11, in <module>
    load_entry_point('mlmodels', 'console_scripts', 'ml_models')()
  File "/home/runner/work/mlmodels/mlmodels/mlmodels/models.py", line 530, in main
    fit_cli(arg)
  File "/home/runner/work/mlmodels/mlmodels/mlmodels/models.py", line 420, in fit_cli
    module = module_load(model_uri)  # '1_lstm.py
  File "/home/runner/work/mlmodels/mlmodels/mlmodels/models.py", line 89, in module_load
    raise NameError(f"Module {model_name} notfound, {e1}, {e2}")
NameError: Module model_keras.Autokeras notfound, No module named 'autokeras', tuple index out of range





 ********************************************************************************************************************************************

  ml_models --do fit --config_file /home/runner/work/mlmodels/mlmodels/mlmodels/dataset/json/benchmark_text_classification/jsons/autokeras_classifier.json  --config_mode prod  
fit

  ##### Load JSON /home/runner/work/mlmodels/mlmodels/mlmodels/dataset/json/benchmark_text_classification/jsons/autokeras_classifier.json 
Traceback (most recent call last):
  File "/opt/hostedtoolcache/Python/3.6.12/x64/bin/ml_models", line 11, in <module>
    load_entry_point('mlmodels', 'console_scripts', 'ml_models')()
  File "/home/runner/work/mlmodels/mlmodels/mlmodels/models.py", line 530, in main
    fit_cli(arg)
  File "/home/runner/work/mlmodels/mlmodels/mlmodels/models.py", line 413, in fit_cli
    model_p, data_p, compute_p, out_p = config_get_pars(config_file, arg.config_mode)
  File "/home/runner/work/mlmodels/mlmodels/mlmodels/models.py", line 299, in config_get_pars
    out_p     = path_norm_dict( js.get("out_pars") )
  File "/home/runner/work/mlmodels/mlmodels/mlmodels/util.py", line 201, in path_norm_dict
    for k,v in ddict.items():
AttributeError: 'NoneType' object has no attribute 'items'

  


 ************ JSON File /home/runner/work/mlmodels/mlmodels/mlmodels/dataset/json/benchmark_text_classification/jsons/textvae.json 





 ********************************************************************************************************************************************

  ml_models --do fit --config_file /home/runner/work/mlmodels/mlmodels/mlmodels/dataset/json/benchmark_text_classification/jsons/textvae.json  --config_mode test  
fit

  ##### Load JSON /home/runner/work/mlmodels/mlmodels/mlmodels/dataset/json/benchmark_text_classification/jsons/textvae.json 

  ##### Init model_keras.textvae.py {'path': '/home/runner/work/mlmodels/mlmodels/mlmodels/ztest/ml_keras/textvae/', 'model_uri': 'model_keras.textvae.py'} 
Traceback (most recent call last):
  File "/home/runner/work/mlmodels/mlmodels/mlmodels/models.py", line 72, in module_load
    module = import_module(f"mlmodels.{model_name}")
  File "/opt/hostedtoolcache/Python/3.6.12/x64/lib/python3.6/importlib/__init__.py", line 126, in import_module
    return _bootstrap._gcd_import(name[level:], package, level)
  File "<frozen importlib._bootstrap>", line 994, in _gcd_import
  File "<frozen importlib._bootstrap>", line 971, in _find_and_load
  File "<frozen importlib._bootstrap>", line 953, in _find_and_load_unlocked
ModuleNotFoundError: No module named 'mlmodels.model_keras.textvae'

During handling of the above exception, another exception occurred:

Traceback (most recent call last):
  File "/home/runner/work/mlmodels/mlmodels/mlmodels/models.py", line 84, in module_load
    model_name = str(Path(model_uri).parts[-2]) + "." + str(model_name)
IndexError: tuple index out of range

During handling of the above exception, another exception occurred:

Traceback (most recent call last):
  File "/opt/hostedtoolcache/Python/3.6.12/x64/bin/ml_models", line 11, in <module>
    load_entry_point('mlmodels', 'console_scripts', 'ml_models')()
  File "/home/runner/work/mlmodels/mlmodels/mlmodels/models.py", line 530, in main
    fit_cli(arg)
  File "/home/runner/work/mlmodels/mlmodels/mlmodels/models.py", line 420, in fit_cli
    module = module_load(model_uri)  # '1_lstm.py
  File "/home/runner/work/mlmodels/mlmodels/mlmodels/models.py", line 89, in module_load
    raise NameError(f"Module {model_name} notfound, {e1}, {e2}")
NameError: Module model_keras.textvae notfound, No module named 'mlmodels.model_keras.textvae', tuple index out of range





 ********************************************************************************************************************************************

  ml_models --do fit --config_file /home/runner/work/mlmodels/mlmodels/mlmodels/dataset/json/benchmark_text_classification/jsons/textvae.json  --config_mode prod  
fit

  ##### Load JSON /home/runner/work/mlmodels/mlmodels/mlmodels/dataset/json/benchmark_text_classification/jsons/textvae.json 
Traceback (most recent call last):
  File "/opt/hostedtoolcache/Python/3.6.12/x64/bin/ml_models", line 11, in <module>
    load_entry_point('mlmodels', 'console_scripts', 'ml_models')()
  File "/home/runner/work/mlmodels/mlmodels/mlmodels/models.py", line 530, in main
    fit_cli(arg)
  File "/home/runner/work/mlmodels/mlmodels/mlmodels/models.py", line 413, in fit_cli
    model_p, data_p, compute_p, out_p = config_get_pars(config_file, arg.config_mode)
  File "/home/runner/work/mlmodels/mlmodels/mlmodels/models.py", line 299, in config_get_pars
    out_p     = path_norm_dict( js.get("out_pars") )
  File "/home/runner/work/mlmodels/mlmodels/mlmodels/util.py", line 201, in path_norm_dict
    for k,v in ddict.items():
AttributeError: 'NoneType' object has no attribute 'items'

  


 ************ JSON File /home/runner/work/mlmodels/mlmodels/mlmodels/dataset/json/benchmark_text_classification/jsons/transformer_classifier.json 





 ********************************************************************************************************************************************

  ml_models --do fit --config_file /home/runner/work/mlmodels/mlmodels/mlmodels/dataset/json/benchmark_text_classification/jsons/transformer_classifier.json  --config_mode test  
fit

  ##### Load JSON /home/runner/work/mlmodels/mlmodels/mlmodels/dataset/json/benchmark_text_classification/jsons/transformer_classifier.json 
Traceback (most recent call last):
  File "/opt/hostedtoolcache/Python/3.6.12/x64/bin/ml_models", line 11, in <module>
    load_entry_point('mlmodels', 'console_scripts', 'ml_models')()
  File "/home/runner/work/mlmodels/mlmodels/mlmodels/models.py", line 530, in main
    fit_cli(arg)
  File "/home/runner/work/mlmodels/mlmodels/mlmodels/models.py", line 415, in fit_cli
    path      = out_p['path']
KeyError: 'path'





 ********************************************************************************************************************************************

  ml_models --do fit --config_file /home/runner/work/mlmodels/mlmodels/mlmodels/dataset/json/benchmark_text_classification/jsons/transformer_classifier.json  --config_mode prod  
fit

  ##### Load JSON /home/runner/work/mlmodels/mlmodels/mlmodels/dataset/json/benchmark_text_classification/jsons/transformer_classifier.json 
Traceback (most recent call last):
  File "/opt/hostedtoolcache/Python/3.6.12/x64/bin/ml_models", line 11, in <module>
    load_entry_point('mlmodels', 'console_scripts', 'ml_models')()
  File "/home/runner/work/mlmodels/mlmodels/mlmodels/models.py", line 530, in main
    fit_cli(arg)
  File "/home/runner/work/mlmodels/mlmodels/mlmodels/models.py", line 413, in fit_cli
    model_p, data_p, compute_p, out_p = config_get_pars(config_file, arg.config_mode)
  File "/home/runner/work/mlmodels/mlmodels/mlmodels/models.py", line 299, in config_get_pars
    out_p     = path_norm_dict( js.get("out_pars") )
  File "/home/runner/work/mlmodels/mlmodels/mlmodels/util.py", line 201, in path_norm_dict
    for k,v in ddict.items():
AttributeError: 'NoneType' object has no attribute 'items'
